Workbook
Name DM_TRANGTHAI_HOSO: THIET_LAP!$J$4:$J$11
Name DM_TRANGTHAI_TASK: THIET_LAP!$L$4:$L$8
Name DM_NHANSU: THIET_LAP!$F$4:$F$12
Name DM_PHONGBAN: THIET_LAP!$D$4:$D$10
Name DM_UUTIEN: THIET_LAP!$N$4:$N$8
Name DM_DICHVU: THIET_LAP!$H$4:$H$13

Sheet THIET_LAP
A1: THIẾT LẬP HỆ THỐNG BÁCH KHOA 2026
A3: Điều khiển | D3: PHÒNG BAN | F3: NHÂN SỰ | H3: DỊCH VỤ | J3: TRẠNG THÁI HỒ SƠ | L3: TRẠNG THÁI TASK | N3: MỨC ƯU TIÊN
A4: Mã tiền tố | B4: BK | D4: Phòng Giám đốc | F4: Giám đốc | H4: Đo hiện trạng | J4: Mới tiếp nhận | L4: Cần thực hiện | N4: Thấp
A5: Năm vận hành | B5: 2026 | D5: Phòng Kinh doanh | F5: Lê Văn Dựng | H5: Cắm mốc | J5: Chờ khảo sát | L5: Đang tiến hành | N5: Trung bình
A6: Tiền tệ | B6: VND | D6: Phòng Marketing | F6: Tạ Khắc Tập | H6: Hoàn công | J6: Đang đo | L6: Đang chờ | N6: Cao
A7: Ngưỡng cảnh báo hồ sơ (ngày) | B7: 2 | D7: Phòng Đo đạc | F7: Trương Tấn Quốc | H7: Cấp đổi | J7: Đang làm hồ sơ | L7: Hoàn thành | N7: Rất cao
A8: Ngưỡng cảnh báo task (ngày) | B8: 1 | D8: Phòng Pháp lý | F8: Nguyễn Minh Thông | H8: Hợp thửa | J8: Chờ khách bổ sung | L8: Đã hủy | N8: Khẩn cấp
D9: Phòng Kế toán | F9: Lê Tấn Đạt | H9: Tách Thửa | J9: Đã nộp
D10: Phòng Nhân sự | F10: Lê Văn Xây | H10: Cấp sổ lần đầu | J10: Hoàn thành
F11: Trần Thị Tường Vy | H11: Xác định ranh | J11: Đã hủy
F12: Hồ Thị Mỹ Hằng | H12: Đo GPS
H13: SEO / Marketing
H14: Xin phép xây dựng

Sheet HUONG_DAN
A1: HƯỚNG DẪN SỬ DỤNG FILE FULL AUTO
A3: Bước | B3: Mục tiêu | C3: Hướng dẫn
A4: BƯỚC 1 | B4: Cập nhật danh mục | C4: Sửa phòng ban, nhân sự, dịch vụ, trạng thái ở tab THIET_LAP trước khi dùng.
A5: BƯỚC 2 | B5: Nhập hồ sơ gốc | C5: Mọi công việc mới phải đi vào DATABASE_HOSO. Mã hồ sơ sẽ tự sinh khi có Ngày tạo.
A6: BƯỚC 3 | B6: Giao việc | C6: Tạo các đầu việc trong DATABASE_TASK và gắn đúng Mã hồ sơ.
A7: BƯỚC 4 | B7: Theo dõi tiền | C7: Hợp đồng vào DATABASE_HOP_DONG, thu chi vào DATABASE_THU_CHI.
A8: BƯỚC 5 | B8: Chốt lương | C8: Mỗi dòng khoán / phụ cấp / thưởng phạt nhập ở DATABASE_LUONG_KHOAN.
A9: BƯỚC 6 | B9: Xem dashboard | C9: Giám đốc chỉ cần mở DASHBOARD_GIAMDOC để nhìn toàn hệ thống.
A12: Luồng chuẩn
A13: Khách/Zalo → Form/nhập liệu → DATABASE_HOSO → DATABASE_TASK → Hợp đồng / Thu chi / Lương → Dashboard

Sheet HUONG_DAN_CHUYEN_DOI
A1: HƯỚNG DẪN NỐI DỮ LIỆU CŨ SANG FULL AUTO
A2: File này đã được nạp sẵn dữ liệu mẫu từ hệ thống hiện tại của Bách Khoa để anh dùng làm bản chuyển đổi.
A4: 1. Hồ sơ đo đạc | B4: Đã nạp 320 hồ sơ mới nhất từ file "Bảng 03. Phòng đo vẽ .xlsx" vào DATABASE_HOSO và DODAC_TAC_NGHIEP.
A5: 2. Hợp đồng | B5: Đã nạp 320 hợp đồng liên quan từ file "Quản lý hợp đồng - Công nợ CHUẨN V1.xlsx" vào DATABASE_HOP_DONG.
A6: 3. Thu chi | B6: Đã nạp 220 giao dịch thu chi gần nhất từ file "Thu chi Công Ty Bách Khoa năm 2026.xlsx" vào DATABASE_THU_CHI.
A7: 4. Lương khoán | B7: Đã nạp 231 dòng lương/khoán từ file "Công việc - Lê Văn Dựng_v1.xlsx" vào DATABASE_LUONG_KHOAN.
A8: 5. Cách dùng | B8: Từ nay chỉ nhập hồ sơ mới vào DATABASE_HOSO hoặc Google Form. Các phòng ban cập nhật tiến độ ở tab tác nghiệp riêng.
A9: 6. Quy tắc khóa chính | B9: Mã hồ sơ BK-HS-xxxx là trục nối giữa hồ sơ, task, hợp đồng, thu chi và lương khoán.
A10: 7. Việc cần làm tiếp | B10: Sau phòng đo đạc, anh làm tương tự cho Pháp lý, Kinh doanh và Marketing.

Sheet MAP_NGUON_DU_LIEU
A1: Nguồn hiện tại | B1: Sheet nguồn | C1: Đích trong file mới | D1: Khóa nối | E1: Ghi chú
A2: Bảng 03. Phòng đo vẽ .xlsx | B2: Bảng tổng hợp | C2: DATABASE_HOSO / DODAC_TAC_NGHIEP / DATABASE_TASK | D2: Mã hồ sơ | E2: Đã map từ Mã hợp đồng cũ sang BK-HS-xxxx
A3: Quản lý hợp đồng - Công nợ CHUẨN V1.xlsx | B3: Hợp đồng | C3: DATABASE_HOP_DONG | D3: Mã hợp đồng | E3: Tự nối sang Mã hồ sơ nếu trùng hợp đồng cũ
A4: Thu chi Công Ty Bách Khoa năm 2026.xlsx | B4: ThuChiVat | C4: DATABASE_THU_CHI | D4: Số chứng từ | E4: Chưa nối mã hồ sơ cho các khoản chi nội bộ
A5: Công việc - Lê Văn Dựng_v1.xlsx | B5: Lương đo vẽ / Lương phụ đo | C5: DATABASE_LUONG_KHOAN | D5: Mã hợp đồng cũ | E5: Đã giữ thông tin HĐ cũ trong cột Ghi chú
A6: Bảng 02. Cơ chế khoán đo vẽ.xlsx | B6: Sheet1 | C6: THIET_LAP / DATABASE_LUONG_KHOAN | D6: Loại dịch vụ | E6: Dùng để chuẩn hóa danh mục dịch vụ và mức khoán

Sheet DATABASE_HOSO
A1: DATABASE HỒ SƠ
A2: Nguồn dữ liệu gốc toàn công ty. Mỗi hồ sơ chỉ có 1 dòng.
A3: Mã hồ sơ | B3: Ngày tạo | C3: Phòng ban | D3: Loại dịch vụ | E3: Tên hồ sơ | F3: Tên khách hàng | G3: SĐT | H3: Khu vực/Phường | I3: Phụ trách chính | J3: Hỗ trợ | K3: Ưu tiên | L3: Trạng thái | M3: Deadline | N3: Số ngày còn lại | O3: Cảnh báo | P3: Mã hợp đồng | Q3: Giá trị dự kiến | R3: Link file | S3: Ghi chú
A4: BK-HS-0001 | B4: 46097 | C4: Phòng Đo đạc | D4: Xin phép xây dựng | E4: Hoàng Nam | F4: Công Ty | H4: An Khánh | I4: Võ Thành Minh | J4: Không cần | L4: Trong hạn | M4: 46100 | N4: =IF(M4="","",M4-TODAY()) | O4: =IF(A4="","",IF(L4="Hoàn thành","XONG",IF(L4="Đã hủy","HỦY",IF(N4<0,"QUÁ HẠN",IF(N4<=THIET_LAP!$B$7,"SẮP HẠN","TRONG HẠN"))))) | P4: 128/BK-2026 | S4: Tiến độ: Trong hạn | Ngày bắt đầu: 2026-03-16 00:00:00
A5: BK-HS-0002 | B5: 46094 | C5: Phòng Đo đạc | D5: Cấp đổi | E5: Lê Văn Hoàng | F5: Cô Hoa | H5: Tam Bình | I5: Trương Tấn Quốc | J5: Võ Tứ Hợp | L5: Trong hạn | M5: 46097 | N5: =IF(M5="","",M5-TODAY()) | O5: =IF(A5="","",IF(L5="Hoàn thành","XONG",IF(L5="Đã hủy","HỦY",IF(N5<0,"QUÁ HẠN",IF(N5<=THIET_LAP!$B$7,"SẮP HẠN","TRONG HẠN"))))) | P5: 127/BK-2026 | S5: Tiến độ: Trong hạn | Ngày bắt đầu: 2026-03-13 00:00:00 | Ghi chú: Đợi trao đổi với dịch vụ
A6: BK-HS-0003 | B6: 46094 | C6: Phòng Đo đạc | D6: Hoàn công | E6: Trần Văn Giấy | F6: Tuấn Lộc | H6: Linh Xuân | I6: Lê Văn Xây | J6: Võ Tứ Hợp | L6: Nộp thành công - Chờ kết quả | M6: 46097 | N6: =IF(M6="","",M6-TODAY()) | O6: =IF(A6="","",IF(L6="Hoàn thành","XONG",IF(L6="Đã hủy","HỦY",IF(N6<0,"QUÁ HẠN",IF(N6<=THIET_LAP!$B$7,"SẮP HẠN","TRONG HẠN"))))) | P6: 126/BK-2026 | S6: Tiến độ: Đã nộp | Ngày bắt đầu: 2026-03-13 00:00:00 | Ngày nộp: 2026-03-14 00:00:00
A7: BK-HS-0004 | B7: 46094 | C7: Phòng Đo đạc | D7: Cấp đổi | E7: Nguyễn Văn Học | F7: Công Ty | G7: 0903075675 | H7: Tăng Nhơn Phú | I7: Tạ Khắc Tập | J7: Võ Tứ Hợp | L7: Nộp thành công - Chờ kết quả | M7: 46097 | N7: =IF(M7="","",M7-TODAY()) | O7: =IF(A7="","",IF(L7="Hoàn thành","XONG",IF(L7="Đã hủy","HỦY",IF(N7<0,"QUÁ HẠN",IF(N7<=THIET_LAP!$B$7,"SẮP HẠN","TRONG HẠN"))))) | P7: 125/BK-2026 | S7: Tiến độ: Đã nộp | Ngày bắt đầu: 2026-03-13 00:00:00 | Ngày nộp: 2026-03-16 00:00:00
A8: BK-HS-0005 | B8: 46094 | C8: Phòng Đo đạc | D8: Cấp đổi | E8: Đặng Khoa Học-Trần Ngọc Thùy Tiên | F8: Tuấn Lộc | H8: Hiệp Bình | I8: Tạ Khắc Tập | J8: Võ Tứ Hợp | L8: Nộp thành công - Chờ kết quả | M8: 46097 | N8: =IF(M8="","",M8-TODAY()) | O8: =IF(A8="","",IF(L8="Hoàn thành","XONG",IF(L8="Đã hủy","HỦY",IF(N8<0,"QUÁ HẠN",IF(N8<=THIET_LAP!$B$7,"SẮP HẠN","TRONG HẠN"))))) | P8: 124/BK-2026 | S8: Tiến độ: Đã nộp | Ngày bắt đầu: 2026-03-13 00:00:00 | Ngày nộp: 2026-03-16 00:00:00
A9: BK-HS-0006 | B9: 46094 | C9: Phòng Đo đạc | D9: Cắm mốc | E9: Đào Minh Quân | F9: Công Ty | H9: Linh Xuân | I9: Tạ Khắc Tập | J9: Võ Tứ Hợp | L9: Hoàn thành | M9: 46097 | N9: =IF(M9="","",M9-TODAY()) | O9: =IF(A9="","",IF(L9="Hoàn thành","XONG",IF(L9="Đã hủy","HỦY",IF(N9<0,"QUÁ HẠN",IF(N9<=THIET_LAP!$B$7,"SẮP HẠN","TRONG HẠN"))))) | P9: 123/BK-2026 | S9: Tiến độ: Hoàn thành | Ngày bắt đầu: 2026-03-13 00:00:00 | Ngày nộp: 2026-03-13 00:00:00 | Ngày HT: 2026-03-13 00:00:00 | Số cọc: 2.0 | Loại cọc: Trụ xi măng
A10: BK-HS-0007 | B10: 46093 | C10: Phòng Đo đạc | D10: Cấp đổi | E10: Trần Thanh Khương | F10: Công Ty | G10: 0987960518 | H10: Linh Xuân | I10: Lê Văn Dựng | J10: Võ Tứ Hợp | L10: QUÁ HẠN | M10: 46096 | N10: =IF(M10="","",M10-TODAY()) | O10: =IF(A10="","",IF(L10="Hoàn thành","XONG",IF(L10="Đã hủy","HỦY",IF(N10<0,"QUÁ HẠN",IF(N10<=THIET_LAP!$B$7,"SẮP HẠN","TRONG HẠN"))))) | P10: 122/BK-2026 | S10: Tiến độ: QUÁ HẠN | Ngày bắt đầu: 2026-03-12 00:00:00 | Ghi chú: hồ sơ lệch ranh chờ pa
A11: BK-HS-0008 | B11: 46093 | C11: Phòng Đo đạc | D11: Hoàn công | E11: Nguyễn Thị Hoa | F11: Anh Chiến KTS | H11: Tăng Nhơn Phú | I11: Lê Văn Dựng | J11: Võ Tứ Hợp | L11: QUÁ HẠN | M11: 46096 | N11: =IF(M11="","",M11-TODAY()) | O11: =IF(A11="","",IF(L11="Hoàn thành","XONG",IF(L11="Đã hủy","HỦY",IF(N11<0,"QUÁ HẠN",IF(N11<=THIET_LAP!$B$7,"SẮP HẠN","TRONG HẠN"))))) | P11: 121/BK-2026 | S11: Tiến độ: QUÁ HẠN | Ngày bắt đầu: 2026-03-12 00:00:00
A12: BK-HS-0009 | B12: 46092 | C12: Phòng Đo đạc | D12: Xác định diện tích | E12: Nguyễn Xuân Hạnh | F12: Công Ty | G12: 0903139386 | H12: An Khánh | I12: Lê Văn Xây | J12: Võ Tứ Hợp | L12: QUÁ HẠN | M12: 46095 | N12: =IF(M12="","",M12-TODAY()) | O12: =IF(A12="","",IF(L12="Hoàn thành","XONG",IF(L12="Đã hủy","HỦY",IF(N12<0,"QUÁ HẠN",IF(N12<=THIET_LAP!$B$7,"SẮP HẠN","TRONG HẠN"))))) | P12: 120/BK-2026 | S12: Tiến độ: QUÁ HẠN | Ngày bắt đầu: 2026-03-11 00:00:00
A13: BK-HS-0010 | B13: 46092 | C13: Phòng Đo đạc | D13: Hoàn công | E13: Đặng Quang Huy | F13: Cô Hoa | H13: Linh Xuân | I13: Lê Văn Xây | J13: Võ Tứ Hợp | L13: QUÁ HẠN | M13: 46095 | N13: =IF(M13="","",M13-TODAY()) | O13: =IF(A13="","",IF(L13="Hoàn thành","XONG",IF(L13="Đã hủy","HỦY",IF(N13<0,"QUÁ HẠN",IF(N13<=THIET_LAP!$B$7,"SẮP HẠN","TRONG HẠN"))))) | P13: 119/BK-2026 | S13: Tiến độ: QUÁ HẠN | Ngày bắt đầu: 2026-03-11 00:00:00
A14: BK-HS-0011 | B14: 46092 | C14: Phòng Đo đạc | D14: Cấp đổi | E14: Đào Minh Quân | F14: Công Ty | G14: 0399409272 | H14: Linh Xuân | I14: Trương Tấn Quốc | J14: Võ Tứ Hợp | L14: Nộp thành công - Chờ kết quả | M14: 46095 | N14: =IF(M14="","",M14-TODAY()) | O14: =IF(A14="","",IF(L14="Hoàn thành","XONG",IF(L14="Đã hủy","HỦY",IF(N14<0,"QUÁ HẠN",IF(N14<=THIET_LAP!$B$7,"SẮP HẠN","TRONG HẠN"))))) | P14: 117/BK-2026 | S14: Tiến độ: Đã nộp | Ngày bắt đầu: 2026-03-11 00:00:00 | Ngày nộp: 2026-03-13 00:00:00 | Ghi chú: Cần cắm mốc | Giải trình: Đợi trích lục
A15: BK-HS-0012 | B15: 46091 | C15: Phòng Đo đạc | D15: Cắm mốc | E15: Trần Phước Vân | F15: Chinh Đen | H15: Cát Lái | I15: Tạ Khắc Tập | J15: Không cần | L15: Hoàn thành | M15: 46094 | N15: =IF(M15="","",M15-TODAY()) | O15: =IF(A15="","",IF(L15="Hoàn thành","XONG",IF(L15="Đã hủy","HỦY",IF(N15<0,"QUÁ HẠN",IF(N15<=THIET_LAP!$B$7,"SẮP HẠN","TRONG HẠN"))))) | P15: 116/BK-2026 | S15: Tiến độ: Hoàn thành | Ngày bắt đầu: 2026-03-10 00:00:00 | Ngày nộp: 2026-03-10 00:00:00 | Ngày HT: 2026-03-10 00:00:00 | Số cọc: 5.0 | Loại cọc: Cọc sắt
A16: BK-HS-0013 | B16: 46091 | C16: Phòng Đo đạc | D16: Chuyển mục đích | E16: Nguyễn Đức Mẫn | F16: Công Ty | G16: 0938270838 | H16: Hiệp Bình | I16: Lê Văn Xây | J16: Không cần | L16: QUÁ HẠN | M16: 46094 | N16: =IF(M16="","",M16-TODAY()) | O16: =IF(A16="","",IF(L16="Hoàn thành","XONG",IF(L16="Đã hủy","HỦY",IF(N16<0,"QUÁ HẠN",IF(N16<=THIET_LAP!$B$7,"SẮP HẠN","TRONG HẠN"))))) | P16: 115/BK-2026 | S16: Tiến độ: QUÁ HẠN | Ngày bắt đầu: 2026-03-10 00:00:00
A17: BK-HS-0014 | B17: 46091 | C17: Phòng Đo đạc | D17: Cắm mốc | E17: Lê Quang Khoa | F17: Đạt Việt Phát Land | H17: Thủ Đức | I17: Tạ Khắc Tập | J17: Võ Tứ Hợp | L17: Hoàn thành | M17: 46094 | N17: =IF(M17="","",M17-TODAY()) | O17: =IF(A17="","",IF(L17="Hoàn thành","XONG",IF(L17="Đã hủy","HỦY",IF(N17<0,"QUÁ HẠN",IF(N17<=THIET_LAP!$B$7,"SẮP HẠN","TRONG HẠN"))))) | P17: 114/BK-2026 | S17: Tiến độ: Hoàn thành | Ngày bắt đầu: 2026-03-10 00:00:00 | Ngày nộp: 2026-03-10 00:00:00 | Ngày HT: 2026-03-10 00:00:00 | Số cọc: 7.0 | Loại cọc: Cọc sắt
A18: BK-HS-0015 | B18: 46091 | C18: Phòng Đo đạc | D18: Xác định diện tích | E18: Đỗ Thị Trang | F18: Công Ty | G18: zalo Victoria | H18: Tam Bình | I18: Lê Văn Dựng | J18: Võ Tứ Hợp | L18: Hoàn thành | M18: 46094 | N18: =IF(M18="","",M18-TODAY()) | O18: =IF(A18="","",IF(L18="Hoàn thành","XONG",IF(L18="Đã hủy","HỦY",IF(N18<0,"QUÁ HẠN",IF(N18<=THIET_LAP!$B$7,"SẮP HẠN","TRONG HẠN"))))) | P18: 113/BK-2026 | S18: Tiến độ: Hoàn thành | Ngày bắt đầu: 2026-03-10 00:00:00 | Ngày nộp: 2026-03-10 00:00:00 | Ngày HT: 2026-03-10 00:00:00 | Lần nộp: 0.0
A19: BK-HS-0016 | B19: 46091 | C19: Phòng Đo đạc | D19: Xác định diện tích | E19: Đỗ Thị Trang | F19: Công Ty | G19: zalo Victoria | H19: Tam Bình | I19: Lê Văn Dựng | J19: Không cần | L19: Hoàn thành | M19: 46094 | N19: =IF(M19="","",M19-TODAY()) | O19: =IF(A19="","",IF(L19="Hoàn thành","XONG",IF(L19="Đã hủy","HỦY",IF(N19<0,"QUÁ HẠN",IF(N19<=THIET_LAP!$B$7,"SẮP HẠN","TRONG HẠN"))))) | P19: 112/BK-2026 | S19: Tiến độ: Hoàn thành | Ngày bắt đầu: 2026-03-10 00:00:00 | Ngày nộp: 2026-03-10 00:00:00 | Ngày HT: 2026-03-10 00:00:00 | Lần nộp: 0.0
A20: BK-HS-0017 | B20: 46090 | C20: Phòng Đo đạc | D20: Đo GPS | E20: Nguyễn Doãn Tuấn | F20: Công Ty | H20: Long Phước | I20: Lê Văn Dựng | J20: Không cần | L20: Hoàn thành | M20: 46093 | N20: =IF(M20="","",M20-TODAY()) | O20: =IF(A20="","",IF(L20="Hoàn thành","XONG",IF(L20="Đã hủy","HỦY",IF(N20<0,"QUÁ HẠN",IF(N20<=THIET_LAP!$B$7,"SẮP HẠN","TRONG HẠN"))))) | P20: 111/BK-2026 | S20: Tiến độ: Hoàn thành | Ngày bắt đầu: 2026-03-09 00:00:00 | Ngày nộp: 2026-03-10 00:00:00 | Ngày HT: 2026-03-10 00:00:00 | Lần nộp: 1.0
A21: BK-HS-0018 | B21: 46090 | C21: Phòng Đo đạc | D21: Cấp sổ lần đầu | E21: Nguyễn Doãn Tuấn | F21: Công Ty | G21: 0979676897 | H21: Long Phước | I21: Tạ Khắc Tập | J21: Võ Tứ Hợp | L21: Hoàn thành | M21: 46093 | N21: =IF(M21="","",M21-TODAY()) | O21: =IF(A21="","",IF(L21="Hoàn thành","XONG",IF(L21="Đã hủy","HỦY",IF(N21<0,"QUÁ HẠN",IF(N21<=THIET_LAP!$B$7,"SẮP HẠN","TRONG HẠN"))))) | P21: 110/BK-2026 | S21: Tiến độ: Hoàn thành | Ngày bắt đầu: 2026-03-09 00:00:00 | Ngày nộp: 2026-03-11 00:00:00 | Ngày HT: 2026-03-11 00:00:00 | Lần nộp: 1.0 | Ghi chú: BAO CAO GPS
A22: BK-HS-0019 | B22: 46090 | C22: Phòng Đo đạc | D22: Đo GPS | E22: Đỗ Bình Trọng | F22: Anh Hoàng nhà đầu tư | H22: Long Trường | I22: Lê Văn Dựng | J22: Không cần | L22: Hoàn thành | M22: 46093 | N22: =IF(M22="","",M22-TODAY()) | O22: =IF(A22="","",IF(L22="Hoàn thành","XONG",IF(L22="Đã hủy","HỦY",IF(N22<0,"QUÁ HẠN",IF(N22<=THIET_LAP!$B$7,"SẮP HẠN","TRONG HẠN"))))) | P22: 109/BK-2026 | S22: Tiến độ: Hoàn thành | Ngày bắt đầu: 2026-03-09 00:00:00 | Ngày nộp: 2026-03-09 00:00:00 | Ngày HT: 2026-03-09 00:00:00 | Lần nộp: 1.0
A23: BK-HS-0020 | B23: 46090 | C23: Phòng Đo đạc | D23: Cấp đổi | E23: Đỗ Bình Trọng | F23: Anh Hoàng Nhà Đầu Tư | H23: Long Trường | I23: Lê Văn Dựng | J23: Không cần | K23: Cao | L23: Nộp thành công - Chờ kết quả | M23: 46091 | N23: =IF(M23="","",M23-TODAY()) | O23: =IF(A23="","",IF(L23="Hoàn thành","XONG",IF(L23="Đã hủy","HỦY",IF(N23<0,"QUÁ HẠN",IF(N23<=THIET_LAP!$B$7,"SẮP HẠN","TRONG HẠN"))))) | P23: 108/BK-2026 | S23: Tiến độ: Đã nộp | Ngày bắt đầu: 2026-03-09 00:00:00 | Ngày nộp: 2026-03-10 00:00:00 | Lần nộp: 1.0
A24: BK-HS-0021 | B24: 46088 | C24: Phòng Đo đạc | D24: Xin phép xây dựng | E24: Bùi Đình Khánh | F24: Công Ty | G24: 0988737070 | H24: Tăng Nhơn Phú | I24: Võ Tứ Hợp | J24: Không cần | L24: Hủy | M24: 46091 | N24: =IF(M24="","",M24-TODAY()) | O24: =IF(A24="","",IF(L24="Hoàn thành","XONG",IF(L24="Đã hủy","HỦY",IF(N24<0,"QUÁ HẠN",IF(N24<=THIET_LAP!$B$7,"SẮP HẠN","TRONG HẠN"))))) | P24: 107/BK-2026 | S24: Tiến độ: ĐÃ HỦY | Ngày bắt đầu: 2026-03-07 00:00:00 | Ngày nộp: 2026-03-07 00:00:00 | Lần nộp: 0.0
A25: BK-HS-0022 | B25: 46087 | C25: Phòng Đo đạc | D25: Hoàn công | E25: Trần Phi Long | F25: Công Ty | G25: 0908449238 | H25: Tam Bình | I25: Lê Văn Xây | J25: Võ Tứ Hợp | L25: Nộp thành công - Chờ kết quả | M25: 46090 | N25: =IF(M25="","",M25-TODAY()) | O25: =IF(A25="","",IF(L25="Hoàn thành","XONG",IF(L25="Đã hủy","HỦY",IF(N25<0,"QUÁ HẠN",IF(N25<=THIET_LAP!$B$7,"SẮP HẠN","TRONG HẠN"))))) | P25: 106/BK-2026 | S25: Tiến độ: Đã nộp | Ngày bắt đầu: 2026-03-06 00:00:00 | Ngày nộp: 2026-03-12 00:00:00 | Lần nộp: 0.0
A26: BK-HS-0023 | B26: 46086 | C26: Phòng Đo đạc | D26: Cắm mốc | E26: Phạm Thị Giao Linh | F26: Tùng Huế DV | H26: Bình Trưng | I26: Lê Văn Dựng | J26: Võ Tứ Hợp | L26: Hoàn thành | M26: 46089 | N26: =IF(M26="","",M26-TODAY()) | O26: =IF(A26="","",IF(L26="Hoàn thành","XONG",IF(L26="Đã hủy","HỦY",IF(N26<0,"QUÁ HẠN",IF(N26<=THIET_LAP!$B$7,"SẮP HẠN","TRONG HẠN"))))) | P26: 105/BK-2026 | S26: Tiến độ: Hoàn thành | Ngày bắt đầu: 2026-03-05 00:00:00 | Ngày nộp: 2026-03-05 00:00:00 | Ngày HT: 2026-03-05 00:00:00 | Lần nộp: 0.0 | Số cọc: 6.0 | Loại cọc: Trụ xi măng
A27: BK-HS-0024 | B27: 46085 | C27: Phòng Đo đạc | D27: Cấp sổ lần đầu | E27: Trương Quế Phương | F27: Công Ty | G27: 0903880063 | H27: Hiệp Bình | I27: Trương Tấn Quốc | J27: Võ Tứ Hợp | L27: Hoàn thành | M27: 46088 | N27: =IF(M27="","",M27-TODAY()) | O27: =IF(A27="","",IF(L27="Hoàn thành","XONG",IF(L27="Đã hủy","HỦY",IF(N27<0,"QUÁ HẠN",IF(N27<=THIET_LAP!$B$7,"SẮP HẠN","TRONG HẠN"))))) | P27: 104/BK-2026 | S27: Tiến độ: Hoàn thành | Ngày bắt đầu: 2026-03-04 00:00:00 | Ngày nộp: 2026-03-05 00:00:00 | Ngày HT: 2026-03-05 00:00:00 | Lần nộp: 0.0 | Ghi chú: Lúc trước đã hủy, giờ vẽ nộp phường
A28: BK-HS-0025 | B28: 46085 | C28: Phòng Đo đạc | D28: Cắm mốc | E28: Đỗ Thị Trang | F28: Công Ty | G28: 0977633333 | H28: Tam Bình | I28: Lê Văn Dựng | J28: Võ Tứ Hợp | L28: Hoàn thành | M28: 46088 | N28: =IF(M28="","",M28-TODAY()) | O28: =IF(A28="","",IF(L28="Hoàn thành","XONG",IF(L28="Đã hủy","HỦY",IF(N28<0,"QUÁ HẠN",IF(N28<=THIET_LAP!$B$7,"SẮP HẠN","TRONG HẠN"))))) | P28: 103/BK-2026 | S28: Tiến độ: Hoàn thành | Ngày bắt đầu: 2026-03-04 00:00:00 | Ngày nộp: 2026-03-05 00:00:00 | Ngày HT: 2026-03-05 00:00:00 | Lần nộp: 1.0
A29: BK-HS-0026 | B29: 46085 | C29: Phòng Đo đạc | D29: Xác định diện tích | E29: Bùi Đình Khánh-Nguyễn Thị Kim Quyên | F29: Công Ty | G29: 0988737070 | H29: Tăng Nhơn Phú | I29: Trương Tấn Quốc | J29: Không cần | L29: Hoàn thành | M29: 46088 | N29: =IF(M29="","",M29-TODAY()) | O29: =IF(A29="","",IF(L29="Hoàn thành","XONG",IF(L29="Đã hủy","HỦY",IF(N29<0,"QUÁ HẠN",IF(N29<=THIET_LAP!$B$7,"SẮP HẠN","TRONG HẠN"))))) | P29: 102/BK-2026 | S29: Tiến độ: Hoàn thành | Ngày bắt đầu: 2026-03-04 00:00:00 | Ngày nộp: 2026-03-04 00:00:00 | Ngày HT: 2026-03-04 00:00:00 | Lần nộp: 1.0
A30: BK-HS-0027 | B30: 46085 | C30: Phòng Đo đạc | D30: Xác định diện tích | E30: Lê Quang Thạnh | F30: Công Ty | G30: 0989698007 | H30: Bình Trưng | I30: Lê Văn Dựng | J30: Không cần | L30: Hoàn thành | M30: 46088 | N30: =IF(M30="","",M30-TODAY()) | O30: =IF(A30="","",IF(L30="Hoàn thành","XONG",IF(L30="Đã hủy","HỦY",IF(N30<0,"QUÁ HẠN",IF(N30<=THIET_LAP!$B$7,"SẮP HẠN","TRONG HẠN"))))) | P30: 101/BK-2026 | S30: Tiến độ: Hoàn thành | Ngày bắt đầu: 2026-03-04 00:00:00 | Ngày nộp: 2026-03-05 00:00:00 | Ngày HT: 2026-03-05 00:00:00 | Lần nộp: 0.0 | Ghi chú: hồ sơ cấp đổi lấn thửa chủ nhà yêu cầu vẽ XDDT để đưa lên phường trình bày
A31: BK-HS-0028 | B31: 46085 | C31: Phòng Đo đạc | D31: Hoàn công | E31: Tô Thị MỸ Nương | F31: Tuấn Lộc | H31: Cát Lái | I31: Tạ Khắc Tập | J31: Võ Tứ Hợp | L31: Nộp thành công - Chờ kết quả | M31: 46088 | N31: =IF(M31="","",M31-TODAY()) | O31: =IF(A31="","",IF(L31="Hoàn thành","XONG",IF(L31="Đã hủy","HỦY",IF(N31<0,"QUÁ HẠN",IF(N31<=THIET_LAP!$B$7,"SẮP HẠN","TRONG HẠN"))))) | P31: 100/BK-2026 | S31: Tiến độ: Đã nộp | Ngày bắt đầu: 2026-03-04 00:00:00 | Ngày nộp: 2026-03-07 00:00:00 | Lần nộp: 1.0 | Giải trình: GIAM DT+ VE THEO GPXD
A32: BK-HS-0029 | B32: 46085 | C32: Phòng Đo đạc | D32: Hoàn công | E32: Phan Trong Quang | F32: Công Ty | H32: Long Phước | I32: Tạ Khắc Tập | J32: Võ Tứ Hợp | L32: QUÁ HẠN | M32: 46088 | N32: =IF(M32="","",M32-TODAY()) | O32: =IF(A32="","",IF(L32="Hoàn thành","XONG",IF(L32="Đã hủy","HỦY",IF(N32<0,"QUÁ HẠN",IF(N32<=THIET_LAP!$B$7,"SẮP HẠN","TRONG HẠN"))))) | P32: 099/BK-2026 | S32: Tiến độ: QUÁ HẠN | Ngày bắt đầu: 2026-03-04 00:00:00 | Lần nộp: 1.0 | Giải trình: SAI HIEN TRANG+ GIAY PHEP XD KO ĐÚNG BVXP CHỜ CHU NHÀ RA PHUONG DDIEU CHINH GPXD
A33: BK-HS-0030 | B33: 46085 | C33: Phòng Đo đạc | D33: Cắm mốc | E33: Nguyễn Thị Cẩm Vân | F33: Công Ty | H33: Long Phước | I33: Lê Văn Dựng | J33: Không cần | L33: Hoàn thành | M33: 46088 | N33: =IF(M33="","",M33-TODAY()) | O33: =IF(A33="","",IF(L33="Hoàn thành","XONG",IF(L33="Đã hủy","HỦY",IF(N33<0,"QUÁ HẠN",IF(N33<=THIET_LAP!$B$7,"SẮP HẠN","TRONG HẠN"))))) | P33: 098/BK-2026 | S33: Tiến độ: Hoàn thành | Ngày bắt đầu: 2026-03-04 00:00:00 | Ngày nộp: 2026-03-04 00:00:00 | Ngày HT: 2026-03-04 00:00:00 | Lần nộp: 1.0
A34: BK-HS-0031 | B34: 46084 | C34: Phòng Đo đạc | D34: Hoàn công | E34: Nguyễn Thị Ngọc Thuận | F34: Tuấn Lộc | H34: Long Trường | I34: Lê Văn Xây | J34: Võ Tứ Hợp | L34: QUÁ HẠN | M34: 46087 | N34: =IF(M34="","",M34-TODAY()) | O34: =IF(A34="","",IF(L34="Hoàn thành","XONG",IF(L34="Đã hủy","HỦY",IF(N34<0,"QUÁ HẠN",IF(N34<=THIET_LAP!$B$7,"SẮP HẠN","TRONG HẠN"))))) | P34: 097/BK-2026 | S34: Tiến độ: QUÁ HẠN | Ngày bắt đầu: 2026-03-03 00:00:00 | Lần nộp: 1.0
A35: BK-HS-0032 | B35: 46084 | C35: Phòng Đo đạc | D35: Cấp đổi | E35: Nguyễn Quốc Chiến-Trần Thị Thu Hương | F35: Công Ty | G35: 0989035122 | H35: An Khánh | I35: Trương Tấn Quốc | J35: Võ Tứ Hợp | L35: Nộp thành công - Chờ kết quả | M35: 46087 | N35: =IF(M35="","",M35-TODAY()) | O35: =IF(A35="","",IF(L35="Hoàn thành","XONG",IF(L35="Đã hủy","HỦY",IF(N35<0,"QUÁ HẠN",IF(N35<=THIET_LAP!$B$7,"SẮP HẠN","TRONG HẠN"))))) | P35: 096/BK-2026 | S35: Tiến độ: Đã nộp | Ngày bắt đầu: 2026-03-03 00:00:00 | Ngày nộp: 2026-03-06 00:00:00 | Lần nộp: 1.0
A36: BK-HS-0033 | B36: 46083 | C36: Phòng Đo đạc | D36: Cấp sổ lần đầu | E36: Nguyễn Hoàng Tấn | F36: Nguyễn Tâm DV | H36: Hiệp Bình | I36: Tạ Khắc Tập | J36: Lê Tấn Đạt | L36: Hoàn thành | M36: 46086 | N36: =IF(M36="","",M36-TODAY()) | O36: =IF(A36="","",IF(L36="Hoàn thành","XONG",IF(L36="Đã hủy","HỦY",IF(N36<0,"QUÁ HẠN",IF(N36<=THIET_LAP!$B$7,"SẮP HẠN","TRONG HẠN"))))) | P36: 095/BK-2026 | S36: Tiến độ: Hoàn thành | Ngày bắt đầu: 2026-03-02 00:00:00 | Ngày nộp: 2026-03-04 00:00:00 | Ngày HT: 2026-03-04 00:00:00 | Lần nộp: 1.0
A37: BK-HS-0034 | B37: 46080 | C37: Phòng Đo đạc | D37: Cấp đổi | E37: Lê Quang Thạnh | F37: Công Ty | G37: 0918393071 | H37: Bình Trưng | I37: Lê Văn Dựng | J37: Võ Tứ Hợp | L37: QUÁ HẠN | M37: 46083 | N37: =IF(M37="","",M37-TODAY()) | O37: =IF(A37="","",IF(L37="Hoàn thành","XONG",IF(L37="Đã hủy","HỦY",IF(N37<0,"QUÁ HẠN",IF(N37<=THIET_LAP!$B$7,"SẮP HẠN","TRONG HẠN"))))) | P37: 094/BK-2026 | S37: Tiến độ: QUÁ HẠN | Ngày bắt đầu: 2026-02-27 00:00:00 | Lần nộp: 1.0 | Ghi chú: Đợi chủ nhà đập hàng rào
A38: BK-HS-0035 | B38: 46080 | C38: Phòng Đo đạc | D38: Cắm mốc | E38: Thái Thị Bích Vân | F38: Anh Duẩn DV | H38: Hiệp Bình | I38: Lê Văn Dựng | J38: Võ Tứ Hợp | L38: Hoàn thành | M38: 46083 | N38: =IF(M38="","",M38-TODAY()) | O38: =IF(A38="","",IF(L38="Hoàn thành","XONG",IF(L38="Đã hủy","HỦY",IF(N38<0,"QUÁ HẠN",IF(N38<=THIET_LAP!$B$7,"SẮP HẠN","TRONG HẠN"))))) | P38: 093/BK-2026 | S38: Tiến độ: Hoàn thành | Ngày bắt đầu: 2026-02-27 00:00:00 | Ngày nộp: 2026-02-28 00:00:00 | Ngày HT: 2026-02-28 00:00:00 | Lần nộp: 1.0 | Chi kỹ thuật: Đã thanh toán | Loại cọc: Cọc sắt
A39: BK-HS-0036 | B39: 46080 | C39: Phòng Đo đạc | D39: Điều chỉnh bản vẽ | E39: Phạm Thị Giao Linh | F39: Tùng Huế DV | H39: Bình Trưng | I39: Trương Tấn Quốc | J39: Không cần | L39: Nộp thành công - Chờ kết quả | M39: 46083 | N39: =IF(M39="","",M39-TODAY()) | O39: =IF(A39="","",IF(L39="Hoàn thành","XONG",IF(L39="Đã hủy","HỦY",IF(N39<0,"QUÁ HẠN",IF(N39<=THIET_LAP!$B$7,"SẮP HẠN","TRONG HẠN"))))) | P39: 092/BK-2026 | S39: Tiến độ: Đã nộp | Ngày bắt đầu: 2026-02-27 00:00:00 | Ngày nộp: 2026-03-16 00:00:00 | Lần nộp: 1.0 | Ghi chú: Cần cắm lại trụ
A40: BK-HS-0037 | B40: 46080 | C40: Phòng Đo đạc | D40: Điều chỉnh bản vẽ | E40: Tôn Phượng Nga | F40: Công Ty | G40: 0909256563 | H40: Long Phước | I40: Trương Tấn Quốc | J40: Không cần | L40: QUÁ HẠN | M40: 46083 | N40: =IF(M40="","",M40-TODAY()) | O40: =IF(A40="","",IF(L40="Hoàn thành","XONG",IF(L40="Đã hủy","HỦY",IF(N40<0,"QUÁ HẠN",IF(N40<=THIET_LAP!$B$7,"SẮP HẠN","TRONG HẠN"))))) | P40: 091/BK-2026 | S40: Tiến độ: QUÁ HẠN | Ngày bắt đầu: 2026-02-27 00:00:00 | Lần nộp: 1.0 | Ghi chú: Cần cắm lại trụ | Giải trình: Đợi làm việc với phường
...

Sheet DATABASE_TASK
A1: DATABASE TASK
A2: Bảng giao việc liên phòng. Mỗi task là 1 đầu việc.
A3: Mã task | B3: Mã hồ sơ | C3: Phòng ban | D3: Tên công việc | E3: Người giao | F3: Người nhận | G3: Ngày giao | H3: Deadline | I3: Ưu tiên | J3: Trạng thái | K3: Kết quả | L3: Quá hạn? | M3: Ngày hoàn thành | N3: Ghi chú
A4: BK-TSK-0001 | B4: BK-HS-0001 | C4: Phòng Đo đạc | D4: Xin phép xây dựng | E4: Giám đốc | F4: Võ Thành Minh | G4: 46097 | H4: 46100 | J4: Trong hạn | K4: Trong hạn | L4: =IF(OR(H4="",J4="Hoàn thành",J4="Đã hủy"),"",IF(H4<TODAY(),"QUÁ HẠN",IF(H4-TODAY()<=THIET_LAP!$B$8,"SẮP HẠN","TRONG HẠN")))
A5: BK-TSK-0002 | B5: BK-HS-0002 | C5: Phòng Đo đạc | D5: Cấp đổi | E5: Giám đốc | F5: Trương Tấn Quốc | G5: 46094 | H5: 46097 | J5: Trong hạn | K5: Trong hạn | L5: =IF(OR(H5="",J5="Hoàn thành",J5="Đã hủy"),"",IF(H5<TODAY(),"QUÁ HẠN",IF(H5-TODAY()<=THIET_LAP!$B$8,"SẮP HẠN","TRONG HẠN"))) | N5: Đợi trao đổi với dịch vụ
A6: BK-TSK-0003 | B6: BK-HS-0003 | C6: Phòng Đo đạc | D6: Hoàn công | E6: Giám đốc | F6: Lê Văn Xây | G6: 46094 | H6: 46097 | J6: Nộp thành công - Chờ kết quả | K6: Đã nộp | L6: =IF(OR(H6="",J6="Hoàn thành",J6="Đã hủy"),"",IF(H6<TODAY(),"QUÁ HẠN",IF(H6-TODAY()<=THIET_LAP!$B$8,"SẮP HẠN","TRONG HẠN")))
A7: BK-TSK-0004 | B7: BK-HS-0004 | C7: Phòng Đo đạc | D7: Cấp đổi | E7: Giám đốc | F7: Tạ Khắc Tập | G7: 46094 | H7: 46097 | J7: Nộp thành công - Chờ kết quả | K7: Đã nộp | L7: =IF(OR(H7="",J7="Hoàn thành",J7="Đã hủy"),"",IF(H7<TODAY(),"QUÁ HẠN",IF(H7-TODAY()<=THIET_LAP!$B$8,"SẮP HẠN","TRONG HẠN")))
A8: BK-TSK-0005 | B8: BK-HS-0005 | C8: Phòng Đo đạc | D8: Cấp đổi | E8: Giám đốc | F8: Tạ Khắc Tập | G8: 46094 | H8: 46097 | J8: Nộp thành công - Chờ kết quả | K8: Đã nộp | L8: =IF(OR(H8="",J8="Hoàn thành",J8="Đã hủy"),"",IF(H8<TODAY(),"QUÁ HẠN",IF(H8-TODAY()<=THIET_LAP!$B$8,"SẮP HẠN","TRONG HẠN")))
A9: BK-TSK-0006 | B9: BK-HS-0006 | C9: Phòng Đo đạc | D9: Cắm mốc | E9: Giám đốc | F9: Tạ Khắc Tập | G9: 46094 | H9: 46097 | J9: Hoàn thành | K9: Hoàn thành | L9: =IF(OR(H9="",J9="Hoàn thành",J9="Đã hủy"),"",IF(H9<TODAY(),"QUÁ HẠN",IF(H9-TODAY()<=THIET_LAP!$B$8,"SẮP HẠN","TRONG HẠN"))) | M9: 46094
A10: BK-TSK-0007 | B10: BK-HS-0007 | C10: Phòng Đo đạc | D10: Cấp đổi | E10: Giám đốc | F10: Lê Văn Dựng | G10: 46093 | H10: 46096 | J10: QUÁ HẠN | K10: QUÁ HẠN | L10: =IF(OR(H10="",J10="Hoàn thành",J10="Đã hủy"),"",IF(H10<TODAY(),"QUÁ HẠN",IF(H10-TODAY()<=THIET_LAP!$B$8,"SẮP HẠN","TRONG HẠN"))) | N10: hồ sơ lệch ranh chờ pa
A11: BK-TSK-0008 | B11: BK-HS-0008 | C11: Phòng Đo đạc | D11: Hoàn công | E11: Giám đốc | F11: Lê Văn Dựng | G11: 46093 | H11: 46096 | J11: QUÁ HẠN | K11: QUÁ HẠN | L11: =IF(OR(H11="",J11="Hoàn thành",J11="Đã hủy"),"",IF(H11<TODAY(),"QUÁ HẠN",IF(H11-TODAY()<=THIET_LAP!$B$8,"SẮP HẠN","TRONG HẠN")))
A12: BK-TSK-0009 | B12: BK-HS-0009 | C12: Phòng Đo đạc | D12: Xác định diện tích | E12: Giám đốc | F12: Lê Văn Xây | G12: 46092 | H12: 46095 | J12: QUÁ HẠN | K12: QUÁ HẠN | L12: =IF(OR(H12="",J12="Hoàn thành",J12="Đã hủy"),"",IF(H12<TODAY(),"QUÁ HẠN",IF(H12-TODAY()<=THIET_LAP!$B$8,"SẮP HẠN","TRONG HẠN")))
A13: BK-TSK-0010 | B13: BK-HS-0010 | C13: Phòng Đo đạc | D13: Hoàn công | E13: Giám đốc | F13: Lê Văn Xây | G13: 46092 | H13: 46095 | J13: QUÁ HẠN | K13: QUÁ HẠN | L13: =IF(OR(H13="",J13="Hoàn thành",J13="Đã hủy"),"",IF(H13<TODAY(),"QUÁ HẠN",IF(H13-TODAY()<=THIET_LAP!$B$8,"SẮP HẠN","TRONG HẠN")))
A14: BK-TSK-0011 | B14: BK-HS-0011 | C14: Phòng Đo đạc | D14: Cấp đổi | E14: Giám đốc | F14: Trương Tấn Quốc | G14: 46092 | H14: 46095 | J14: Nộp thành công - Chờ kết quả | K14: Đã nộp | L14: =IF(OR(H14="",J14="Hoàn thành",J14="Đã hủy"),"",IF(H14<TODAY(),"QUÁ HẠN",IF(H14-TODAY()<=THIET_LAP!$B$8,"SẮP HẠN","TRONG HẠN"))) | N14: Cần cắm mốc | Đợi trích lục
A15: BK-TSK-0012 | B15: BK-HS-0012 | C15: Phòng Đo đạc | D15: Cắm mốc | E15: Giám đốc | F15: Tạ Khắc Tập | G15: 46091 | H15: 46094 | J15: Hoàn thành | K15: Hoàn thành | L15: =IF(OR(H15="",J15="Hoàn thành",J15="Đã hủy"),"",IF(H15<TODAY(),"QUÁ HẠN",IF(H15-TODAY()<=THIET_LAP!$B$8,"SẮP HẠN","TRONG HẠN"))) | M15: 46091
A16: BK-TSK-0013 | B16: BK-HS-0013 | C16: Phòng Đo đạc | D16: Chuyển mục đích | E16: Giám đốc | F16: Lê Văn Xây | G16: 46091 | H16: 46094 | J16: QUÁ HẠN | K16: QUÁ HẠN | L16: =IF(OR(H16="",J16="Hoàn thành",J16="Đã hủy"),"",IF(H16<TODAY(),"QUÁ HẠN",IF(H16-TODAY()<=THIET_LAP!$B$8,"SẮP HẠN","TRONG HẠN")))
A17: BK-TSK-0014 | B17: BK-HS-0014 | C17: Phòng Đo đạc | D17: Cắm mốc | E17: Giám đốc | F17: Tạ Khắc Tập | G17: 46091 | H17: 46094 | J17: Hoàn thành | K17: Hoàn thành | L17: =IF(OR(H17="",J17="Hoàn thành",J17="Đã hủy"),"",IF(H17<TODAY(),"QUÁ HẠN",IF(H17-TODAY()<=THIET_LAP!$B$8,"SẮP HẠN","TRONG HẠN"))) | M17: 46091
A18: BK-TSK-0015 | B18: BK-HS-0015 | C18: Phòng Đo đạc | D18: Xác định diện tích | E18: Giám đốc | F18: Lê Văn Dựng | G18: 46091 | H18: 46094 | J18: Hoàn thành | K18: Hoàn thành | L18: =IF(OR(H18="",J18="Hoàn thành",J18="Đã hủy"),"",IF(H18<TODAY(),"QUÁ HẠN",IF(H18-TODAY()<=THIET_LAP!$B$8,"SẮP HẠN","TRONG HẠN"))) | M18: 46091
A19: BK-TSK-0016 | B19: BK-HS-0016 | C19: Phòng Đo đạc | D19: Xác định diện tích | E19: Giám đốc | F19: Lê Văn Dựng | G19: 46091 | H19: 46094 | J19: Hoàn thành | K19: Hoàn thành | L19: =IF(OR(H19="",J19="Hoàn thành",J19="Đã hủy"),"",IF(H19<TODAY(),"QUÁ HẠN",IF(H19-TODAY()<=THIET_LAP!$B$8,"SẮP HẠN","TRONG HẠN"))) | M19: 46091
A20: BK-TSK-0017 | B20: BK-HS-0017 | C20: Phòng Đo đạc | D20: Đo GPS | E20: Giám đốc | F20: Lê Văn Dựng | G20: 46090 | H20: 46093 | J20: Hoàn thành | K20: Hoàn thành | L20: =IF(OR(H20="",J20="Hoàn thành",J20="Đã hủy"),"",IF(H20<TODAY(),"QUÁ HẠN",IF(H20-TODAY()<=THIET_LAP!$B$8,"SẮP HẠN","TRONG HẠN"))) | M20: 46091
A21: BK-TSK-0018 | B21: BK-HS-0018 | C21: Phòng Đo đạc | D21: Cấp sổ lần đầu | E21: Giám đốc | F21: Tạ Khắc Tập | G21: 46090 | H21: 46093 | J21: Hoàn thành | K21: Hoàn thành | L21: =IF(OR(H21="",J21="Hoàn thành",J21="Đã hủy"),"",IF(H21<TODAY(),"QUÁ HẠN",IF(H21-TODAY()<=THIET_LAP!$B$8,"SẮP HẠN","TRONG HẠN"))) | M21: 46092 | N21: BAO CAO GPS
A22: BK-TSK-0019 | B22: BK-HS-0019 | C22: Phòng Đo đạc | D22: Đo GPS | E22: Giám đốc | F22: Lê Văn Dựng | G22: 46090 | H22: 46093 | J22: Hoàn thành | K22: Hoàn thành | L22: =IF(OR(H22="",J22="Hoàn thành",J22="Đã hủy"),"",IF(H22<TODAY(),"QUÁ HẠN",IF(H22-TODAY()<=THIET_LAP!$B$8,"SẮP HẠN","TRONG HẠN"))) | M22: 46090
A23: BK-TSK-0020 | B23: BK-HS-0020 | C23: Phòng Đo đạc | D23: Cấp đổi | E23: Giám đốc | F23: Lê Văn Dựng | G23: 46090 | H23: 46091 | I23: Cao | J23: Nộp thành công - Chờ kết quả | K23: Đã nộp | L23: =IF(OR(H23="",J23="Hoàn thành",J23="Đã hủy"),"",IF(H23<TODAY(),"QUÁ HẠN",IF(H23-TODAY()<=THIET_LAP!$B$8,"SẮP HẠN","TRONG HẠN")))
A24: BK-TSK-0021 | B24: BK-HS-0021 | C24: Phòng Đo đạc | D24: Xin phép xây dựng | E24: Giám đốc | F24: Võ Tứ Hợp | G24: 46088 | H24: 46091 | J24: Hủy | K24: ĐÃ HỦY | L24: =IF(OR(H24="",J24="Hoàn thành",J24="Đã hủy"),"",IF(H24<TODAY(),"QUÁ HẠN",IF(H24-TODAY()<=THIET_LAP!$B$8,"SẮP HẠN","TRONG HẠN")))
A25: BK-TSK-0022 | B25: BK-HS-0022 | C25: Phòng Đo đạc | D25: Hoàn công | E25: Giám đốc | F25: Lê Văn Xây | G25: 46087 | H25: 46090 | J25: Nộp thành công - Chờ kết quả | K25: Đã nộp | L25: =IF(OR(H25="",J25="Hoàn thành",J25="Đã hủy"),"",IF(H25<TODAY(),"QUÁ HẠN",IF(H25-TODAY()<=THIET_LAP!$B$8,"SẮP HẠN","TRONG HẠN")))
A26: BK-TSK-0023 | B26: BK-HS-0023 | C26: Phòng Đo đạc | D26: Cắm mốc | E26: Giám đốc | F26: Lê Văn Dựng | G26: 46086 | H26: 46089 | J26: Hoàn thành | K26: Hoàn thành | L26: =IF(OR(H26="",J26="Hoàn thành",J26="Đã hủy"),"",IF(H26<TODAY(),"QUÁ HẠN",IF(H26-TODAY()<=THIET_LAP!$B$8,"SẮP HẠN","TRONG HẠN"))) | M26: 46086
A27: BK-TSK-0024 | B27: BK-HS-0024 | C27: Phòng Đo đạc | D27: Cấp sổ lần đầu | E27: Giám đốc | F27: Trương Tấn Quốc | G27: 46085 | H27: 46088 | J27: Hoàn thành | K27: Hoàn thành | L27: =IF(OR(H27="",J27="Hoàn thành",J27="Đã hủy"),"",IF(H27<TODAY(),"QUÁ HẠN",IF(H27-TODAY()<=THIET_LAP!$B$8,"SẮP HẠN","TRONG HẠN"))) | M27: 46086 | N27: Lúc trước đã hủy, giờ vẽ nộp phường
A28: BK-TSK-0025 | B28: BK-HS-0025 | C28: Phòng Đo đạc | D28: Cắm mốc | E28: Giám đốc | F28: Lê Văn Dựng | G28: 46085 | H28: 46088 | J28: Hoàn thành | K28: Hoàn thành | L28: =IF(OR(H28="",J28="Hoàn thành",J28="Đã hủy"),"",IF(H28<TODAY(),"QUÁ HẠN",IF(H28-TODAY()<=THIET_LAP!$B$8,"SẮP HẠN","TRONG HẠN"))) | M28: 46086
A29: BK-TSK-0026 | B29: BK-HS-0026 | C29: Phòng Đo đạc | D29: Xác định diện tích | E29: Giám đốc | F29: Trương Tấn Quốc | G29: 46085 | H29: 46088 | J29: Hoàn thành | K29: Hoàn thành | L29: =IF(OR(H29="",J29="Hoàn thành",J29="Đã hủy"),"",IF(H29<TODAY(),"QUÁ HẠN",IF(H29-TODAY()<=THIET_LAP!$B$8,"SẮP HẠN","TRONG HẠN"))) | M29: 46085
A30: BK-TSK-0027 | B30: BK-HS-0027 | C30: Phòng Đo đạc | D30: Xác định diện tích | E30: Giám đốc | F30: Lê Văn Dựng | G30: 46085 | H30: 46088 | J30: Hoàn thành | K30: Hoàn thành | L30: =IF(OR(H30="",J30="Hoàn thành",J30="Đã hủy"),"",IF(H30<TODAY(),"QUÁ HẠN",IF(H30-TODAY()<=THIET_LAP!$B$8,"SẮP HẠN","TRONG HẠN"))) | M30: 46086 | N30: hồ sơ cấp đổi lấn thửa chủ nhà yêu cầu vẽ XDDT để đưa lên phường trình bày
A31: BK-TSK-0028 | B31: BK-HS-0028 | C31: Phòng Đo đạc | D31: Hoàn công | E31: Giám đốc | F31: Tạ Khắc Tập | G31: 46085 | H31: 46088 | J31: Nộp thành công - Chờ kết quả | K31: Đã nộp | L31: =IF(OR(H31="",J31="Hoàn thành",J31="Đã hủy"),"",IF(H31<TODAY(),"QUÁ HẠN",IF(H31-TODAY()<=THIET_LAP!$B$8,"SẮP HẠN","TRONG HẠN"))) | N31: GIAM DT+ VE THEO GPXD
A32: BK-TSK-0029 | B32: BK-HS-0029 | C32: Phòng Đo đạc | D32: Hoàn công | E32: Giám đốc | F32: Tạ Khắc Tập | G32: 46085 | H32: 46088 | J32: QUÁ HẠN | K32: QUÁ HẠN | L32: =IF(OR(H32="",J32="Hoàn thành",J32="Đã hủy"),"",IF(H32<TODAY(),"QUÁ HẠN",IF(H32-TODAY()<=THIET_LAP!$B$8,"SẮP HẠN","TRONG HẠN"))) | N32: SAI HIEN TRANG+ GIAY PHEP XD KO ĐÚNG BVXP CHỜ CHU NHÀ RA PHUONG DDIEU CHINH GPXD
A33: BK-TSK-0030 | B33: BK-HS-0030 | C33: Phòng Đo đạc | D33: Cắm mốc | E33: Giám đốc | F33: Lê Văn Dựng | G33: 46085 | H33: 46088 | J33: Hoàn thành | K33: Hoàn thành | L33: =IF(OR(H33="",J33="Hoàn thành",J33="Đã hủy"),"",IF(H33<TODAY(),"QUÁ HẠN",IF(H33-TODAY()<=THIET_LAP!$B$8,"SẮP HẠN","TRONG HẠN"))) | M33: 46085
A34: BK-TSK-0031 | B34: BK-HS-0031 | C34: Phòng Đo đạc | D34: Hoàn công | E34: Giám đốc | F34: Lê Văn Xây | G34: 46084 | H34: 46087 | J34: QUÁ HẠN | K34: QUÁ HẠN | L34: =IF(OR(H34="",J34="Hoàn thành",J34="Đã hủy"),"",IF(H34<TODAY(),"QUÁ HẠN",IF(H34-TODAY()<=THIET_LAP!$B$8,"SẮP HẠN","TRONG HẠN")))
A35: BK-TSK-0032 | B35: BK-HS-0032 | C35: Phòng Đo đạc | D35: Cấp đổi | E35: Giám đốc | F35: Trương Tấn Quốc | G35: 46084 | H35: 46087 | J35: Nộp thành công - Chờ kết quả | K35: Đã nộp | L35: =IF(OR(H35="",J35="Hoàn thành",J35="Đã hủy"),"",IF(H35<TODAY(),"QUÁ HẠN",IF(H35-TODAY()<=THIET_LAP!$B$8,"SẮP HẠN","TRONG HẠN")))
A36: BK-TSK-0033 | B36: BK-HS-0033 | C36: Phòng Đo đạc | D36: Cấp sổ lần đầu | E36: Giám đốc | F36: Tạ Khắc Tập | G36: 46083 | H36: 46086 | J36: Hoàn thành | K36: Hoàn thành | L36: =IF(OR(H36="",J36="Hoàn thành",J36="Đã hủy"),"",IF(H36<TODAY(),"QUÁ HẠN",IF(H36-TODAY()<=THIET_LAP!$B$8,"SẮP HẠN","TRONG HẠN"))) | M36: 46085
A37: BK-TSK-0034 | B37: BK-HS-0034 | C37: Phòng Đo đạc | D37: Cấp đổi | E37: Giám đốc | F37: Lê Văn Dựng | G37: 46080 | H37: 46083 | J37: QUÁ HẠN | K37: QUÁ HẠN | L37: =IF(OR(H37="",J37="Hoàn thành",J37="Đã hủy"),"",IF(H37<TODAY(),"QUÁ HẠN",IF(H37-TODAY()<=THIET_LAP!$B$8,"SẮP HẠN","TRONG HẠN"))) | N37: Đợi chủ nhà đập hàng rào
A38: BK-TSK-0035 | B38: BK-HS-0035 | C38: Phòng Đo đạc | D38: Cắm mốc | E38: Giám đốc | F38: Lê Văn Dựng | G38: 46080 | H38: 46083 | J38: Hoàn thành | K38: Hoàn thành | L38: =IF(OR(H38="",J38="Hoàn thành",J38="Đã hủy"),"",IF(H38<TODAY(),"QUÁ HẠN",IF(H38-TODAY()<=THIET_LAP!$B$8,"SẮP HẠN","TRONG HẠN"))) | M38: 46081
A39: BK-TSK-0036 | B39: BK-HS-0036 | C39: Phòng Đo đạc | D39: Điều chỉnh bản vẽ | E39: Giám đốc | F39: Trương Tấn Quốc | G39: 46080 | H39: 46083 | J39: Nộp thành công - Chờ kết quả | K39: Đã nộp | L39: =IF(OR(H39="",J39="Hoàn thành",J39="Đã hủy"),"",IF(H39<TODAY(),"QUÁ HẠN",IF(H39-TODAY()<=THIET_LAP!$B$8,"SẮP HẠN","TRONG HẠN"))) | N39: Cần cắm lại trụ
A40: BK-TSK-0037 | B40: BK-HS-0037 | C40: Phòng Đo đạc | D40: Điều chỉnh bản vẽ | E40: Giám đốc | F40: Trương Tấn Quốc | G40: 46080 | H40: 46083 | J40: QUÁ HẠN | K40: QUÁ HẠN | L40: =IF(OR(H40="",J40="Hoàn thành",J40="Đã hủy"),"",IF(H40<TODAY(),"QUÁ HẠN",IF(H40-TODAY()<=THIET_LAP!$B$8,"SẮP HẠN","TRONG HẠN"))) | N40: Cần cắm lại trụ | Đợi làm việc với phường
...

Sheet DATABASE_HOP_DONG
A1: DATABASE HỢP ĐỒNG & CÔNG NỢ
A2: Theo dõi hợp đồng, thanh toán và công nợ theo Mã hồ sơ.
A3: Mã hợp đồng | B3: Mã hồ sơ | C3: Tên khách hàng | D3: Phòng ban | E3: Dịch vụ | F3: Ngày ký | G3: Giá trị hợp đồng | H3: Đã thu | I3: Còn nợ | J3: Tình trạng | K3: Sale / nguồn | L3: Ngày đến hạn | M3: Ghi chú
A4: 488-2/BK-2025 | B4: BK-HS-0320 | C4: Nguyễn Hoàng Quân | D4: Phòng Đo đạc | E4: Đo GPS | F4: 45954 | G4: 1 | H4: 1 | I4: =IF(G4="","",G4-H4) | J4: =IF(A4="","",IF(I4<=0,"Đã tất toán",IF(L4<TODAY(),"Quá hạn","Còn nợ"))) | K4: Hoàng Quân
A5: 537/BK-2025 | B5: BK-HS-0319 | C5: Nguyễn Thanh Vũ | D5: Phòng Đo đạc | E5: Cấp đổi | F5: 45954 | G5: 39639491 | H5: 39639491 | I5: =IF(G5="","",G5-H5) | J5: =IF(A5="","",IF(I5<=0,"Đã tất toán",IF(L5<TODAY(),"Quá hạn","Còn nợ"))) | K5: Công Ty
A6: 538/BK-2025 | B6: BK-HS-0318 | C6: TRương Quế Phương | D6: Phòng Đo đạc | E6: Cắm mốc | F6: 45954 | G6: 2500000 | H6: 2500000 | I6: =IF(G6="","",G6-H6) | J6: =IF(A6="","",IF(I6<=0,"Đã tất toán",IF(L6<TODAY(),"Quá hạn","Còn nợ"))) | K6: Anh Chiến KTS
A7: 539/BK-2025 | B7: BK-HS-0317 | C7: Vũ Thị Hương Giang | D7: Phòng Đo đạc | E7: Hoàn công | F7: 45956 | G7: 35000000 | H7: 35000000 | I7: =IF(G7="","",G7-H7) | J7: =IF(A7="","",IF(I7<=0,"Đã tất toán",IF(L7<TODAY(),"Quá hạn","Còn nợ"))) | K7: Công Ty
A8: 541/BK-2025 | B8: BK-HS-0316 | C8: Nguyễn Tấn Thanh | D8: Phòng Đo đạc | E8: Tách Thửa | F8: 45956 | G8: 8000000 | H8: 8000000 | I8: =IF(G8="","",G8-H8) | J8: =IF(A8="","",IF(I8<=0,"Đã tất toán",IF(L8<TODAY(),"Quá hạn","Còn nợ"))) | K8: Chị Xuân DV
A9: 542/BK-2025 | B9: BK-HS-0315 | C9: Nguyễn Tấn Thanh | D9: Phòng Đo đạc | E9: Tách Thửa | F9: 45956 | G9: 8000000 | H9: 8000000 | I9: =IF(G9="","",G9-H9) | J9: =IF(A9="","",IF(I9<=0,"Đã tất toán",IF(L9<TODAY(),"Quá hạn","Còn nợ"))) | K9: Chị Xuân DV
A10: 540/BK-2025 | B10: BK-HS-0314 | C10: Phạm Thị Phương | D10: Phòng Đo đạc | E10: Cấp đổi | F10: 45957 | G10: 10000000 | H10: 10000000 | I10: =IF(G10="","",G10-H10) | J10: =IF(A10="","",IF(I10<=0,"Đã tất toán",IF(L10<TODAY(),"Quá hạn","Còn nợ"))) | K10: Nguyễn Khoa DV
A11: 543/BK-2025 | B11: BK-HS-0313 | C11: Trần Đức Phú | D11: Phòng Đo đạc | E11: Cấp đổi | F11: 45957 | H11: 0 | I11: =IF(G11="","",G11-H11) | J11: =IF(A11="","",IF(I11<=0,"Đã tất toán",IF(L11<TODAY(),"Quá hạn","Còn nợ"))) | K11: Hoàng Quân
A12: 543-1/BK-2025 | B12: BK-HS-0312 | C12: Trần Đức Phú | D12: Phòng Đo đạc | E12: Cắm mốc | F12: 45957 | G12: 3600000 | H12: 3600000 | I12: =IF(G12="","",G12-H12) | J12: =IF(A12="","",IF(I12<=0,"Đã tất toán",IF(L12<TODAY(),"Quá hạn","Còn nợ"))) | K12: Hoàng Quân
A13: 543-2/BK-2025 | B13: BK-HS-0311 | C13: Trần Đức Phú | D13: Phòng Đo đạc | E13: Đo GPS | F13: 45957 | G13: 1 | H13: 1 | I13: =IF(G13="","",G13-H13) | J13: =IF(A13="","",IF(I13<=0,"Đã tất toán",IF(L13<TODAY(),"Quá hạn","Còn nợ"))) | K13: Hoàng Quân
A14: 544/BK-2025 | B14: BK-HS-0310 | C14: Trần Đức Phú | D14: Phòng Đo đạc | E14: Cấp đổi | F14: 45957 | G14: 25000000 | H14: 0 | I14: =IF(G14="","",G14-H14) | J14: =IF(A14="","",IF(I14<=0,"Đã tất toán",IF(L14<TODAY(),"Quá hạn","Còn nợ"))) | K14: Hoàng Quân
A15: 544-1/BK-2025 | B15: BK-HS-0309 | C15: Trần Đức Phú | D15: Phòng Đo đạc | E15: Cắm mốc | F15: 45957 | G15: 3900000 | H15: 3900000 | I15: =IF(G15="","",G15-H15) | J15: =IF(A15="","",IF(I15<=0,"Đã tất toán",IF(L15<TODAY(),"Quá hạn","Còn nợ"))) | K15: Hoàng Quân
A16: 544-2/BK-2025 | B16: BK-HS-0308 | C16: Trần Đức Phú | D16: Phòng Đo đạc | E16: Đo GPS | F16: 45957 | G16: 1 | H16: 1 | I16: =IF(G16="","",G16-H16) | J16: =IF(A16="","",IF(I16<=0,"Đã tất toán",IF(L16<TODAY(),"Quá hạn","Còn nợ"))) | K16: Hoàng Quân
A17: 545/BK-2025 | B17: BK-HS-0307 | C17: Trần Quang Vinh | D17: Phòng Đo đạc | E17: Cắm mốc | F17: 45957 | G17: 3000000 | H17: 3000000 | I17: =IF(G17="","",G17-H17) | J17: =IF(A17="","",IF(I17<=0,"Đã tất toán",IF(L17<TODAY(),"Quá hạn","Còn nợ"))) | K17: Hoàng Quân
A18: 546/BK-2025 | B18: BK-HS-0306 | C18: Trần Quang Vinh | D18: Phòng Đo đạc | E18: Cắm mốc | F18: 45957 | G18: 3000000 | H18: 3000000 | I18: =IF(G18="","",G18-H18) | J18: =IF(A18="","",IF(I18<=0,"Đã tất toán",IF(L18<TODAY(),"Quá hạn","Còn nợ"))) | K18: Hoàng Quân
A19: 547/BK-2025 | B19: BK-HS-0305 | C19: Trần Quang Vinh | D19: Phòng Đo đạc | E19: Cắm mốc | F19: 45957 | G19: 3000000 | H19: 3000000 | I19: =IF(G19="","",G19-H19) | J19: =IF(A19="","",IF(I19<=0,"Đã tất toán",IF(L19<TODAY(),"Quá hạn","Còn nợ"))) | K19: Hoàng Quân
A20: 548/BK-2025 | B20: BK-HS-0304 | C20: Ngô Thanh Quyền | D20: Phòng Đo đạc | E20: Cấp đổi | F20: 45958 | G20: 18000000 | H20: 18000000 | I20: =IF(G20="","",G20-H20) | J20: =IF(A20="","",IF(I20<=0,"Đã tất toán",IF(L20<TODAY(),"Quá hạn","Còn nợ"))) | K20: Nguyễn Hương DV
A21: 548-1/BK-2025 | B21: BK-HS-0303 | C21: Ngô Thanh Quyền | D21: Phòng Đo đạc | E21: Cắm mốc | F21: 45960 | G21: 1 | H21: 1 | I21: =IF(G21="","",G21-H21) | J21: =IF(A21="","",IF(I21<=0,"Đã tất toán",IF(L21<TODAY(),"Quá hạn","Còn nợ"))) | K21: Nguyễn Hương DV
A22: 535-2/BK-2025 | B22: BK-HS-0302 | C22: Võ Văn Ninh | D22: Phòng Đo đạc | E22: Cắm mốc | F22: 45960 | G22: 15000000 | H22: 15000000 | I22: =IF(G22="","",G22-H22) | J22: =IF(A22="","",IF(I22<=0,"Đã tất toán",IF(L22<TODAY(),"Quá hạn","Còn nợ"))) | K22: Công Ty
A23: 549/BK-2025 | B23: BK-HS-0301 | C23: Lý Thị Mỹ Phượng | D23: Phòng Đo đạc | E23: Hoàn công | F23: 45960 | G23: 1 | H23: 1 | I23: =IF(G23="","",G23-H23) | J23: =IF(A23="","",IF(I23<=0,"Đã tất toán",IF(L23<TODAY(),"Quá hạn","Còn nợ"))) | K23: Tấn Hiếu DV
... A40: 558-1/BK-2025 | B40: BK-HS-0284 | C40: Trương Yến Chi | D40: Phòng Đo đạc | E40: Cắm mốc | F40: 45970 | G40: 3000000 | H40: 3000000 | I40: =IF(G40="","",G40-H40) | J40: =IF(A40="","",IF(I40<=0,"Đã tất toán",IF(L40<TODAY(),"Quá hạn","Còn nợ"))) | K40: Công Ty
A41: 564/BK-2025 | B41: BK-HS-0283 | C41: Phạm Gia Minh | D41: Phòng Đo đạc | E41: Hoàn công | F41: 45970 | H41: 0 | I41: =IF(G41="","",G41-H41) | J41: =IF(A41="","",IF(I41<=0,"Đã tất toán",IF(L41<TODAY(),"Quá hạn","Còn nợ"))) | K41: Anh Long PCT
A42: 355-1/BK-2025 | B42: BK-HS-0282 | C42: Nguyễn Thị Vinh | D42: Phòng Đo đạc | E42: Cắm mốc | F42: 45970 | G42: 1 | H42: 1 | I42: =IF(G42="","",G42-H42) | J42: =IF(A42="","",IF(I42<=0,"Đã tất toán",IF(L42<TODAY(),"Quá hạn","Còn nợ"))) | K42: Công Ty
A43: 565/BK-2025 | B43: BK-HS-0281 | C43: Hoàng Anh Tú | D43: Phòng Đo đạc | E43: Chuyển mục đích | F43: 45970 | G43: 20000000 | H43: 20000000 | I43: =IF(G43="","",G43-H43) | J43: =IF(A43="","",IF(I43<=0,"Đã tất toán",IF(L43<TODAY(),"Quá hạn","Còn nợ"))) | K43: Anh Long PCT
A44: 566/BK-2025 | B44: BK-HS-0280 | C44: Nguyễn Văn Phúc | D44: Phòng Đo đạc | E44: Cắm mốc | F44: 45969 | G44: 4000000 | H44: 4000000 | I44: =IF(G44="","",G44-H44) | J44: =IF(A44="","",IF(I44<=0,"Đã tất toán",IF(L44<TODAY(),"Quá hạn","Còn nợ"))) | K44: Công Ty
A45: 285-1/BK-2025 | B45: BK-HS-0279 | C45: Nguyễn Văn Cơ | D45: Phòng Đo đạc | E45: Đo GPS | F45: 45972 | G45: 2 | H45: 2 | I45: =IF(G45="","",G45-H45) | J45: =IF(A45="","",IF(I45<=0,"Đã tất toán",IF(L45<TODAY(),"Quá hạn","Còn nợ"))) | K45: Anh Minh DV HBP
A46: 285-2/BK-2025 | B46: BK-HS-0278 | C46: Nguyễn Văn Cơ | D46: Phòng Đo đạc | E46: Cắm mốc | F46: 45972 | G46: 3000000 | H46: 0 | I46: =IF(G46="","",G46-H46) | J46: =IF(A46="","",IF(I46<=0,"Đã tất toán",IF(L46<TODAY(),"Quá hạn","Còn nợ"))) | K46: Anh Minh DV HBP
A47: 567/BK-2025 | B47: BK-HS-0277 | C47: Nguyễn Thị Kim Cúc | D47: Phòng Đo đạc | E47: Cấp sổ lần đầu | F47: 45974 | G47: 10000000 | H47: 10000000 | I47: =IF(G47="","",G47-H47) | J47: =IF(A47="","",IF(I47<=0,"Đã tất toán",IF(L47<TODAY(),"Quá hạn","Còn nợ"))) | K47: Đạt Việt Phát Land
A48: 568/BK-2025 | B48: BK-HS-0276 | C48: Nguyễn Văn Trường | D48: Phòng Đo đạc | E48: Chuyển mục đích | F48: 45974 | G48: 9000000 | H48: 9000000 | I48: =IF(G48="","",G48-H48) | J48: =IF(A48="","",IF(I48<=0,"Đã tất toán",IF(L48<TODAY(),"Quá hạn","Còn nợ"))) | K48: Công Ty
A49: 570/BK-2025 | B49: BK-HS-0275 | C49: Quang Hào | D49: Phòng Đo đạc | E49: Cắm mốc | F49: 45974 | G49: 3000000 | H49: 3000000 | I49: =IF(G49="","",G49-H49) | J49: =IF(A49="","",IF(I49<=0,"Đã tất toán",IF(L49<TODAY(),"Quá hạn","Còn nợ"))) | K49: Công Ty
A50: 571/BK-2025 | B50: BK-HS-0274 | C50: Trần Đức Phú | D50: Phòng Đo đạc | E50: Xác định diện tích | F50: 45974 | G50: 3000000 | H50: 0 | I50: =IF(G50="","",G50-H50) | J50: =IF(A50="","",IF(I50<=0,"Đã tất toán",IF(L50<TODAY(),"Quá hạn","Còn nợ"))) | K50: Hoàng Quân
A51: 572/BK-2025 | B51: BK-HS-0273 | C51: Trần Quang Vinh | D51: Phòng Đo đạc | E51: Xác định diện tích | F51: 45974 | G51: 3000000 | H51: 0 | I51: =IF(G51="","",G51-H51) | J51: =IF(A51="","",IF(I51<=0,"Đã tất toán",IF(L51<TODAY(),"Quá hạn","Còn nợ"))) | K51: Hoàng Quân
A52: 573/BK-2025 | B52: BK-HS-0272 | C52: Trần Đức Phú | D52: Phòng Đo đạc | E52: Xác định diện tích | F52: 45974 | G52: 3000000 | H52: 0 | I52: =IF(G52="","",G52-H52) | J52: =IF(A52="","",IF(I52<=0,"Đã tất toán",IF(L52<TODAY(),"Quá hạn","Còn nợ"))) | K52: Hoàng Quân
A53: 574/BK-2025 | B53: BK-HS-0271 | C53: Nguyễn Thị Quỳnh Lan | D53: Phòng Đo đạc | E53: Cấp đổi | F53: 45975 | G53: 15000000 | H53: 15000000 | I53: =IF(G53="","",G53-H53) | J53: =IF(A53="","",IF(I53<=0,"Đã tất toán",IF(L53<TODAY(),"Quá hạn","Còn nợ"))) | K53: Công Ty
... A58: 579/BK-2025 | B58: BK-HS-0266 | C58: Bùi Văn Hoàng | D58: Phòng Đo đạc | E58: Cấp đổi | F58: 45978 | G58: 35000000 | H58: 35000000 | I58: =IF(G58="","",G58-H58) | J58: =IF(A58="","",IF(I58<=0,"Đã tất toán",IF(L58<TODAY(),"Quá hạn","Còn nợ"))) | K58: Anh Hoàng Nhà Đầu Tư
A59: 582/BK-2025 | B59: BK-HS-0265 | C59: Nguyễn Trọng Khoa | D59: Phòng Đo đạc | E59: Cấp đổi | F59: 45978 | H59: 0 | I59: =IF(G59="","",G59-H59) | J59: =IF(A59="","",IF(I59<=0,"Đã tất toán",IF(L59<TODAY(),"Quá hạn","Còn nợ"))) | K59: Cô Hoa
A60: 583/BK-2025 | B60: BK-HS-0264 | C60: Trần Tuấn Anh | D60: Phòng Đo đạc | E60: Cấp đổi | F60: 45978 | H60: 0 | I60: =IF(G60="","",G60-H60) | J60: =IF(A60="","",IF(I60<=0,"Đã tất toán",IF(L60<TODAY(),"Quá hạn","Còn nợ"))) | K60: Cô Hoa
...

Sheet DATABASE_THU_CHI
A1: DATABASE THU CHI
A2: Mọi thu/chi nên gắn Mã hồ sơ hoặc Mã hợp đồng khi có liên quan.
A3: Ngày | B3: Mã phiếu | C3: Loại Thu/Chi | D3: Mã hồ sơ | E3: Mã hợp đồng | F3: Diễn giải | G3: Phòng ban | H3: Người nhận/Nộp | I3: Hình thức | J3: Số tiền | K3: Thu (+) | L3: Chi (-) | M3: Ghi chú
A4: 46097 | B4: PC-03/2026-085 | C4: Chi | F4: Gửi bv bv Hoàng Thị Cúc - Chi bảo vệ | G4: Phòng Kế toán | H4: bảo vệ | I4: Tiền mặt | J4: 50000 | K4: =IF(C4="Thu",J4,0) | L4: =IF(C4="Chi",J4,0) | M4: =K4-L4
A5: 46097 | B5: PC-03/2026-086 | C5: Chi | F5: thanh toán trích lục Lê Văn Hoàng - Lấy trích lục | G5: Phòng Kế toán | H5: Chi nhánh số 2 | I5: Chuyển khoản | J5: 200000 | K5: =IF(C5="Thu",J5,0) | L5: =IF(C5="Chi",J5,0) | M5: =K5-L5
A6: 46097 | B6: PC-03/2026-087 | C6: Chi | F6: gửi chị Huy nộp bản vẽ sáng 16/3 - Chi quầy tiếp nhận | G6: Phòng Kế toán | H6: Chị Huy | I6: Tiền mặt | J6: 100000 | K6: =IF(C6="Thu",J6,0) | L6: =IF(C6="Chi",J6,0) | M6: =K6-L6
A7: 46097 | B7: PC-03/2026-088 | C7: Chi | F7: Phan Xuân Phước (255) - Lấy bản vẽ | G7: Phòng Kế toán | H7: Chi nhánh số 2 | I7: Chuyển khoản | J7: 130873 | K7: =IF(C7="Thu",J7,0) | L7: =IF(C7="Chi",J7,0) | M7: =K7-L7
A8: 46097 | B8: PC-03/2026-089 | C8: Chi | F8: nộp hồ sơ tách thửa Trần Thị Ngọc Dung - Chi quầy tiếp nhận | G8: Phòng Kế toán | H8: quầy tiếp nhận | I8: Tiền mặt | J8: 200000 | K8: =IF(C8="Thu",J8,0) | L8: =IF(C8="Chi",J8,0) | M8: =K8-L8
A9: 46097 | B9: PC-03/2026-090 | C9: Chi | F9: Đào Thị Hòa (235) - Lấy bản vẽ | G9: Phòng Kế toán | H9: Chi nhánh số 2 | I9: Chuyển khoản | J9: 86900 | K9: =IF(C9="Thu",J9,0) | L9: =IF(C9="Chi",J9,0) | M9: =K9-L9
A10: 46097 | B10: PC-03/2026-091 | C10: Chi | F10: gửi chị Huy lấy bản vẽ đạt 16/3 - Chi quầy tiếp nhận | G10: Phòng Kế toán | H10: Chị Huy | I10: Tiền mặt | J10: 100000 | K10: =IF(C10="Thu",J10,0) | L10: =IF(C10="Chi",J10,0) | M10: =K10-L10
A11: 46097 | B11: PC-03/2026-092 | C11: Chi | F11: nộp hs Phan Xuân Phước - Chi quầy tiếp nhận | G11: Phòng Kế toán | H11: quầy tiếp nhận | I11: Tiền mặt | J11: 100000 | K11: =IF(C11="Thu",J11,0) | L11: =IF(C11="Chi",J11,0) | M11: =K11-L11
A12: 46097 | B12: PC-03/2026-093 | C12: Chi | F12: gửi hợp đồng cho anh Ý - Chuyển phát - Bưu chính-Grap | G12: Phòng Kế toán | H12: Anh Ý | I12: Chuyển khoản | J12: 41000 | K12: =IF(C12="Thu",J12,0) | L12: =IF(C12="Chi",J12,0) | M12: =K12-L12
A13: 46097 | B13: PC-03/2026-094 | C13: Chi | F13: gửi phi nông nghiệp Phan Xuân Phước cho chị Trâm - Đóng thuế | G13: Phòng Kế toán | H13: Chị Trâm | I13: Tiền mặt | J13: 300000 | K13: =IF(C13="Thu",J13,0) | L13: =IF(C13="Chi",J13,0) | M13: =K13-L13
A14: 46097 | B14: PC-03/2026-095 | C14: Chi | F14: đóng thuế phi NN Phan Xuân Phước - Đóng thuế | G14: Phòng Kế toán | H14: Agribank | I14: Tiền mặt | J14: 53000 | K14: =IF(C14="Thu",J14,0) | L14: =IF(C14="Chi",J14,0) | M14: =K14-L14
A15: 46097 | B15: PC-03/2026-096 | C15: Chi | F15: gửi bv cho anh Xuất - Chi bảo vệ | G15: Phòng Kế toán | H15: bảo vệ | I15: Tiền mặt | J15: 50000 | K15: =IF(C15="Thu",J15,0) | L15: =IF(C15="Chi",J15,0) | M15: =K15-L15
... A223: 46053 | B223: PC-01/2026-339 | C223: Chi | F223: trái cây 31/1 - Sinh hoạt gia đình | G223: Phòng Kế toán | H223: Hằng | I223: Tiền mặt | J223: 140000 | K223: =IF(C223="Thu",J223,0) | L223: =IF(C223="Chi",J223,0) | M223: =K223-L223
A224: 2026-06-23 13:31:38 | B224: PC-03/2026-0097 | C224: Chi | D224: None | E224: None | F224: Lệ phí trích lục bản đồ | G224: Phòng Đo đạc | H224: Võ Thành Minh | I224: Tiền mặt | J224: 150000 | K224: =IF(C224="Thu",J224,0) | L224: =IF(C224="Chi",J224,0) | M224: =K224-L224
A225: 2026-06-23 13:32:14 | B225: PC-03/2026-0098 | C225: Chi | D225: None | E225: None | F225: Lệ phí trích lục bản đồ | G225: Phòng Đo đạc | H225: Võ Thành Minh | I225: Tiền mặt | J225: 150000 | K225: =IF(C225="Thu",J225,0) | L225: =IF(C225="Chi",J225,0) | M225: =K225-L225
A226: 2026-06-23 13:33:52 | B226: PC-03/2026-0099 | C226: Chi | D226: None | E226: None | F226: Le phi trich luc bang do | G226: Phong Do dac | H226: Vo Thanh Minh | I226: Tien mat | J226: 150000 | K226: =IF(C226="Thu",J226,0) | L226: =IF(C226="Chi",J226,0) | M226: =K226-L226
A227: 2026-06-23 13:45:36 | B227: PC-03/2026-0100 | C227: Chi | D227: None | E227: None | F227: Test chi phí Python | G227: Phòng Giám đốc | H227: Lê Văn Dựng | I227: Tiền mặt | J227: 500000 | K227: =IF(C227="Thu",J227,0) | L227: =IF(C227="Chi",J227,0) | M227: =K227-L227
K228: =IF(C228="Thu",J228,0) | L228: =IF(C228="Chi",J228,0) | M228: =K228-L228
K229: =IF(C229="Thu",J229,0) | L229: =IF(C229="Chi",J229,0) | M229: =K229-L229
K230: =IF(C230="Thu",J230,0) | L230: =IF(C230="Chi",J230,0) | M230: =K230-L230
K231: =IF(C231="Thu",J231,0) | L231: =IF(C231="Chi",J231,0) | M231: =K231-L231
K232: =IF(C232="Thu",J232,0) | L232: =IF(C232="Chi",J232,0) | M232: =K232-L232
K233: =IF(C233="Thu",J233,0) | L233: =IF(C233="Chi",J233,0) | M233: =K233-L233
K234: =IF(C234="Thu",J234,0) | L234: =IF(C234="Chi",J234,0) | M234: =K234-L234
K235: =IF(C235="Thu",J235,0) | L235: =IF(C235="Chi",J235,0) | M235: =K235-L235
K236: =IF(C236="Thu",J236,0) | L236: =IF(C236="Chi",J236,0) | M236: =K236-L236
K237: =IF(C237="Thu",J237,0) | L237: =IF(C237="Chi",J237,0) | M237: =K237-L237
K238: =IF(C238="Thu",J238,0) | L238: =IF(C238="Chi",J238,0) | M238: =K238-L238
K239: =IF(C239="Thu",J239,0) | L239: =IF(C239="Chi",J239,0) | M239: =K239-L239
... K243: =IF(C243="Thu",J243,0) | L243: =IF(C243="Chi",J243,0) | M243: =K243-L243
B244: =IF(A244="","",THIET_LAP!$B$4&"-TC-"&TEXT(COUNT($A$4:A244),"0000")) | K244: =IF(C244="Thu",J244,0) | L244: =IF(C244="Chi",J244,0)
B245: =IF(A245="","",THIET_LAP!$B$4&"-TC-"&TEXT(COUNT($A$4:A245),"0000")) | K245: =IF(C245="Thu",J245,0) | L245: =IF(C245="Chi",J245,0)
B246: =IF(A246="","",THIET_LAP!$B$4&"-TC-"&TEXT(COUNT($A$4:A246),"0000")) | K246: =IF(C246="Thu",J246,0) | L246: =IF(C246="Chi",J246,0)
B247: =IF(A247="","",THIET_LAP!$B$4&"-TC-"&TEXT(COUNT($A$4:A247),"0000")) | K247: =IF(C247="Thu",J247,0) | L247: =IF(C247="Chi",J247,0)
B248: =IF(A248="","",THIET_LAP!$B$4&"-TC-"&TEXT(COUNT($A$4:A248),"0000")) | K248: =IF(C248="Thu",J248,0) | L248: =IF(C248="Chi",J248,0)
B249: =IF(A249="","",THIET_LAP!$B$4&"-TC-"&TEXT(COUNT($A$4:A249),"0000")) | K249: =IF(C249="Thu",J249,0) | L249: =IF(C249="Chi",J249,0)
B250: =IF(A250="","",THIET_LAP!$B$4&"-TC-"&TEXT(COUNT($A$4:A250),"0000")) | K250: =IF(C250="Thu",J250,0) | L250: =IF(C250="Chi",J250,0)
...

Sheet DATABASE_LUONG_KHOAN
A1: DATABASE LƯƠNG KHOÁN
A2: Mỗi dòng là 1 khoản khoán / phụ cấp / thưởng phạt gắn với hồ sơ hoặc task.
A3: Tháng | B3: Nhân sự | C3: Mã hồ sơ | D3: Mã task | E3: Công đoạn khoán | F3: Phòng ban | G3: Số tiền khoán | H3: Phụ cấp | I3: Thưởng/Phạt | J3: Tổng nhận | K3: Ngày chốt | L3: Ghi chú
A4: 46082 | B4: Lê Văn Dựng | C4: BK-HS-0030 | E4: Cắm mốc | F4: Phòng Đo đạc | G4: 1200000 | H4: 0 | I4: 0 | J4: =IF(B4="","",SUM(G4:I4)) | K4: 46085 | L4: HĐ cũ: 098/BK-2026
A5: 46082 | B5: Lê Văn Dựng | C5: BK-HS-0027 | E5: Xác định diện tích | F5: Phòng Đo đạc | G5: 700000 | H5: 0 | I5: 0 | J5: =IF(B5="","",SUM(G5:I5)) | K5: 46086 | L5: HĐ cũ: 101/BK-2026 | hồ sơ cấp đổi lấn thửa chủ nhà yêu cầu vẽ XDDT để đưa lên phường trình bày
A6: 46082 | B6: Lê Văn Dựng | C6: BK-HS-0025 | E6: Cắm mốc | F6: Phòng Đo đạc | G6: 1200000 | H6: 0 | I6: 0 | J6: =IF(B6="","",SUM(G6:I6)) | K6: 46086 | L6: HĐ cũ: 103/BK-2026
A7: 46082 | B7: Lê Văn Dựng | C7: BK-HS-0023 | E7: Cắm mốc | F7: Phòng Đo đạc | G7: 1200000 | H7: 300000 | I7: 0 | J7: =IF(B7="","",SUM(G7:I7)) | K7: 46086 | L7: HĐ cũ: 105/BK-2026
A8: 46082 | B8: Lê Văn Dựng | C8: BK-HS-0019 | E8: Đo GPS | F8: Phòng Đo đạc | G8: 1200000 | H8: 0 | I8: 0 | J8: =IF(B8="","",SUM(G8:I8)) | K8: 46090 | L8: HĐ cũ: 109/BK-2026
A9: 46082 | B9: Lê Văn Dựng | C9: BK-HS-0020 | E9: Cấp đổi | F9: Phòng Đo đạc | G9: 1100000 | H9: 0 | I9: 300000 | J9: =IF(B9="","",SUM(G9:I9)) | K9: 46091 | L9: HĐ cũ: 108/BK-2026
A10: 46082 | B10: Lê Văn Dựng | C10: BK-HS-0017 | E10: Đo GPS | F10: Phòng Đo đạc | G10: 1200000 | H10: 0 | I10: 0 | J10: =IF(B10="","",SUM(G10:I10)) | K10: 46091 | L10: HĐ cũ: 111/BK-2026
A11: 46082 | B11: Lê Văn Dựng | C11: BK-HS-0016 | E11: Xác định diện tích | F11: Phòng Đo đạc | G11: 700000 | H11: 0 | I11: 0 | J11: =IF(B11="","",SUM(G11:I11)) | K11: 46091 | L11: HĐ cũ: 112/BK-2026
A12: 46082 | B12: Lê Văn Dựng | C12: BK-HS-0015 | E12: Xác định diện tích | F12: Phòng Đo đạc | G12: 700000 | H12: 0 | I12: 0 | J12: =IF(B12="","",SUM(G12:I12)) | K12: 46091 | L12: HĐ cũ: 113/BK-2026
A13: 46082 | B13: Lê Văn Dựng | C13: BK-HS-0167 | E13: Hoàn công | F13: Phòng Đo đạc | G13: 1100000 | H13: 0 | I13: 0 | J13: =IF(B13="","",SUM(G13:I13)) | K13: 46092 | L13: HĐ cũ: 653/BK-2025
A14: 46054 | B14: Lê Văn Dựng | C14: BK-HS-0076 | E14: Cấp đổi | F14: Phòng Đo đạc | G14: 1100000 | H14: 0 | I14: 0 | J14: =IF(B14="","",SUM(G14:I14)) | K14: 46056 | L14: HĐ cũ: 053/BK-2026 | hồ sơ chưa xử lý được do khu đất có ao sâu không thể chôn trụ xi măng được,chờ khách hàng san lấp
A15: 46054 | B15: Lê Văn Dựng | C15: BK-HS-0052 | E15: Xác định diện tích | F15: Phòng Đo đạc | G15: 700000 | H15: 0 | I15: 0 | J15: =IF(B15="","",SUM(G15:I15)) | K15: 46056 | L15: HĐ cũ: 076/BK-2026
... A32: 46023 | B32: Lê Văn Dựng | C32: BK-HS-0109 | E32: Cấp đổi | F32: Phòng Đo đạc | G32: 0 | H32: 0 | I32: 0 | J32: =IF(B32="","",SUM(G32:I32)) | K32: 46038 | L32: HĐ cũ: 020/BK-2026
A33: 46023 | B33: Lê Văn Dựng | E33: Cấp đổi | F33: Phòng Đo đạc | G33: 0 | H33: 0 | I33: 0 | J33: =IF(B33="","",SUM(G33:I33)) | K33: 46038 | L33: HĐ cũ: 482/BK-2025 | Thửa 28
A34: 46023 | B34: Lê Văn Dựng | E34: Cấp đổi | F34: Phòng Đo đạc | G34: 0 | H34: 0 | I34: 0 | J34: =IF(B34="","",SUM(G34:I34)) | K34: 46038 | L34: HĐ cũ: 483/BK-2025 | Thửa 60
A35: 46023 | B35: Lê Văn Dựng | E35: Cấp đổi | F35: Phòng Đo đạc | G35: 0 | H35: 0 | I35: 0 | J35: =IF(B35="","",SUM(G35:I35)) | K35: 46038 | L35: HĐ cũ: 484/BK-2025 | Thửa 61
A36: 46023 | B36: Lê Văn Dựng | E36: Cấp đổi | F36: Phòng Đo đạc | G36: 0 | H36: 0 | I36: 0 | J36: =IF(B36="","",SUM(G36:I36)) | K36: 46038 | L36: HĐ cũ: 489/BK-2025 | Thửa 508
A37: 46023 | B37: Lê Văn Dựng | E37: Cấp đổi | F37: Phòng Đo đạc | G37: 0 | H37: 0 | I37: 0 | J37: =IF(B37="","",SUM(G37:I37)) | K37: 46038 | L37: HĐ cũ: 490/BK-2025 | Thửa 526, 527
A38: 46023 | B38: Lê Văn Dựng | C38: BK-HS-0093 | E38: Đo GPS | F38: Phòng Đo đạc | G38: 1200000 | H38: 0 | I38: 0 | J38: =IF(B38="","",SUM(G38:I38)) | K38: 46038 | L38: HĐ cũ: 036/BK-2026
A39: 46023 | B39: Lê Văn Dựng | C39: BK-HS-0149 | E39: Cấp đổi | F39: Phòng Đo đạc | G39: 0 | H39: 0 | I39: 0 | J39: =IF(B39="","",SUM(G39:I39)) | K39: 46039 | L39: HĐ cũ: 665/BK-2025
A40: 46023 | B40: Lê Văn Dựng | C40: BK-HS-0152 | E40: Cấp đổi | F40: Phòng Đo đạc | G40: 0 | H40: 0 | I40: 0 | J40: =IF(B40="","",SUM(G40:I40)) | K40: 46039 | L40: HĐ cũ: 664/BK-2025
A41: 46023 | B41: Lê Văn Dựng | E41: Cấp đổi | F41: Phòng Đo đạc | G41: 0 | H41: 0 | I41: 0 | J41: =IF(B41="","",SUM(G41:I41)) | K41: 46039 | L41: HĐ cũ: 465/BK-2025
A42: 46023 | B42: Lê Văn Dựng | E42: Cấp sổ lần đầu | F42: Phòng Đo đạc | G42: 0 | H42: 0 | I42: 0 | J42: =IF(B42="","",SUM(G42:I42)) | K42: 46039 | L42: HĐ cũ: 112/BK-2025 | Lấy 1 bộ hso
A43: 46023 | B43: Lê Văn Dựng | E43: Cấp sổ lần đầu | F43: Phòng Đo đạc | G43: 0 | H43: 0 | I43: 0 | J43: =IF(B43="","",SUM(G43:I43)) | K43: 46039 | L43: HĐ cũ: 114/BK-2025
A44: 46023 | B44: Lê Văn Dựng | C44: BK-HS-0089 | E44: Cắm mốc | F44: Phòng Đo đạc | G44: 1200000 | H44: 50000 | I44: 0 | J44: =IF(B44="","",SUM(G44:I44)) | K44: 46040 | L44: HĐ cũ: 040/BK-2026 | Cắm mốc,Chôn trụ xi măng đã chốt khách hàng 4 triệu (chưa thanh toán)
A45: 46023 | B45: Lê Văn Dựng | C45: BK-HS-0092 | E45: Hoàn công | F45: Phòng Đo đạc | G45: 1100000 | H45: 0 | I45: 0 | J45: =IF(B45="","",SUM(G45:I45)) | K45: 46041 | L45: HĐ cũ: 037/BK-2026
A46: 46023 | B46: Lê Văn Dựng | C46: BK-HS-0061 | E46: Đo GPS | F46: Phòng Đo đạc | G46: 1200000 | H46: 0 | I46: 0 | J46: =IF(B46="","",SUM(G46:I46)) | K46: 46052 | L46: HĐ cũ: 067/BK-2026
A47: 46023 | B47: Lê Văn Dựng | C47: BK-HS-0059 | E47: Đo GPS | F47: Phòng Đo đạc | G47: 1200000 | H47: 0 | I47: 0 | J47: =IF(B47="","",SUM(G47:I47)) | K47: 46052 | L47: HĐ cũ: 069/BK-2026
A48: 45992 | B48: Lê Văn Dựng | C48: BK-HS-0226 | E48: Cắm mốc | F48: Phòng Đo đạc | G48: 1200000 | H48: 375000 | I48: 0 | J48: =IF(B48="","",SUM(G48:I48)) | K48: 45992 | L48: HĐ cũ: 608-1/BK-2025
A49: 45992 | B49: Lê Văn Dựng | C49: BK-HS-0225 | E49: Đo GPS | F49: Phòng Đo đạc | G49: 1200000 | H49: 0 | I49: 0 | J49: =IF(B49="","",SUM(G49:I49)) | K49: 45992 | L49: HĐ cũ: 608-2/BK-2025
A50: 45992 | B50: Lê Văn Dựng | C50: BK-HS-0223 | E50: Cắm mốc | F50: Phòng Đo đạc | G50: 1200000 | H50: 100000 | I50: 0 | J50: =IF(B50="","",SUM(G50:I50)) | K50: 45992 | L50: HĐ cũ: 609-1/BK-2025
A51: 45992 | B51: Lê Văn Dựng | C51: BK-HS-0222 | E51: Đo GPS | F51: Phòng Đo đạc | G51: 1200000 | H51: 0 | I51: 0 | J51: =IF(B51="","",SUM(G51:I51)) | K51: 45992 | L51: HĐ cũ: 609-2/BK-2025
A52: 45992 | B52: Lê Văn Dựng | C52: BK-HS-0220 | E52: Cắm mốc | F52: Phòng Đo đạc | G52: 1200000 | H52: 1000000 | I52: 0 | J52: =IF(B52="","",SUM(G52:I52)) | K52: 45992 | L52: HĐ cũ: 610-1/BK-2025
A53: 45992 | B53: Lê Văn Dựng | C53: BK-HS-0219 | E53: Đo GPS | F53: Phòng Đo đạc | G53: 1200000 | H53: 0 | I53: 0 | J53: =IF(B53="","",SUM(G53:I53)) | K53: 45992 | L53: HĐ cũ: 610-2/BK-2025
A54: 45992 | B54: Lê Văn Dựng | C54: BK-HS-0218 | E54: Cắm mốc | F54: Phòng Đo đạc | G54: 1200000 | H54: 225000 | I54: 0 | J54: =IF(B54="","",SUM(G54:I54)) | K54: 45992 | L54: HĐ cũ: 611/BK-2025 | shd cũ 136/BK-2025
A55: 45992 | B55: Lê Văn Dựng | C55: BK-HS-0217 | E55: Đo GPS | F55: Phòng Đo đạc | G55: 1200000 | H55: 0 | I55: 0 | J55: =IF(B55="","",SUM(G55:I55)) | K55: 45992 | L55: HĐ cũ: 612/BK-2025
