Workbook

Sheet Bảng tổng hợp
A1: Dấu thời gian | B1: Mã hợp đồng | C1: Tên hồ sơ | D1: Pháp lý | E1: Phường | F1: Tên khách hàng | G1: Số Điện Thoại Liên Hệ | H1: Phụ Trách Chính | I1: Phụ đo | J1: Độ ưu tiên | K1: Trạng thái mới nhất | L1: Cảnh báo | M1: Hạng mục công việc | N1: Ngày bắt đầu | O1: Hạn xử lý | P1: Ngày nộp | Q1: Ngày HT | R1: Lần nộp | S1: Ghi chú | T1: Giải trình lý do | U1: Quản lý phê duyệt | V1: Chi kỹ thuật | W1: Số cọc cắm mốc | X1: Loại cọc cắm
A2: 45890.616 | B2: 112/BK-2025 | C2: P Linh Đông, HSo Tùng M | E2: Hiệp Bình | F2: Tùng Mập | H2: Lê Văn Dựng | I2: Tạ Khắc Tập | K2: {=IFERROR(VLOOKUP(B2, SORT('Nhật ký nộp hồ sơ '!B:D, 'Nhật ký nộp hồ sơ '!A:A, FALSE), 3, FALSE),"")} -> Hủy | L2: =IF(K2="Hủy","ĐÃ HỦY", IF(K2="Nộp thành công - Chờ kết quả","Đã nộp", IF(K2="Hoàn thành","Hoàn thành", IF(O2="","", IF(TODAY()>O2,"QUÁ HẠN","Trong hạn") )))) -> ĐÃ HỦY | M2: Cấp sổ lần đầu | N2: =IFERROR(__xludf.DUMMYFUNCTION("ARRAYFORMULA(IF(A2:A3293="""","""",TO_DATE(INT(A2:A3293))))"),45890.0) -> 45890 | O2: {=IF(N2:N3293="", "", SWITCH(IF(J2:J3293="", "Trung bình", TRIM(J2:J3293)), "Cao", N2:N3293+1, "Trung bình", N2:N3293+3, "Thấp", N2:N3293+5))} -> 45893 | P2: =IFERROR(__xludf.DUMMYFUNCTION("IFERROR(QUERY('Nhật ký nộp hồ sơ '!A:I, ""SELECT I WHERE B = '""&B2&""' ORDER BY A DESC LIMIT 1"", 0))"),46039.0) -> 46039 | Q2: =IF(K2="Hoàn thành", P2, "") | R2: {=IF(B16:B3293="", "", COUNTIF('Nhật ký nộp hồ sơ '!B:B, B16:B3293))} -> 1 | S2: Lấy 1 bộ hso | T2: đã vẽ xong,Đợi bổ sung giấy tờ | U2: Đợi phương án | V2: Đã thanh toán
A3: 45890.614 | B3: 114/BK-2025 | C3: P Linh Đông, HSo Tùng M 02 | E3: Hiệp Bình | F3: Tùng Mập | H3: Lê Văn Dựng | I3: Tạ Khắc Tập | K3: {=IFERROR(VLOOKUP(B3, SORT('Nhật ký nộp hồ sơ '!B:D, 'Nhật ký nộp hồ sơ '!A:A, FALSE), 3, FALSE),"")} -> Hủy | L3: =IF(K3="Hủy","ĐÃ HỦY", IF(K3="Nộp thành công - Chờ kết quả","Đã nộp", IF(K3="Hoàn thành","Hoàn thành", IF(O3="","", IF(TODAY()>O3,"QUÁ HẠN","Trong hạn") )))) -> ĐÃ HỦY | M3: Cấp sổ lần đầu | N3: =IFERROR(__xludf.DUMMYFUNCTION("""COMPUTED_VALUE"""),45890.0) -> 45890 | O3: 45893 | P3: =IFERROR(__xludf.DUMMYFUNCTION("IFERROR(QUERY('Nhật ký nộp hồ sơ '!A:I, ""SELECT I WHERE B = '""&B3&""' ORDER BY A DESC LIMIT 1"", 0))"),46039.0) -> 46039 | Q3: =IF(K3="Hoàn thành", P3, "") | R3: 1 | T3: đã vẽ xong,Đợi bổ sung giấy tờ | U3: Đợi phương án | V3: Đã thanh toán
A4: 45891.579 | B4: 13-XDDT/BK-2025 | C4: Anh Thanh | E4: Hiệp Bình | F4: Anh Thanh DV | H4: Tạ Khắc Tập | I4: Lê Tấn Đạt | K4: {=IFERROR(VLOOKUP(B4, SORT('Nhật ký nộp hồ sơ '!B:D, 'Nhật ký nộp hồ sơ '!A:A, FALSE), 3, FALSE),"")} -> Hoàn thành | L4: =IF(K4="Hủy","ĐÃ HỦY", IF(K4="Nộp thành công - Chờ kết quả","Đã nộp", IF(K4="Hoàn thành","Hoàn thành", IF(O4="","", IF(TODAY()>O4,"QUÁ HẠN","Trong hạn") )))) -> Hoàn thành | M4: Xác định diện tích | N4: =IFERROR(__xludf.DUMMYFUNCTION("""COMPUTED_VALUE"""),45891.0) -> 45891 | O4: 45894 | P4: =IFERROR(__xludf.DUMMYFUNCTION("IFERROR(QUERY('Nhật ký nộp hồ sơ '!A:I, ""SELECT I WHERE B = '""&B4&""' ORDER BY A DESC LIMIT 1"", 0))"),45873.0) -> 45873 | Q4: =IF(K4="Hoàn thành", P4, "") -> 45873 | R4: 1 | V4: Đã thanh toán
A5: 45890.599 | B5: 15-KT/BK-2025 | C5: Lý Thị Thuỳ Dung | D5: Có | E5: Tam Bình | F5: Cô Hoa | H5: Trương Tấn Quốc | I5: Tạ Khắc Tập | K5: {=IFERROR(VLOOKUP(B5, SORT('Nhật ký nộp hồ sơ '!B:D, 'Nhật ký nộp hồ sơ '!A:A, FALSE), 3, FALSE),"")} -> Hủy | L5: =IF(K5="Hủy","ĐÃ HỦY", IF(K5="Nộp thành công - Chờ kết quả","Đã nộp", IF(K5="Hoàn thành","Hoàn thành", IF(O5="","", IF(TODAY()>O5,"QUÁ HẠN","Trong hạn") )))) -> ĐÃ HỦY | M5: Hoàn công | N5: =IFERROR(__xludf.DUMMYFUNCTION("""COMPUTED_VALUE"""),45890.0) -> 45890 | O5: 45893 | P5: =IFERROR(__xludf.DUMMYFUNCTION("IFERROR(QUERY('Nhật ký nộp hồ sơ '!A:I, ""SELECT I WHERE B = '""&B5&""' ORDER BY A DESC LIMIT 1"", 0))"),46038.0) -> 46038 | Q5: =IF(K5="Hoàn thành", P5, "") | R5: 1 | S5: + anh Lê Văn Xây phụ đo | T5: Đợi trao đổi chủ nhà | U5: Đợi phương án | V5: Đã thanh toán
A6: 45891.516 | B6: 162-1/BK-2025 | C6: Nguyễn Thành Nhựt 1 | E6: Long Phước | F6: Anh Toàn Ủy Ban | H6: Nguyễn Minh Thông | I6: Tạ Khắc Tập | K6: {=IFERROR(VLOOKUP(B6, SORT('Nhật ký nộp hồ sơ '!B:D, 'Nhật ký nộp hồ sơ '!A:A, FALSE), 3, FALSE),"")} -> Hủy | L6: =IF(K6="Hủy","ĐÃ HỦY", IF(K6="Nộp thành công - Chờ kết quả","Đã nộp", IF(K6="Hoàn thành","Hoàn thành", IF(O6="","", IF(TODAY()>O6,"QUÁ HẠN","Trong hạn") )))) -> ĐÃ HỦY | M6: Cấp đổi | N6: =IFERROR(__xludf.DUMMYFUNCTION("""COMPUTED_VALUE"""),45891.0) -> 45891 | O6: 45894 | P6: =IFERROR(__xludf.DUMMYFUNCTION("IFERROR(QUERY('Nhật ký nộp hồ sơ '!A:I, ""SELECT I WHERE B = '""&B6&""' ORDER BY A DESC LIMIT 1"", 0))"),45892.0) -> 45892 | Q6: =IF(K6="Hoàn thành", P6, "") | R6: 1 | T6: A TOÀN MANG BẢN VỄ GIẢM DT CHO CHỦ NHÀ CAM KẾT MÀ K PHẢI HỒI | U6: Đợi phương án | V6: Đã thanh toán
A7: 45891.515 | B7: 162-2/BK-2025 | C7: Nguyễn Thành Nhựt 2 | E7: Long Phước | F7: Anh Toàn Ủy Ban | H7: Nguyễn Minh Thông | I7: Tạ Khắc Tập | K7: {=IFERROR(VLOOKUP(B7, SORT('Nhật ký nộp hồ sơ '!B:D, 'Nhật ký nộp hồ sơ '!A:A, FALSE), 3, FALSE),"")} -> Hủy | L7: =IF(K7="Hủy","ĐÃ HỦY", IF(K7="Nộp thành công - Chờ kết quả","Đã nộp", IF(K7="Hoàn thành","Hoàn thành", IF(O7="","", IF(TODAY()>O7,"QUÁ HẠN","Trong hạn") )))) -> ĐÃ HỦY | M7: Cấp đổi | N7: =IFERROR(__xludf.DUMMYFUNCTION("""COMPUTED_VALUE"""),45891.0) -> 45891 | O7: 45894 | P7: =IFERROR(__xludf.DUMMYFUNCTION("IFERROR(QUERY('Nhật ký nộp hồ sơ '!A:I, ""SELECT I WHERE B = '""&B7&""' ORDER BY A DESC LIMIT 1"", 0))"),46038.0) -> 46038 | Q7: =IF(K7="Hoàn thành", P7, "") | R7: 5 | T7: A TOÀN MANG BẢN VỄ GIẢM DT CHO CHỦ NHÀ CAM KẾT MÀ K PHẢI HỒI | U7: Đợi phương án | V7: Đã thanh toán
A8: 45891.509 | B8: 203/BK-2025 | C8: Doãn Thị Mai Xuân Điệp | E8: Bình Trưng | F8: Tùng Mập | H8: Nguyễn Minh Thông | I8: Tạ Khắc Tập | K8: {=IFERROR(VLOOKUP(B8, SORT('Nhật ký nộp hồ sơ '!B:D, 'Nhật ký nộp hồ sơ '!A:A, FALSE), 3, FALSE),"")} -> Hủy | L8: =IF(K8="Hủy","ĐÃ HỦY", IF(K8="Nộp thành công - Chờ kết quả","Đã nộp", IF(K8="Hoàn thành","Hoàn thành", IF(O8="","", IF(TODAY()>O8,"QUÁ HẠN","Trong hạn") )))) -> ĐÃ HỦY | M8: Hoàn công | N8: =IFERROR(__xludf.DUMMYFUNCTION("""COMPUTED_VALUE"""),45891.0) -> 45891 | O8: 45894 | P8: =IFERROR(__xludf.DUMMYFUNCTION("IFERROR(QUERY('Nhật ký nộp hồ sơ '!A:I, ""SELECT I WHERE B = '""&B8&""' ORDER BY A DESC LIMIT 1"", 0))"),46039.0) -> 46039 | Q8: =IF(K8="Hoàn thành", P8, "") | R8: 1 | T8: TÙNG MẬP CHƯA ĐƯA GIẤY TỜ | U8: Đợi phương án | V8: Đã thanh toán
A9: 45891.508 | B9: 204/BK-2025 | C9: Nguyễn Duy Khánh | E9: Bình Trưng | F9: Tùng Mập | H9: Nguyễn Minh Thông | I9: Tạ Khắc Tập | K9: {=IFERROR(VLOOKUP(B9, SORT('Nhật ký nộp hồ sơ '!B:D, 'Nhật ký nộp hồ sơ '!A:A, FALSE), 3, FALSE),"")} -> Hủy | L9: =IF(K9="Hủy","ĐÃ HỦY", IF(K9="Nộp thành công - Chờ kết quả","Đã nộp", IF(K9="Hoàn thành","Hoàn thành", IF(O9="","", IF(TODAY()>O9,"QUÁ HẠN","Trong hạn") )))) -> ĐÃ HỦY | M9: Hoàn công | N9: =IFERROR(__xludf.DUMMYFUNCTION("""COMPUTED_VALUE"""),45891.0) -> 45891 | O9: 45894 | P9: =IFERROR(__xludf.DUMMYFUNCTION("IFERROR(QUERY('Nhật ký nộp hồ sơ '!A:I, ""SELECT I WHERE B = '""&B9&""' ORDER BY A DESC LIMIT 1"", 0))"),46039.0) -> 46039 | Q9: =IF(K9="Hoàn thành", P9, "") | R9: 2 | T9: TÙNG MẬP CHƯA ĐƯA GIẤY TỜ | U9: Đợi phương án | V9: Đã thanh toán
A10: 45887.496 | B10: 219/BK-2025 | C10: Hưu Văn Xưa | E10: Hiệp Bình | F10: Tuấn Lộc | H10: Lê Văn Xây | I10: Tạ Khắc Tập | K10: {=IFERROR(VLOOKUP(B10, SORT('Nhật ký nộp hồ sơ '!B:D, 'Nhật ký nộp hồ sơ '!A:A, FALSE), 3, FALSE),"")} -> Nộp thành công - Chờ kết quả | L10: =IF(K10="Hủy","ĐÃ HỦY", IF(K10="Nộp thành công - Chờ kết quả","Đã nộp", IF(K10="Hoàn thành","Hoàn thành", IF(O10="","", IF(TODAY()>O10,"QUÁ HẠN","Trong hạn") )))) -> Đã nộp | M10: Hoàn công | N10: =IFERROR(__xludf.DUMMYFUNCTION("""COMPUTED_VALUE"""),45887.0) -> 45887 | O10: 45890 | P10: =IFERROR(__xludf.DUMMYFUNCTION("IFERROR(QUERY('Nhật ký nộp hồ sơ '!A:I, ""SELECT I WHERE B = '""&B10&""' ORDER BY A DESC LIMIT 1"", 0))"),45887.0) -> 45887 | Q10: =IF(K10="Hoàn thành", P10, "") | R10: 1 | S10: Hồ sơ cũ nay mới xử lý | T10: jkhihuuh | V10: Đã thanh toán
A11: 45891.506 | B11: 230/BK-2025 | C11: Nguyễn Thanh Phong | E11: Tăng Nhơn Phú | F11: Anh Thành Thanh Tra XD | H11: Trương Tấn Quốc | I11: Tạ Khắc Tập | K11: {=IFERROR(VLOOKUP(B11, SORT('Nhật ký nộp hồ sơ '!B:D, 'Nhật ký nộp hồ sơ '!A:A, FALSE), 3, FALSE),"")} -> Hoàn thành | L11: =IF(K11="Hủy","ĐÃ HỦY", IF(K11="Nộp thành công - Chờ kết quả","Đã nộp", IF(K11="Hoàn thành","Hoàn thành", IF(O11="","", IF(TODAY()>O11,"QUÁ HẠN","Trong hạn") )))) -> Hoàn thành | M11: Hoàn công | N11: =IFERROR(__xludf.DUMMYFUNCTION("""COMPUTED_VALUE"""),45891.0) -> 45891 | O11: 45894 | P11: =IFERROR(__xludf.DUMMYFUNCTION("IFERROR(QUERY('Nhật ký nộp hồ sơ '!A:I, ""SELECT I WHERE B = '""&B11&""' ORDER BY A DESC LIMIT 1"", 0))"),45904.0) -> 45904 | Q11: =IF(K11="Hoàn thành", P11, "") -> 45904 | R11: 1 | S11: + anh Xây phụ đo, đo hoàn công, xuống đo ghé lấy bộ hồ sơ | V11: Đã thanh toán
A12: 45890.618 | B12: 253-DC/BK-2025 | C12: DC Trịnh Thị Lan Viên | E12: Phước Long | F12: Chinh Đen | H12: Nguyễn Minh Thông | I12: Không cần | K12: {=IFERROR(VLOOKUP(B12, SORT('Nhật ký nộp hồ sơ '!B:D, 'Nhật ký nộp hồ sơ '!A:A, FALSE), 3, FALSE),"")} -> Hủy | L12: =IF(K12="Hủy","ĐÃ HỦY", IF(K12="Nộp thành công - Chờ kết quả","Đã nộp", IF(K12="Hoàn thành","Hoàn thành", IF(O12="","", IF(TODAY()>O12,"QUÁ HẠN","Trong hạn") )))) -> ĐÃ HỦY | M12: Điều chỉnh bản vẽ | N12: =IFERROR(__xludf.DUMMYFUNCTION("""COMPUTED_VALUE"""),45890.0) -> 45890 | O12: 45893 | P12: =IFERROR(__xludf.DUMMYFUNCTION("IFERROR(QUERY('Nhật ký nộp hồ sơ '!A:I, ""SELECT I WHERE B = '""&B12&""' ORDER BY A DESC LIMIT 1"", 0))"),45899.0) -> 45899 | Q12: =IF(K12="Hoàn thành", P12, "") | R12: 1 | S12: Vẽ theo hiện trạng nhà xin công nhận Không gạch caro | T12: KHÔNG CÓ BẢN VẼ NHÀ MẪU TẢM HUỶ | U12: Hủy | V12: Đã thanh toán
A13: 45894.643 | B13: 263/HĐĐV/25 | C13: Bùi Thị Mai | E13: An Khánh | F13: Đạt Việt Phát Land | H13: Lê Văn Xây | I13: Lê Tấn Đạt | K13: {=IFERROR(VLOOKUP(B13, SORT('Nhật ký nộp hồ sơ '!B:D, 'Nhật ký nộp hồ sơ '!A:A, FALSE), 3, FALSE),"")} -> Hoàn thành | L13: =IF(K13="Hủy","ĐÃ HỦY", IF(K13="Nộp thành công - Chờ kết quả","Đã nộp", IF(K13="Hoàn thành","Hoàn thành", IF(O13="","", IF(TODAY()>O13,"QUÁ HẠN","Trong hạn") )))) -> Hoàn thành | M13: Hoàn công | N13: =IFERROR(__xludf.DUMMYFUNCTION("""COMPUTED_VALUE"""),45894.0) -> 45894 | O13: 45897 | P13: =IFERROR(__xludf.DUMMYFUNCTION("IFERROR(QUERY('Nhật ký nộp hồ sơ '!A:I, ""SELECT I WHERE B = '""&B13&""' ORDER BY A DESC LIMIT 1"", 0))"),45912.0) -> 45912 | Q13: =IF(K13="Hoàn thành", P13, "") -> 45912 | R13: 3 | V13: Đã thanh toán
A14: 45890.518 | B14: 269/BK-2025 | C14: Phạm Thị Linh Phương | D14: Có | E14: Hiệp Bình | F14: Chị Phấn DV | H14: Nguyễn Minh Thông | I14: Không cần | K14: {=IFERROR(VLOOKUP(B14, SORT('Nhật ký nộp hồ sơ '!B:D, 'Nhật ký nộp hồ sơ '!A:A, FALSE), 3, FALSE),"")} -> Hủy | L14: =IF(K14="Hủy","ĐÃ HỦY", IF(K14="Nộp thành công - Chờ kết quả","Đã nộp", IF(K14="Hoàn thành","Hoàn thành", IF(O14="","", IF(TODAY()>O14,"QUÁ HẠN","Trong hạn") )))) -> ĐÃ HỦY | M14: Hợp thửa | N14: =IFERROR(__xludf.DUMMYFUNCTION("""COMPUTED_VALUE"""),45890.0) -> 45890 | O14: 45893 | P14: =IFERROR(__xludf.DUMMYFUNCTION("IFERROR(QUERY('Nhật ký nộp hồ sơ '!A:I, ""SELECT I WHERE B = '""&B14&""' ORDER BY A DESC LIMIT 1"", 0))"),46039.0) -> 46039 | Q14: =IF(K14="Hoàn thành", P14, "") | R14: 1 | T14: CHUYỂN MỤC ĐÍCH CHƯA CHỐT DC CHỦ NHÀ | U14: Đợi phương án | V14: Đã thanh toán
A15: 45890.515 | B15: 270/BK-2025 | C15: Trần Thị Muối | E15: Hiệp Bình | F15: Chị Phấn DV | H15: Lê Văn Dựng | I15: Tạ Khắc Tập | K15: {=IFERROR(VLOOKUP(B15, SORT('Nhật ký nộp hồ sơ '!B:D, 'Nhật ký nộp hồ sơ '!A:A, FALSE), 3, FALSE),"")} -> Hủy | L15: =IF(K15="Hủy","ĐÃ HỦY", IF(K15="Nộp thành công - Chờ kết quả","Đã nộp", IF(K15="Hoàn thành","Hoàn thành", IF(O15="","", IF(TODAY()>O15,"QUÁ HẠN","Trong hạn") )))) -> ĐÃ HỦY | M15: Hoàn công | N15: =IFERROR(__xludf.DUMMYFUNCTION("""COMPUTED_VALUE"""),45890.0) -> 45890 | O15: 45893 | P15: =IFERROR(__xludf.DUMMYFUNCTION("IFERROR(QUERY('Nhật ký nộp hồ sơ '!A:I, ""SELECT I WHERE B = '""&B15&""' ORDER BY A DESC LIMIT 1"", 0))"),45899.0) -> 45899 | Q15: =IF(K15="Hoàn thành", P15, "") | R15: 1 | T15: sai công năng,sân có dãy nhà trọ cũ chưa tháo dở,đã báo chị phấn dv | U15: Hủy | V15: Đã thanh toán
A16: 45885.63 | B16: 272/BK-2025 | C16: Lý Văn Huệ | E16: Hiệp Bình | F16: Tùng Mập | H16: Lê Văn Dựng | I16: Võ Thành Minh | K16: {=IFERROR(VLOOKUP(B16, SORT('Nhật ký nộp hồ sơ '!B:D, 'Nhật ký nộp hồ sơ '!A:A, FALSE), 3, FALSE),"")} -> Hoàn thành | L16: =IF(K16="Hủy","ĐÃ HỦY", IF(K16="Nộp thành công - Chờ kết quả","Đã nộp", IF(K16="Hoàn thành","Hoàn thành", IF(O16="","", IF(TODAY()>O16,"QUÁ HẠN","Trong hạn") )))) -> Hoàn thành | M16: Cấp sổ lần đầu | N16: =IFERROR(__xludf.DUMMYFUNCTION("""COMPUTED_VALUE"""),45885.0) -> 45885 | O16: 45888 | P16: =IFERROR(__xludf.DUMMYFUNCTION("IFERROR(QUERY('Nhật ký nộp hồ sơ '!A:I, ""SELECT I WHERE B = '""&B16&""' ORDER BY A DESC LIMIT 1"", 0))"),45880.0) -> 45880 | Q16: =IF(K16="Hoàn thành", P16, "") -> 45880 | R16: 1 | V16: Đã thanh toán
A17: 45884.354 | B17: 273/BK-2025 | C17: Trần Ngọc Minh | E17: Hiệp Bình | F17: Tùng Mập | H17: Lê Văn Dựng | I17: Võ Thành Minh | K17: {=IFERROR(VLOOKUP(B17, SORT('Nhật ký nộp hồ sơ '!B:D, 'Nhật ký nộp hồ sơ '!A:A, FALSE), 3, FALSE),"")} -> Hoàn thành | L17: =IF(K17="Hủy","ĐÃ HỦY", IF(K17="Nộp thành công - Chờ kết quả","Đã nộp", IF(K17="Hoàn thành","Hoàn thành", IF(O17="","", IF(TODAY()>O17,"QUÁ HẠN","Trong hạn") )))) -> Hoàn thành | M17: Cấp sổ lần đầu | N17: =IFERROR(__xludf.DUMMYFUNCTION("""COMPUTED_VALUE"""),45884.0) -> 45884 | O17: 45887 | P17: =IFERROR(__xludf.DUMMYFUNCTION("IFERROR(QUERY('Nhật ký nộp hồ sơ '!A:I, ""SELECT I WHERE B = '""&B17&""' ORDER BY A DESC LIMIT 1"", 0))"),45880.0) -> 45880 | Q17: =IF(K17="Hoàn thành", P17, "") -> 45880 | R17: 1 | V17: Đã thanh toán
A18: 45884.354 | B18: 274/BK-2025 | C18: Tống Văn Đảnh | E18: Hiệp Bình | F18: Tùng Mập | H18: Lê Văn Dựng | I18: Võ Thành Minh | K18: {=IFERROR(VLOOKUP(B18, SORT('Nhật ký nộp hồ sơ '!B:D, 'Nhật ký nộp hồ sơ '!A:A, FALSE), 3, FALSE),"")} -> Hoàn thành | L18: =IF(K18="Hủy","ĐÃ HỦY", IF(K18="Nộp thành công - Chờ kết quả","Đã nộp", IF(K18="Hoàn thành","Hoàn thành", IF(O18="","", IF(TODAY()>O18,"QUÁ HẠN","Trong hạn") )))) -> Hoàn thành | M18: Cấp sổ lần đầu | N18: =IFERROR(__xludf.DUMMYFUNCTION("""COMPUTED_VALUE"""),45884.0) -> 45884 | O18: 45887 | P18: =IFERROR(__xludf.DUMMYFUNCTION("IFERROR(QUERY('Nhật ký nộp hồ sơ '!A:I, ""SELECT I WHERE B = '""&B18&""' ORDER BY A DESC LIMIT 1"", 0))"),45883.0) -> 45883 | Q18: =IF(K18="Hoàn thành", P18, "") -> 45883 | R18: 1 | V18: Đã thanh toán
A19: 45894.476 | B19: 280/BK-2025 | C19: Lý Văn Tư | D19: Có | E19: Tam Bình | F19: Cô Hoa | H19: Lê Văn Dựng | I19: Võ Thành Minh | K19: {=IFERROR(VLOOKUP(B19, SORT('Nhật ký nộp hồ sơ '!B:D, 'Nhật ký nộp hồ sơ '!A:A, FALSE), 3, FALSE),"")} -> Hoàn thành | L19: =IF(K19="Hủy","ĐÃ HỦY", IF(K19="Nộp thành công - Chờ kết quả","Đã nộp", IF(K19="Hoàn thành","Hoàn thành", IF(O19="","", IF(TODAY()>O19,"QUÁ HẠN","Trong hạn") )))) -> Hoàn thành | M19: Xác định diện tích | N19: =IFERROR(__xludf.DUMMYFUNCTION("""COMPUTED_VALUE"""),45894.0) -> 45894 | O19: 45897 | P19: =IFERROR(__xludf.DUMMYFUNCTION("IFERROR(QUERY('Nhật ký nộp hồ sơ '!A:I, ""SELECT I WHERE B = '""&B19&""' ORDER BY A DESC LIMIT 1"", 0))"),45863.0) -> 45863 | Q19: =IF(K19="Hoàn thành", P19, "") -> 45863 | R19: 1 | V19: Đã thanh toán
A20: 45890.513 | B20: 284/BK-2025 | C20: Lê Hồng Phong - Phạm Thị Mai Xuân | E20: Tam Bình | F20: Tuấn Lộc | H20: Lê Văn Xây | I20: Tạ Khắc Tập | K20: {=IFERROR(VLOOKUP(B20, SORT('Nhật ký nộp hồ sơ '!B:D, 'Nhật ký nộp hồ sơ '!A:A, FALSE), 3, FALSE),"")} -> Hủy | L20: =IF(K20="Hủy","ĐÃ HỦY", IF(K20="Nộp thành công - Chờ kết quả","Đã nộp", IF(K20="Hoàn thành","Hoàn thành", IF(O20="","", IF(TODAY()>O20,"QUÁ HẠN","Trong hạn") )))) -> ĐÃ HỦY | M20: Hoàn công | N20: =IFERROR(__xludf.DUMMYFUNCTION("""COMPUTED_VALUE"""),45890.0) -> 45890 | O20: 45893 | P20: =IFERROR(__xludf.DUMMYFUNCTION("IFERROR(QUERY('Nhật ký nộp hồ sơ '!A:I, ""SELECT I WHERE B = '""&B20&""' ORDER BY A DESC LIMIT 1"", 0))"),46038.0) -> 46038 | Q20: =IF(K20="Hoàn thành", P20, "") | R20: 3 | T20: đã đo dịch vụ báo chờ | U20: Đợi phương án | V20: Đã thanh toán
A21: 45890.621 | B21: 285/BK-2025 | C21: Nguyễn Văn Cơ | E21: Hiệp Bình | F21: Anh Minh DV HBP | H21: Lê Văn Dựng | I21: Không cần | K21: {=IFERROR(VLOOKUP(B21, SORT('Nhật ký nộp hồ sơ '!B:D, 'Nhật ký nộp hồ sơ '!A:A, FALSE), 3, FALSE),"")} -> Hoàn thành | L21: =IF(K21="Hủy","ĐÃ HỦY", IF(K21="Nộp thành công - Chờ kết quả","Đã nộp", IF(K21="Hoàn thành","Hoàn thành", IF(O21="","", IF(TODAY()>O21,"QUÁ HẠN","Trong hạn") )))) -> Hoàn thành | M21: Cấp đổi | N21: =IFERROR(__xludf.DUMMYFUNCTION("""COMPUTED_VALUE"""),45890.0) -> 45890 | O21: 45893 | P21: =IFERROR(__xludf.DUMMYFUNCTION("IFERROR(QUERY('Nhật ký nộp hồ sơ '!A:I, ""SELECT I WHERE B = '""&B21&""' ORDER BY A DESC LIMIT 1"", 0))"),46044.0) -> 46044 | Q21: =IF(K21="Hoàn thành", P21, "") -> 46044 | R21: 1 | T21: chờ minh dv làm việc với chủ nhà(80% hủy) | U21: Đợi phương án | V21: Đã thanh toán
A22: 45891.46 | B22: 293-DC/BK-2025 | C22: Nguyễn Quang Đạt - Nguyễn Thị Quảng | E22: An Khánh | F22: Tấn Hiếu DV | H22: Lê Văn Dựng | I22: Không cần | K22: {=IFERROR(VLOOKUP(B22, SORT('Nhật ký nộp hồ sơ '!B:D, 'Nhật ký nộp hồ sơ '!A:A, FALSE), 3, FALSE),"")} -> Hoàn thành | L22: =IF(K22="Hủy","ĐÃ HỦY", IF(K22="Nộp thành công - Chờ kết quả","Đã nộp", IF(K22="Hoàn thành","Hoàn thành", IF(O22="","", IF(TODAY()>O22,"QUÁ HẠN","Trong hạn") )))) -> Hoàn thành | M22: Điều chỉnh bản vẽ | N22: =IFERROR(__xludf.DUMMYFUNCTION("""COMPUTED_VALUE"""),45891.0) -> 45891 | O22: 45894 | P22: =IFERROR(__xludf.DUMMYFUNCTION("IFERROR(QUERY('Nhật ký nộp hồ sơ '!A:I, ""SELECT I WHERE B = '""&B22&""' ORDER BY A DESC LIMIT 1"", 0))"),45877.0) -> 45877 | Q22: =IF(K22="Hoàn thành", P22, "") -> 45877 | R22: 1 | S22: Lỗi nhân sự | V22: Đã thanh toán
A23: 45894.588 | B23: 296/HĐĐV/25 | C23: Trương Thị Gái | E23: Hiệp Bình | F23: Đạt Việt Phát Land | H23: Lê Văn Xây | I23: Lê Tấn Đạt | K23: {=IFERROR(VLOOKUP(B23, SORT('Nhật ký nộp hồ sơ '!B:D, 'Nhật ký nộp hồ sơ '!A:A, FALSE), 3, FALSE),"")} -> Hoàn thành | L23: =IF(K23="Hủy","ĐÃ HỦY", IF(K23="Nộp thành công - Chờ kết quả","Đã nộp", IF(K23="Hoàn thành","Hoàn thành", IF(O23="","", IF(TODAY()>O23,"QUÁ HẠN","Trong hạn") )))) -> Hoàn thành | M23: Cấp đổi | N23: =IFERROR(__xludf.DUMMYFUNCTION("""COMPUTED_VALUE"""),45894.0) -> 45894 | O23: 45897 | P23: =IFERROR(__xludf.DUMMYFUNCTION("IFERROR(QUERY('Nhật ký nộp hồ sơ '!A:I, ""SELECT I WHERE B = '""&B23&""' ORDER BY A DESC LIMIT 1"", 0))"),45904.0) -> 45904 | Q23: =IF(K23="Hoàn thành", P23, "") -> 45904 | R23: 4 | V23: Đã thanh toán
A24: 45897.503 | B24: 299-1/BK-2025 | C24: Nguyễn Văn Có | D24: Có | E24: Thủ Đức | F24: Anh Cường Sài Gòn DV | H24: Nguyễn Minh Thông | I24: Tạ Khắc Tập | K24: {=IFERROR(VLOOKUP(B24, SORT('Nhật ký nộp hồ sơ '!B:D, 'Nhật ký nộp hồ sơ '!A:A, FALSE), 3, FALSE),"")} -> Hoàn thành | L24: =IF(K24="Hủy","ĐÃ HỦY", IF(K24="Nộp thành công - Chờ kết quả","Đã nộp", IF(K24="Hoàn thành","Hoàn thành", IF(O24="","", IF(TODAY()>O24,"QUÁ HẠN","Trong hạn") )))) -> Hoàn thành | M24: Cấp đổi | N24: =IFERROR(__xludf.DUMMYFUNCTION("""COMPUTED_VALUE"""),45897.0) -> 45897 | O24: 45900 | P24: =IFERROR(__xludf.DUMMYFUNCTION("IFERROR(QUERY('Nhật ký nộp hồ sơ '!A:I, ""SELECT I WHERE B = '""&B24&""' ORDER BY A DESC LIMIT 1"", 0))"),45897.0) -> 45897 | Q24: =IF(K24="Hoàn thành", P24, "") -> 45897 | R24: 3 | V24: Đã thanh toán
A25: 45890.507 | B25: 302/BK-2025 | C25: Trần Quốc Tuấn | E25: Tam Bình | F25: Tuấn Đen | H25: Lê Văn Xây | I25: Lê Tấn Đạt | K25: {=IFERROR(VLOOKUP(B25, SORT('Nhật ký nộp hồ sơ '!B:D, 'Nhật ký nộp hồ sơ '!A:A, FALSE), 3, FALSE),"")} -> Hủy | L25: =IF(K25="Hủy","ĐÃ HỦY", IF(K25="Nộp thành công - Chờ kết quả","Đã nộp", IF(K25="Hoàn thành","Hoàn thành", IF(O25="","", IF(TODAY()>O25,"QUÁ HẠN","Trong hạn") )))) -> ĐÃ HỦY | M25: Cấp đổi | N25: =IFERROR(__xludf.DUMMYFUNCTION("""COMPUTED_VALUE"""),45890.0) -> 45890 | O25: 45893 | P25: =IFERROR(__xludf.DUMMYFUNCTION("IFERROR(QUERY('Nhật ký nộp hồ sơ '!A:I, ""SELECT I WHERE B = '""&B25&""' ORDER BY A DESC LIMIT 1"", 0))"),45899.0) -> 45899 | Q25: =IF(K25="Hoàn thành", P25, "") | R25: 1 | T25: sai hien trang huy | U25: Hủy | V25: Đã thanh toán
A26: 45891.494 | B26: 304/BK-2025 | C26: Lê Tiến Phong - Lê Nguyên Phương | E26: Tăng Nhơn Phú | F26: Tuấn Đen | H26: Tạ Khắc Tập | I26: Lê Tấn Đạt | K26: {=IFERROR(VLOOKUP(B26, SORT('Nhật ký nộp hồ sơ '!B:D, 'Nhật ký nộp hồ sơ '!A:A, FALSE), 3, FALSE),"")} -> Hoàn thành | L26: =IF(K26="Hủy","ĐÃ HỦY", IF(K26="Nộp thành công - Chờ kết quả","Đã nộp", IF(K26="Hoàn thành","Hoàn thành", IF(O26="","", IF(TODAY()>O26,"QUÁ HẠN","Trong hạn") )))) -> Hoàn thành | M26: Cấp đổi | N26: =IFERROR(__xludf.DUMMYFUNCTION("""COMPUTED_VALUE"""),45891.0) -> 45891 | O26: 45894 | P26: =IFERROR(__xludf.DUMMYFUNCTION("IFERROR(QUERY('Nhật ký nộp hồ sơ '!A:I, ""SELECT I WHERE B = '""&B26&""' ORDER BY A DESC LIMIT 1"", 0))"),45881.0) -> 45881 | Q26: =IF(K26="Hoàn thành", P26, "") -> 45881 | R26: 1 | V26: Đã thanh toán
A27: 45890.493 | B27: 305/BK-2025 | C27: Đoàn Trọng Ân | D27: Có | E27: Linh Xuân | F27: Công Ty | G27: 0901936357 | H27: Lê Văn Xây | I27: Lê Tấn Đạt | K27: {=IFERROR(VLOOKUP(B27, SORT('Nhật ký nộp hồ sơ '!B:D, 'Nhật ký nộp hồ sơ '!A:A, FALSE), 3, FALSE),"")} -> Hoàn thành | L27: =IF(K27="Hủy","ĐÃ HỦY", IF(K27="Nộp thành công - Chờ kết quả","Đã nộp", IF(K27="Hoàn thành","Hoàn thành", IF(O27="","", IF(TODAY()>O27,"QUÁ HẠN","Trong hạn") )))) -> Hoàn thành | M27: Tách Thửa | N27: =IFERROR(__xludf.DUMMYFUNCTION("""COMPUTED_VALUE"""),45890.0) -> 45890 | O27: 45893 | P27: =IFERROR(__xludf.DUMMYFUNCTION("IFERROR(QUERY('Nhật ký nộp hồ sơ '!A:I, ""SELECT I WHERE B = '""&B27&""' ORDER BY A DESC LIMIT 1"", 0))"),46037.0) -> 46037 | Q27: =IF(K27="Hoàn thành", P27, "") -> 46037 | R27: 1 | T27: sai hien trang cho phuong an chu nha | U27: Đợi phương án | V27: Đã thanh toán
A28: 45891.491 | B28: 309/BK-2025 | C28: Ngô Thị Hồng Khanh | E28: Tăng Nhơn Phú | F28: Công Ty | G28: 0374674853 | H28: Lê Văn Dựng | I28: Lê Tấn Đạt | K28: {=IFERROR(VLOOKUP(B28, SORT('Nhật ký nộp hồ sơ '!B:D, 'Nhật ký nộp hồ sơ '!A:A, FALSE), 3, FALSE),"")} -> Hoàn thành | L28: =IF(K28="Hủy","ĐÃ HỦY", IF(K28="Nộp thành công - Chờ kết quả","Đã nộp", IF(K28="Hoàn thành","Hoàn thành", IF(O28="","", IF(TODAY()>O28,"QUÁ HẠN","Trong hạn") )))) -> Hoàn thành | M28: Cấp đổi | N28: =IFERROR(__xludf.DUMMYFUNCTION("""COMPUTED_VALUE"""),45891.0) -> 45891 | O28: 45894 | P28: =IFERROR(__xludf.DUMMYFUNCTION("IFERROR(QUERY('Nhật ký nộp hồ sơ '!A:I, ""SELECT I WHERE B = '""&B28&""' ORDER BY A DESC LIMIT 1"", 0))"),45877.0) -> 45877 | Q28: =IF(K28="Hoàn thành", P28, "") -> 45877 | R28: 1 | S28: chạy toạ độ hết sát đất, gạch sọc phần chưa được công nhận | V28: Đã thanh toán
A29: 45891.489 | B29: 310/BK-2025 | C29: Lê Văn Châu | E29: Long Phước | F29: Công Ty | G29: 0913926672 | H29: Lê Văn Dựng | I29: Không cần | K29: {=IFERROR(VLOOKUP(B29, SORT('Nhật ký nộp hồ sơ '!B:D, 'Nhật ký nộp hồ sơ '!A:A, FALSE), 3, FALSE),"")} -> Hoàn thành | L29: =IF(K29="Hủy","ĐÃ HỦY", IF(K29="Nộp thành công - Chờ kết quả","Đã nộp", IF(K29="Hoàn thành","Hoàn thành", IF(O29="","", IF(TODAY()>O29,"QUÁ HẠN","Trong hạn") )))) -> Hoàn thành | M29: Cấp sổ lần đầu | N29: =IFERROR(__xludf.DUMMYFUNCTION("""COMPUTED_VALUE"""),45891.0) -> 45891 | O29: 45894 | P29: =IFERROR(__xludf.DUMMYFUNCTION("IFERROR(QUERY('Nhật ký nộp hồ sơ '!A:I, ""SELECT I WHERE B = '""&B29&""' ORDER BY A DESC LIMIT 1"", 0))"),45867.0) -> 45867 | Q29: =IF(K29="Hoàn thành", P29, "") -> 45867 | R29: 1 | S29: có thể đo GPS | V29: Đã thanh toán
A30: 45894.367 | B30: 311-2/BK-2025 | C30: Lê Văn Châu | E30: Long Phước | F30: Công Ty | G30: 0913926672 | H30: Lê Văn Dựng | I30: Không cần | K30: {=IFERROR(VLOOKUP(B30, SORT('Nhật ký nộp hồ sơ '!B:D, 'Nhật ký nộp hồ sơ '!A:A, FALSE), 3, FALSE),"")} -> Hoàn thành | L30: =IF(K30="Hủy","ĐÃ HỦY", IF(K30="Nộp thành công - Chờ kết quả","Đã nộp", IF(K30="Hoàn thành","Hoàn thành", IF(O30="","", IF(TODAY()>O30,"QUÁ HẠN","Trong hạn") )))) -> Hoàn thành | M30: Đo GPS | N30: =IFERROR(__xludf.DUMMYFUNCTION("""COMPUTED_VALUE"""),45894.0) -> 45894 | O30: 45897 | P30: =IFERROR(__xludf.DUMMYFUNCTION("IFERROR(QUERY('Nhật ký nộp hồ sơ '!A:I, ""SELECT I WHERE B = '""&B30&""' ORDER BY A DESC LIMIT 1"", 0))"),45867.0) -> 45867 | Q30: =IF(K30="Hoàn thành", P30, "") -> 45867 | R30: 1 | V30: Đã thanh toán
A31: 45891.482 | B31: 311/BK-2025 | C31: Lê Văn Châu | E31: Long Phước | F31: Công Ty | G31: 0913926672 | H31: Lê Văn Dựng | I31: Không cần | K31: {=IFERROR(VLOOKUP(B31, SORT('Nhật ký nộp hồ sơ '!B:D, 'Nhật ký nộp hồ sơ '!A:A, FALSE), 3, FALSE),"")} -> Hoàn thành | L31: =IF(K31="Hủy","ĐÃ HỦY", IF(K31="Nộp thành công - Chờ kết quả","Đã nộp", IF(K31="Hoàn thành","Hoàn thành", IF(O31="","", IF(TODAY()>O31,"QUÁ HẠN","Trong hạn") )))) -> Hoàn thành | M31: Cấp sổ lần đầu | N31: =IFERROR(__xludf.DUMMYFUNCTION("""COMPUTED_VALUE"""),45891.0) -> 45891 | O31: 45894 | P31: =IFERROR(__xludf.DUMMYFUNCTION("IFERROR(QUERY('Nhật ký nộp hồ sơ '!A:I, ""SELECT I WHERE B = '""&B31&""' ORDER BY A DESC LIMIT 1"", 0))"),45867.0) -> 45867 | Q31: =IF(K31="Hoàn thành", P31, "") -> 45867 | R31: 2 | S31: HỢP THỨC HOÁ BỔ SUNG | V31: Đã thanh toán
A32: 45891.479 | B32: 312/BK-2025 | C32: Nguyễn Xuân Quang - Trần Thị Bé Loan | E32: Long Trường | F32: Khangdien home | G32: 0908119226 | H32: Lê Văn Dựng | I32: Lê Tấn Đạt | K32: {=IFERROR(VLOOKUP(B32, SORT('Nhật ký nộp hồ sơ '!B:D, 'Nhật ký nộp hồ sơ '!A:A, FALSE), 3, FALSE),"")} -> Hoàn thành | L32: =IF(K32="Hủy","ĐÃ HỦY", IF(K32="Nộp thành công - Chờ kết quả","Đã nộp", IF(K32="Hoàn thành","Hoàn thành", IF(O32="","", IF(TODAY()>O32,"QUÁ HẠN","Trong hạn") )))) -> Hoàn thành | M32: Cấp đổi | N32: =IFERROR(__xludf.DUMMYFUNCTION("""COMPUTED_VALUE"""),45891.0) -> 45891 | O32: 45894 | P32: =IFERROR(__xludf.DUMMYFUNCTION("IFERROR(QUERY('Nhật ký nộp hồ sơ '!A:I, ""SELECT I WHERE B = '""&B32&""' ORDER BY A DESC LIMIT 1"", 0))"),45882.0) -> 45882 | Q32: =IF(K32="Hoàn thành", P32, "") -> 45882 | R32: 1 | S32: mai 3h bên anh có mặt ở địa chỉ 36 1D Melosa Khang Điền, chủ nhà sẽ dẫn anh xuống lô đất nông nghiệp đó nha, sau đó 4h hơn anh quay về Mega Village 103 N2 để đo nhà đó nha anh + lấy bộ hso | V32: Đã thanh toán
A33: 45894.437 | B33: 313-2/BK-2025 | C33: Nguyễn Ngọc Thuần | E33: Long Trường | F33: Công Ty | G33: 0919171713 | H33: Lê Văn Dựng | I33: Không cần | K33: {=IFERROR(VLOOKUP(B33, SORT('Nhật ký nộp hồ sơ '!B:D, 'Nhật ký nộp hồ sơ '!A:A, FALSE), 3, FALSE),"")} -> Hoàn thành | L33: =IF(K33="Hủy","ĐÃ HỦY", IF(K33="Nộp thành công - Chờ kết quả","Đã nộp", IF(K33="Hoàn thành","Hoàn thành", IF(O33="","", IF(TODAY()>O33,"QUÁ HẠN","Trong hạn") )))) -> Hoàn thành | M33: Đo GPS | N33: =IFERROR(__xludf.DUMMYFUNCTION("""COMPUTED_VALUE"""),45894.0) -> 45894 | O33: 45897 | P33: =IFERROR(__xludf.DUMMYFUNCTION("IFERROR(QUERY('Nhật ký nộp hồ sơ '!A:I, ""SELECT I WHERE B = '""&B33&""' ORDER BY A DESC LIMIT 1"", 0))"),45869.0) -> 45869 | Q33: =IF(K33="Hoàn thành", P33, "") -> 45869 | R33: 4 | V33: Đã thanh toán
A34: 45891.472 | B34: 313/BK-2025 | C34: Nguyễn Ngọc Thuần | E34: Long Trường | F34: Công Ty | G34: 0919171713 | H34: Lê Văn Dựng | I34: Lê Tấn Đạt | K34: {=IFERROR(VLOOKUP(B34, SORT('Nhật ký nộp hồ sơ '!B:D, 'Nhật ký nộp hồ sơ '!A:A, FALSE), 3, FALSE),"")} -> Hoàn thành | L34: =IF(K34="Hủy","ĐÃ HỦY", IF(K34="Nộp thành công - Chờ kết quả","Đã nộp", IF(K34="Hoàn thành","Hoàn thành", IF(O34="","", IF(TODAY()>O34,"QUÁ HẠN","Trong hạn") )))) -> Hoàn thành | M34: Cấp đổi | N34: =IFERROR(__xludf.DUMMYFUNCTION("""COMPUTED_VALUE"""),45891.0) -> 45891 | O34: 45894 | P34: =IFERROR(__xludf.DUMMYFUNCTION("IFERROR(QUERY('Nhật ký nộp hồ sơ '!A:I, ""SELECT I WHERE B = '""&B34&""' ORDER BY A DESC LIMIT 1"", 0))"),45895.0) -> 45895 | Q34: =IF(K34="Hoàn thành", P34, "") -> 45895 | R34: 4 | S34: mai 3h bên anh có mặt ở địa chỉ 36 1D Melosa Khang Điền, chủ nhà sẽ dẫn anh xuống lô đất nông nghiệp đó nha + lấy bộ hso + có thể đo thêm GPS | V34: Đã thanh toán
A35: 45891.468 | B35: 315/BK-2025 | C35: Trương Ngọc Yên | E35: Hiệp Bình | F35: Anh Lý Luật Sư | H35: Tạ Khắc Tập | I35: Trương Tấn Quốc | K35: {=IFERROR(VLOOKUP(B35, SORT('Nhật ký nộp hồ sơ '!B:D, 'Nhật ký nộp hồ sơ '!A:A, FALSE), 3, FALSE),"")} -> Hoàn thành | L35: =IF(K35="Hủy","ĐÃ HỦY", IF(K35="Nộp thành công - Chờ kết quả","Đã nộp", IF(K35="Hoàn thành","Hoàn thành", IF(O35="","", IF(TODAY()>O35,"QUÁ HẠN","Trong hạn") )))) -> Hoàn thành | M35: Cấp sổ lần đầu | N35: =IFERROR(__xludf.DUMMYFUNCTION("""COMPUTED_VALUE"""),45891.0) -> 45891 | O35: 45894 | P35: =IFERROR(__xludf.DUMMYFUNCTION("IFERROR(QUERY('Nhật ký nộp hồ sơ '!A:I, ""SELECT I WHERE B = '""&B35&""' ORDER BY A DESC LIMIT 1"", 0))"),45870.0) -> 45870 | Q35: =IF(K35="Hoàn thành", P35, "") -> 45870 | R35: 2 | V35: Đã thanh toán
A36: 45894.478 | B36: 316/BK-2025 | C36: Đỗ Đình Cẩn | D36: Có | E36: Tam Bình | F36: Cô Hoa | H36: Lê Văn Xây | I36: Lê Tấn Đạt | K36: {=IFERROR(VLOOKUP(B36, SORT('Nhật ký nộp hồ sơ '!B:D, 'Nhật ký nộp hồ sơ '!A:A, FALSE), 3, FALSE),"")} -> Hoàn thành | L36: =IF(K36="Hủy","ĐÃ HỦY", IF(K36="Nộp thành công - Chờ kết quả","Đã nộp", IF(K36="Hoàn thành","Hoàn thành", IF(O36="","", IF(TODAY()>O36,"QUÁ HẠN","Trong hạn") )))) -> Hoàn thành | M36: Cấp đổi | N36: =IFERROR(__xludf.DUMMYFUNCTION("""COMPUTED_VALUE"""),45894.0) -> 45894 | O36: 45897 | P36: =IFERROR(__xludf.DUMMYFUNCTION("IFERROR(QUERY('Nhật ký nộp hồ sơ '!A:I, ""SELECT I WHERE B = '""&B36&""' ORDER BY A DESC LIMIT 1"", 0))"),45890.0) -> 45890 | Q36: =IF(K36="Hoàn thành", P36, "") -> 45890 | R36: 2 | V36: Đã thanh toán
A37: 45894.481 | B37: 317/BK-2025 | C37: Lê Văn Lý | D37: Có | E37: Hiệp Bình | F37: Anh Sơn Hải DV | H37: Nguyễn Minh Thông | I37: Lê Tấn Đạt | K37: {=IFERROR(VLOOKUP(B37, SORT('Nhật ký nộp hồ sơ '!B:D, 'Nhật ký nộp hồ sơ '!A:A, FALSE), 3, FALSE),"")} -> Hoàn thành | L37: =IF(K37="Hủy","ĐÃ HỦY", IF(K37="Nộp thành công - Chờ kết quả","Đã nộp", IF(K37="Hoàn thành","Hoàn thành", IF(O37="","", IF(TODAY()>O37,"QUÁ HẠN","Trong hạn") )))) -> Hoàn thành | M37: Cấp đổi | N37: =IFERROR(__xludf.DUMMYFUNCTION("""COMPUTED_VALUE"""),45894.0) -> 45894 | O37: 45897 | P37: =IFERROR(__xludf.DUMMYFUNCTION("IFERROR(QUERY('Nhật ký nộp hồ sơ '!A:I, ""SELECT I WHERE B = '""&B37&""' ORDER BY A DESC LIMIT 1"", 0))"),45910.0) -> 45910 | Q37: =IF(K37="Hoàn thành", P37, "") -> 45910 | R37: 1 | V37: Đã thanh toán
A38: 45891.467 | B38: 318/BK-2025 | C38: Lê Thị Minh Trang - Trần Văn Hiếu | E38: Tăng Nhơn Phú | F38: Chinh Đen | H38: Nguyễn Minh Thông | I38: Không cần | K38: {=IFERROR(VLOOKUP(B38, SORT('Nhật ký nộp hồ sơ '!B:D, 'Nhật ký nộp hồ sơ '!A:A, FALSE), 3, FALSE),"")} -> Hoàn thành | L38: =IF(K38="Hủy","ĐÃ HỦY", IF(K38="Nộp thành công - Chờ kết quả","Đã nộp", IF(K38="Hoàn thành","Hoàn thành", IF(O38="","", IF(TODAY()>O38,"QUÁ HẠN","Trong hạn") )))) -> Hoàn thành | M38: Cấp đổi | N38: =IFERROR(__xludf.DUMMYFUNCTION("""COMPUTED_VALUE"""),45891.0) -> 45891 | O38: 45894 | P38: =IFERROR(__xludf.DUMMYFUNCTION("IFERROR(QUERY('Nhật ký nộp hồ sơ '!A:I, ""SELECT I WHERE B = '""&B38&""' ORDER BY A DESC LIMIT 1"", 0))"),45891.0) -> 45891 | Q38: =IF(K38="Hoàn thành", P38, "") -> 45891 | R38: 2 | V38: Đã thanh toán
A39: 45890.478 | B39: 319/BK-2025 | C39: Hoàng Thanh Vinh | E39: Hiệp Bình | F39: Tuấn Đen | H39: Lê Văn Xây | I39: Lê Tấn Đạt | K39: {=IFERROR(VLOOKUP(B39, SORT('Nhật ký nộp hồ sơ '!B:D, 'Nhật ký nộp hồ sơ '!A:A, FALSE), 3, FALSE),"")} -> Hủy | L39: =IF(K39="Hủy","ĐÃ HỦY", IF(K39="Nộp thành công - Chờ kết quả","Đã nộp", IF(K39="Hoàn thành","Hoàn thành", IF(O39="","", IF(TODAY()>O39,"QUÁ HẠN","Trong hạn") )))) -> ĐÃ HỦY | M39: Hoàn công | N39: =IFERROR(__xludf.DUMMYFUNCTION("""COMPUTED_VALUE"""),45890.0) -> 45890 | O39: 45893 | P39: =IFERROR(__xludf.DUMMYFUNCTION("IFERROR(QUERY('Nhật ký nộp hồ sơ '!A:I, ""SELECT I WHERE B = '""&B39&""' ORDER BY A DESC LIMIT 1"", 0))"),45905.0) -> 45905 | Q39: =IF(K39="Hoàn thành", P39, "") | R39: 1 | T39: hs sai hien trang | U39: Đợi phương án | V39: Đã thanh toán
A40: 45891.497 | B40: 32-GPS/BK-2025 | C40: Lý Thị Thuỳ Dung | D40: Có | E40: Tam Bình | F40: Cô Hoa | H40: Lê Văn Dựng | I40: Không cần | K40: {=IFERROR(VLOOKUP(B40, SORT('Nhật ký nộp hồ sơ '!B:D, 'Nhật ký nộp hồ sơ '!A:A, FALSE), 3, FALSE),"")} -> Hoàn thành | L40: =IF(K40="Hủy","ĐÃ HỦY", IF(K40="Nộp thành công - Chờ kết quả","Đã nộp", IF(K40="Hoàn thành","Hoàn thành", IF(O40="","", IF(TODAY()>O40,"QUÁ HẠN","Trong hạn") )))) -> Hoàn thành | M40: Đo GPS | N40: =IFERROR(__xludf.DUMMYFUNCTION("""COMPUTED_VALUE"""),45891.0) -> 45891 | O40: 45894 | P40: =IFERROR(__xludf.DUMMYFUNCTION("IFERROR(QUERY('Nhật ký nộp hồ sơ '!A:I, ""SELECT I WHERE B = '""&B40&""' ORDER BY A DESC LIMIT 1"", 0))"),45849.0) -> 45849 | Q40: =IF(K40="Hoàn thành", P40, "") -> 45849 | R40: 1 | V40: Đã thanh toán
...

Sheet Tìm kiếm Hồ sơ
B1: NHẬP SỐ HỢP ĐỒNG | D1: NHẬP TÊN HỒ SƠ | F1: NHẬP TÊN KHÁCH HÀNG
B2: 374
A4: =IFERROR(__xludf.DUMMYFUNCTION("QUERY( 'Bảng tổng hợp'!A:Q, ""SELECT * WHERE A IS NOT NULL"" & IF(B2<>"""", "" AND B CONTAINS '""&B2&""'"", """") & IF(D2<>"""", "" AND C CONTAINS '""&D2&""'"", """") & IF(F2<>"""", "" AND F CONTAINS '""&F2&""'"", """") ) "),"Dấu thời gian") -> Dấu thời gian | B4: =IFERROR(__xludf.DUMMYFUNCTION("""COMPUTED_VALUE"""),"Mã hợp đồng") -> Mã hợp đồng | C4: =IFERROR(__xludf.DUMMYFUNCTION("""COMPUTED_VALUE"""),"Tên hồ sơ") -> Tên hồ sơ | D4: =IFERROR(__xludf.DUMMYFUNCTION("""COMPUTED_VALUE"""),"Pháp lý") -> Pháp lý | E4: =IFERROR(__xludf.DUMMYFUNCTION("""COMPUTED_VALUE"""),"Phường ") -> Phường | F4: =IFERROR(__xludf.DUMMYFUNCTION("""COMPUTED_VALUE"""),"Tên khách hàng ") -> Tên khách hàng | G4: =IFERROR(__xludf.DUMMYFUNCTION("""COMPUTED_VALUE"""),"Số Điện Thoại Liên Hệ") -> Số Điện Thoại Liên Hệ | H4: =IFERROR(__xludf.DUMMYFUNCTION("""COMPUTED_VALUE"""),"Phụ Trách Chính") -> Phụ Trách Chính | I4: =IFERROR(__xludf.DUMMYFUNCTION("""COMPUTED_VALUE"""),"Phụ đo") -> Phụ đo | J4: =IFERROR(__xludf.DUMMYFUNCTION("""COMPUTED_VALUE"""),"Độ ưu tiên") -> Độ ưu tiên | K4: =IFERROR(__xludf.DUMMYFUNCTION("""COMPUTED_VALUE"""),"Trạng thái mới nhất") -> Trạng thái mới nhất | L4: =IFERROR(__xludf.DUMMYFUNCTION("""COMPUTED_VALUE"""),"Cảnh báo") -> Cảnh báo | M4: =IFERROR(__xludf.DUMMYFUNCTION("""COMPUTED_VALUE"""),"Hạng mục công việc") -> Hạng mục công việc | N4: =IFERROR(__xludf.DUMMYFUNCTION("""COMPUTED_VALUE"""),"Ngày bắt đầu") -> Ngày bắt đầu | O4: =IFERROR(__xludf.DUMMYFUNCTION("""COMPUTED_VALUE"""),"Hạn xử lý") -> Hạn xử lý | P4: =IFERROR(__xludf.DUMMYFUNCTION("""COMPUTED_VALUE"""),"Ngày nộp ") -> Ngày nộp | Q4: =IFERROR(__xludf.DUMMYFUNCTION("""COMPUTED_VALUE"""),"Ngày HT") -> Ngày HT
A5: =IFERROR(__xludf.DUMMYFUNCTION("""COMPUTED_VALUE"""),45890.46292042825) -> 45890.463 | B5: =IFERROR(__xludf.DUMMYFUNCTION("""COMPUTED_VALUE"""),"374/BK-2025") -> 374/BK-2025 | C5: =IFERROR(__xludf.DUMMYFUNCTION("""COMPUTED_VALUE"""),"Nguyễn Thị Bạch Tuyết") -> Nguyễn Thị Bạch Tuyết | E5: =IFERROR(__xludf.DUMMYFUNCTION("""COMPUTED_VALUE"""),"Long Phước") -> Long Phước | F5: =IFERROR(__xludf.DUMMYFUNCTION("""COMPUTED_VALUE"""),"Công Ty") -> Công Ty | G5: =IFERROR(__xludf.DUMMYFUNCTION("""COMPUTED_VALUE"""),"909794949") -> 909794949 | H5: =IFERROR(__xludf.DUMMYFUNCTION("""COMPUTED_VALUE"""),"Lê Văn Dựng") -> Lê Văn Dựng | I5: =IFERROR(__xludf.DUMMYFUNCTION("""COMPUTED_VALUE"""),"Không cần") -> Không cần | K5: =IFERROR(__xludf.DUMMYFUNCTION("""COMPUTED_VALUE"""),"Hoàn thành") -> Hoàn thành | L5: =IFERROR(__xludf.DUMMYFUNCTION("""COMPUTED_VALUE"""),"Hoàn thành") -> Hoàn thành | M5: =IFERROR(__xludf.DUMMYFUNCTION("""COMPUTED_VALUE"""),"Cấp đổi") -> Cấp đổi | N5: =IFERROR(__xludf.DUMMYFUNCTION("""COMPUTED_VALUE"""),45890.0) -> 45890 | O5: =IFERROR(__xludf.DUMMYFUNCTION("""COMPUTED_VALUE"""),45893.0) -> 45893 | P5: =IFERROR(__xludf.DUMMYFUNCTION("""COMPUTED_VALUE"""),45904.0) -> 45904 | Q5: =IFERROR(__xludf.DUMMYFUNCTION("""COMPUTED_VALUE"""),45904.0) -> 45904
A6: =IFERROR(__xludf.DUMMYFUNCTION("""COMPUTED_VALUE"""),46188.755579375) -> 46188.756 | B6: =IFERROR(__xludf.DUMMYFUNCTION("""COMPUTED_VALUE"""),"374/BK-2026") -> 374/BK-2026 | C6: =IFERROR(__xludf.DUMMYFUNCTION("""COMPUTED_VALUE"""),"Đỗ Thị Ánh Hằng") -> Đỗ Thị Ánh Hằng | E6: =IFERROR(__xludf.DUMMYFUNCTION("""COMPUTED_VALUE"""),"Long Phước") -> Long Phước | F6: =IFERROR(__xludf.DUMMYFUNCTION("""COMPUTED_VALUE"""),"Công Ty") -> Công Ty | H6: =IFERROR(__xludf.DUMMYFUNCTION("""COMPUTED_VALUE"""),"Tạ Khắc Tập") -> Tạ Khắc Tập | I6: =IFERROR(__xludf.DUMMYFUNCTION("""COMPUTED_VALUE"""),"Võ Tứ Hợp") -> Võ Tứ Hợp | K6: =IFERROR(__xludf.DUMMYFUNCTION("""COMPUTED_VALUE"""),"Nộp thành công - Chờ kết quả") -> Nộp thành công - Chờ kết quả | L6: =IFERROR(__xludf.DUMMYFUNCTION("""COMPUTED_VALUE"""),"Đã nộp") -> Đã nộp | M6: =IFERROR(__xludf.DUMMYFUNCTION("""COMPUTED_VALUE"""),"Cấp đổi") -> Cấp đổi | N6: =IFERROR(__xludf.DUMMYFUNCTION("""COMPUTED_VALUE"""),46188.0) -> 46188 | O6: =IFERROR(__xludf.DUMMYFUNCTION("""COMPUTED_VALUE"""),46191.0) -> 46191 | P6: =IFERROR(__xludf.DUMMYFUNCTION("""COMPUTED_VALUE"""),46191.0) -> 46191

Sheet Xếp hạng Ưu tiên
A1: Tên Nhân viên | B1: Hồ sơ trong hạn | C1: Trong hạn đã giải trình | D1: Trong hạn chưa giải trình | E1: Trong hạn đã giải trình đã cho phương án | F1: Xử lý thực tế trong hạn | G1: Tổng hồ sơ đã giải trình | H1: Tổng hồ sơ chưa giải trình | I1: Tổng Số HS đã cho phương án | J1: Thứ tự Ưu tiên
A2: {=SORT('Tải Công Việc'!A2:I1001, 6, TRUE, 9, TRUE, 8, TRUE, 3, TRUE)} -> Nguyễn Minh Thông | B2: 0 | C2: 0 | D2: 0 | E2: 0 | F2: 0 | G2: 0 | H2: 0 | I2: 0 | J2: ="Ưu tiên số " & ROW(A1) -> Ưu tiên số 1
A3: Lê Văn Xây | B3: 0 | C3: 0 | D3: 0 | E3: 0 | F3: 0 | G3: 0 | H3: 1 | I3: 0 | J3: ="Ưu tiên số " & ROW(A2) -> Ưu tiên số 2
A4: Tạ Khắc Tập | B4: 0 | C4: 0 | D4: 0 | E4: 0 | F4: 0 | G4: 2 | H4: 2 | I4: 0 | J4: ="Ưu tiên số " & ROW(A3) -> Ưu tiên số 3
A5: Trương Tấn Quốc | B5: 0 | C5: 0 | D5: 0 | E5: 0 | F5: 0 | G5: 1 | H5: 4 | I5: 0 | J5: ="Ưu tiên số " & ROW(A4) -> Ưu tiên số 4
A6: Lê Văn Dựng | B6: 1 | C6: 0 | D6: 1 | E6: 0 | F6: 1 | G6: 0 | H6: 3 | I6: 0 | J6: ="Ưu tiên số " & ROW(A5) -> Ưu tiên số 5
A7: Võ Thành Minh
A8: Võ Tứ Hợp

Sheet Tải Công Việc
A1: Tên Nhân viên | B1: Hồ sơ trong hạn | C1: Trong hạn đã giải trình | D1: Trong hạn chưa giải trình | E1: Trong hạn đã giải trình đã cho phương án | F1: Xử lý thực tế | G1: Tổng hồ sơ đã giải trình | H1: Tổng hồ sơ chưa giải trình | I1: Tổng HS đã cho phương án
A2: {=UNIQUE('Bảng tổng hợp'!H2:H999)} -> Lê Văn Dựng | B2: =COUNTIFS('Bảng tổng hợp'!H:H, A2, 'Bảng tổng hợp'!L:L, "trong hạn") -> 1 | C2: =COUNTIFS('Bảng tổng hợp'!H:H, A2, 'Bảng tổng hợp'!L:L, "Trong hạn", 'Bảng tổng hợp'!T:T, "<>") -> 0 | D2: =sum(B2-C2) -> 1 | E2: =COUNTIFS('Bảng tổng hợp'!H:H, A2, 'Bảng tổng hợp'!L:L, "Trong hạn", 'Bảng tổng hợp'!T:T, "<>", 'Bảng tổng hợp'!U:U, "Đã cho phương án") -> 0 | F2: =sum(D2+E2) -> 1 | G2: =COUNTIFS('Giải trình '!F:F, A2, 'Giải trình '!H:H, "<>") -> 0 | H2: =COUNTIFS('Giải trình '!F:F, A2, 'Giải trình '!H:H, "") -> 3 | I2: =COUNTIFS('Giải trình '!F:F, A2, 'Giải trình '!I:I, "Đã cho phương án") -> 0
A3: Tạ Khắc Tập | B3: =COUNTIFS('Bảng tổng hợp'!H:H, A3, 'Bảng tổng hợp'!L:L, "trong hạn") -> 0 | C3: =COUNTIFS('Bảng tổng hợp'!H:H, A3, 'Bảng tổng hợp'!L:L, "Trong hạn", 'Bảng tổng hợp'!T:T, "<>") -> 0 | D3: =sum(B3-C3) -> 0 | E3: =COUNTIFS('Bảng tổng hợp'!H:H, A3, 'Bảng tổng hợp'!L:L, "Trong hạn", 'Bảng tổng hợp'!T:T, "<>", 'Bảng tổng hợp'!U:U, "Đã cho phương án") -> 0 | F3: =sum(D3+E3) -> 0 | G3: =COUNTIFS('Giải trình '!F:F, A3, 'Giải trình '!H:H, "<>") -> 2 | H3: =COUNTIFS('Giải trình '!F:F, A3, 'Giải trình '!H:H, "") -> 2 | I3: =COUNTIFS('Giải trình '!F:F, A3, 'Giải trình '!I:I, "Đã cho phương án") -> 0
A4: Trương Tấn Quốc | B4: =COUNTIFS('Bảng tổng hợp'!H:H, A4, 'Bảng tổng hợp'!L:L, "trong hạn") -> 0 | C4: =COUNTIFS('Bảng tổng hợp'!H:H, A4, 'Bảng tổng hợp'!L:L, "Trong hạn", 'Bảng tổng hợp'!T:T, "<>") -> 0 | D4: =sum(B4-C4) -> 0 | E4: =COUNTIFS('Bảng tổng hợp'!H:H, A4, 'Bảng tổng hợp'!L:L, "Trong hạn", 'Bảng tổng hợp'!T:T, "<>", 'Bảng tổng hợp'!U:U, "Đã cho phương án") -> 0 | F4: =sum(D4+E4) -> 0 | G4: =COUNTIFS('Giải trình '!F:F, A4, 'Giải trình '!H:H, "<>") -> 1 | H4: =COUNTIFS('Giải trình '!F:F, A4, 'Giải trình '!H:H, "") -> 4 | I4: =COUNTIFS('Giải trình '!F:F, A4, 'Giải trình '!I:I, "Đã cho phương án") -> 0
A5: Nguyễn Minh Thông | B5: =COUNTIFS('Bảng tổng hợp'!H:H, A5, 'Bảng tổng hợp'!L:L, "trong hạn") -> 0 | C5: =COUNTIFS('Bảng tổng hợp'!H:H, A5, 'Bảng tổng hợp'!L:L, "Trong hạn", 'Bảng tổng hợp'!T:T, "<>") -> 0 | D5: =sum(B5-C5) -> 0 | E5: =COUNTIFS('Bảng tổng hợp'!H:H, A5, 'Bảng tổng hợp'!L:L, "Trong hạn", 'Bảng tổng hợp'!T:T, "<>", 'Bảng tổng hợp'!U:U, "Đã cho phương án") -> 0 | F5: =sum(D5+E5) -> 0 | G5: =COUNTIFS('Giải trình '!F:F, A5, 'Giải trình '!H:H, "<>") -> 0 | H5: =COUNTIFS('Giải trình '!F:F, A5, 'Giải trình '!H:H, "") -> 0 | I5: =COUNTIFS('Giải trình '!F:F, A5, 'Giải trình '!I:I, "Đã cho phương án") -> 0
A6: Lê Văn Xây | B6: =COUNTIFS('Bảng tổng hợp'!H:H, A6, 'Bảng tổng hợp'!L:L, "trong hạn") -> 0 | C6: =COUNTIFS('Bảng tổng hợp'!H:H, A6, 'Bảng tổng hợp'!L:L, "Trong hạn", 'Bảng tổng hợp'!T:T, "<>") -> 0 | D6: =sum(B6-C6) -> 0 | E6: =COUNTIFS('Bảng tổng hợp'!H:H, A6, 'Bảng tổng hợp'!L:L, "Trong hạn", 'Bảng tổng hợp'!T:T, "<>", 'Bảng tổng hợp'!U:U, "Đã cho phương án") -> 0 | F6: =sum(D6+E6) -> 0 | G6: =COUNTIFS('Giải trình '!F:F, A6, 'Giải trình '!H:H, "<>") -> 0 | H6: =COUNTIFS('Giải trình '!F:F, A6, 'Giải trình '!H:H, "") -> 1 | I6: =COUNTIFS('Giải trình '!F:F, A6, 'Giải trình '!I:I, "Đã cho phương án") -> 0 | S6: =COUNTIFS('Bảng tổng hợp'!H:H, #REF!, 'Bảng tổng hợp'!K:K, "") -> 0
A7: Võ Thành Minh
A8: Võ Tứ Hợp

Sheet Giải trình 
A1: =IFERROR(__xludf.DUMMYFUNCTION("QUERY('Bảng tổng hợp'!A:U, ""SELECT B, C, E, F, O, H, I, T, U, L WHERE L = 'QUÁ HẠN' OR L = 'Trong hạn'"")"),"Mã hợp đồng") -> Mã hợp đồng | B1: =IFERROR(__xludf.DUMMYFUNCTION("""COMPUTED_VALUE"""),"Tên hồ sơ") -> Tên hồ sơ | C1: =IFERROR(__xludf.DUMMYFUNCTION("""COMPUTED_VALUE"""),"Phường ") -> Phường | D1: =IFERROR(__xludf.DUMMYFUNCTION("""COMPUTED_VALUE"""),"Tên khách hàng ") -> Tên khách hàng | E1: =IFERROR(__xludf.DUMMYFUNCTION("""COMPUTED_VALUE"""),"Hạn xử lý") -> Hạn xử lý | F1: =IFERROR(__xludf.DUMMYFUNCTION("""COMPUTED_VALUE"""),"Phụ Trách Chính") -> Phụ Trách Chính | G1: =IFERROR(__xludf.DUMMYFUNCTION("""COMPUTED_VALUE"""),"Phụ đo") -> Phụ đo | H1: =IFERROR(__xludf.DUMMYFUNCTION("""COMPUTED_VALUE"""),"Giải trình lý do") -> Giải trình lý do | I1: =IFERROR(__xludf.DUMMYFUNCTION("""COMPUTED_VALUE"""),"Quản lý phê duyệt") -> Quản lý phê duyệt | J1: =IFERROR(__xludf.DUMMYFUNCTION("""COMPUTED_VALUE"""),"Cảnh báo") -> Cảnh báo
A2: =IFERROR(__xludf.DUMMYFUNCTION("""COMPUTED_VALUE"""),"168/BK-2026") -> 168/BK-2026 | B2: =IFERROR(__xludf.DUMMYFUNCTION("""COMPUTED_VALUE"""),"Trần Thị Tuyết Nhung") -> Trần Thị Tuyết Nhung | C2: =IFERROR(__xludf.DUMMYFUNCTION("""COMPUTED_VALUE"""),"Cát Lái") -> Cát Lái | D2: =IFERROR(__xludf.DUMMYFUNCTION("""COMPUTED_VALUE"""),"Nguyễn Hương DV") -> Nguyễn Hương DV | E2: =IFERROR(__xludf.DUMMYFUNCTION("""COMPUTED_VALUE"""),46111.0) -> 46111 | F2: =IFERROR(__xludf.DUMMYFUNCTION("""COMPUTED_VALUE"""),"Trương Tấn Quốc") -> Trương Tấn Quốc | G2: =IFERROR(__xludf.DUMMYFUNCTION("""COMPUTED_VALUE"""),"Tạ Khắc Tập") -> Tạ Khắc Tập | H2: =IFERROR(__xludf.DUMMYFUNCTION("""COMPUTED_VALUE"""),"Hở ranh chờ trao đổii") -> Hở ranh chờ trao đổii | J2: =IFERROR(__xludf.DUMMYFUNCTION("""COMPUTED_VALUE"""),"QUÁ HẠN") -> QUÁ HẠN
A3: =IFERROR(__xludf.DUMMYFUNCTION("""COMPUTED_VALUE"""),"299/BK-2026") -> 299/BK-2026 | B3: =IFERROR(__xludf.DUMMYFUNCTION("""COMPUTED_VALUE"""),"Tô Duy Nam") -> Tô Duy Nam | C3: =IFERROR(__xludf.DUMMYFUNCTION("""COMPUTED_VALUE"""),"Hiệp Bình") -> Hiệp Bình | D3: =IFERROR(__xludf.DUMMYFUNCTION("""COMPUTED_VALUE"""),"Cô Hoa") -> Cô Hoa | E3: =IFERROR(__xludf.DUMMYFUNCTION("""COMPUTED_VALUE"""),46158.0) -> 46158 | F3: =IFERROR(__xludf.DUMMYFUNCTION("""COMPUTED_VALUE"""),"Lê Văn Xây") -> Lê Văn Xây | G3: =IFERROR(__xludf.DUMMYFUNCTION("""COMPUTED_VALUE"""),"Võ Tứ Hợp") -> Võ Tứ Hợp | J3: =IFERROR(__xludf.DUMMYFUNCTION("""COMPUTED_VALUE"""),"QUÁ HẠN") -> QUÁ HẠN
A4: =IFERROR(__xludf.DUMMYFUNCTION("""COMPUTED_VALUE"""),"311/BK-2026") -> 311/BK-2026 | B4: =IFERROR(__xludf.DUMMYFUNCTION("""COMPUTED_VALUE"""),"Vũ Thanh Hường") -> Vũ Thanh Hường | C4: =IFERROR(__xludf.DUMMYFUNCTION("""COMPUTED_VALUE"""),"Tam Bình") -> Tam Bình | D4: =IFERROR(__xludf.DUMMYFUNCTION("""COMPUTED_VALUE"""),"Cô Hoa") -> Cô Hoa | E4: =IFERROR(__xludf.DUMMYFUNCTION("""COMPUTED_VALUE"""),46164.0) -> 46164 | F4: =IFERROR(__xludf.DUMMYFUNCTION("""COMPUTED_VALUE"""),"Tạ Khắc Tập") -> Tạ Khắc Tập | G4: =IFERROR(__xludf.DUMMYFUNCTION("""COMPUTED_VALUE"""),"Võ Tứ Hợp") -> Võ Tứ Hợp | H4: =IFERROR(__xludf.DUMMYFUNCTION("""COMPUTED_VALUE"""),"chờ trích lục GPĐC, VẼ GIẢM") -> chờ trích lục GPĐC, VẼ GIẢM | J4: =IFERROR(__xludf.DUMMYFUNCTION("""COMPUTED_VALUE"""),"QUÁ HẠN") -> QUÁ HẠN
A5: =IFERROR(__xludf.DUMMYFUNCTION("""COMPUTED_VALUE"""),"317/BK-2026") -> 317/BK-2026 | B5: =IFERROR(__xludf.DUMMYFUNCTION("""COMPUTED_VALUE"""),"Lê Hồng Thư") -> Lê Hồng Thư | C5: =IFERROR(__xludf.DUMMYFUNCTION("""COMPUTED_VALUE"""),"Long Bình") -> Long Bình | D5: =IFERROR(__xludf.DUMMYFUNCTION("""COMPUTED_VALUE"""),"Công Ty") -> Công Ty | E5: =IFERROR(__xludf.DUMMYFUNCTION("""COMPUTED_VALUE"""),46166.0) -> 46166 | F5: =IFERROR(__xludf.DUMMYFUNCTION("""COMPUTED_VALUE"""),"Lê Văn Dựng") -> Lê Văn Dựng | G5: =IFERROR(__xludf.DUMMYFUNCTION("""COMPUTED_VALUE"""),"Tạ Khắc Tập") -> Tạ Khắc Tập | J5: =IFERROR(__xludf.DUMMYFUNCTION("""COMPUTED_VALUE"""),"QUÁ HẠN") -> QUÁ HẠN
A6: =IFERROR(__xludf.DUMMYFUNCTION("""COMPUTED_VALUE"""),"340/BK-2026") -> 340/BK-2026 | B6: =IFERROR(__xludf.DUMMYFUNCTION("""COMPUTED_VALUE"""),"Trịnh Thị Tâm") -> Trịnh Thị Tâm | C6: =IFERROR(__xludf.DUMMYFUNCTION("""COMPUTED_VALUE"""),"Tam Bình") -> Tam Bình | D6: =IFERROR(__xludf.DUMMYFUNCTION("""COMPUTED_VALUE"""),"Công Ty") -> Công Ty | E6: =IFERROR(__xludf.DUMMYFUNCTION("""COMPUTED_VALUE"""),46175.0) -> 46175 | F6: =IFERROR(__xludf.DUMMYFUNCTION("""COMPUTED_VALUE"""),"Tạ Khắc Tập") -> Tạ Khắc Tập | G6: =IFERROR(__xludf.DUMMYFUNCTION("""COMPUTED_VALUE"""),"Võ Tứ Hợp") -> Võ Tứ Hợp | H6: =IFERROR(__xludf.DUMMYFUNCTION("""COMPUTED_VALUE"""),"lệch ranh chờ phương an") -> lệch ranh chờ phương an | J6: =IFERROR(__xludf.DUMMYFUNCTION("""COMPUTED_VALUE"""),"QUÁ HẠN") -> QUÁ HẠN
A7: =IFERROR(__xludf.DUMMYFUNCTION("""COMPUTED_VALUE"""),"347/BK-2026") -> 347/BK-2026 | B7: =IFERROR(__xludf.DUMMYFUNCTION("""COMPUTED_VALUE"""),"Nguyễn Văn Đâu") -> Nguyễn Văn Đâu | C7: =IFERROR(__xludf.DUMMYFUNCTION("""COMPUTED_VALUE"""),"Phước Long") -> Phước Long | D7: =IFERROR(__xludf.DUMMYFUNCTION("""COMPUTED_VALUE"""),"Đạt Việt Phát Land") -> Đạt Việt Phát Land | E7: =IFERROR(__xludf.DUMMYFUNCTION("""COMPUTED_VALUE"""),46182.0) -> 46182 | F7: =IFERROR(__xludf.DUMMYFUNCTION("""COMPUTED_VALUE"""),"Lê Văn Dựng") -> Lê Văn Dựng | G7: =IFERROR(__xludf.DUMMYFUNCTION("""COMPUTED_VALUE"""),"Võ Tứ Hợp") -> Võ Tứ Hợp | J7: =IFERROR(__xludf.DUMMYFUNCTION("""COMPUTED_VALUE"""),"QUÁ HẠN") -> QUÁ HẠN
A8: =IFERROR(__xludf.DUMMYFUNCTION("""COMPUTED_VALUE"""),"350/BK-2026") -> 350/BK-2026 | B8: =IFERROR(__xludf.DUMMYFUNCTION("""COMPUTED_VALUE"""),"Nguyễn Đức Mẫn") -> Nguyễn Đức Mẫn | C8: =IFERROR(__xludf.DUMMYFUNCTION("""COMPUTED_VALUE"""),"Hiệp Bình") -> Hiệp Bình | D8: =IFERROR(__xludf.DUMMYFUNCTION("""COMPUTED_VALUE"""),"Công Ty") -> Công Ty | E8: =IFERROR(__xludf.DUMMYFUNCTION("""COMPUTED_VALUE"""),46184.0) -> 46184 | F8: =IFERROR(__xludf.DUMMYFUNCTION("""COMPUTED_VALUE"""),"Trương Tấn Quốc") -> Trương Tấn Quốc | G8: =IFERROR(__xludf.DUMMYFUNCTION("""COMPUTED_VALUE"""),"Võ Tứ Hợp") -> Võ Tứ Hợp | J8: =IFERROR(__xludf.DUMMYFUNCTION("""COMPUTED_VALUE"""),"QUÁ HẠN") -> QUÁ HẠN
A9: =IFERROR(__xludf.DUMMYFUNCTION("""COMPUTED_VALUE"""),"353/BK-2026") -> 353/BK-2026 | B9: =IFERROR(__xludf.DUMMYFUNCTION("""COMPUTED_VALUE"""),"Lê Chí Việt") -> Lê Chí Việt | C9: =IFERROR(__xludf.DUMMYFUNCTION("""COMPUTED_VALUE"""),"Hiệp Bình") -> Hiệp Bình | D9: =IFERROR(__xludf.DUMMYFUNCTION("""COMPUTED_VALUE"""),"Công Ty") -> Công Ty | E9: =IFERROR(__xludf.DUMMYFUNCTION("""COMPUTED_VALUE"""),46185.0) -> 46185 | F9: =IFERROR(__xludf.DUMMYFUNCTION("""COMPUTED_VALUE"""),"Trương Tấn Quốc") -> Trương Tấn Quốc | G9: =IFERROR(__xludf.DUMMYFUNCTION("""COMPUTED_VALUE"""),"Võ Tứ Hợp") -> Võ Tứ Hợp | J9: =IFERROR(__xludf.DUMMYFUNCTION("""COMPUTED_VALUE"""),"QUÁ HẠN") -> QUÁ HẠN
A10: =IFERROR(__xludf.DUMMYFUNCTION("""COMPUTED_VALUE"""),"356/BK-2026") -> 356/BK-2026 | B10: =IFERROR(__xludf.DUMMYFUNCTION("""COMPUTED_VALUE"""),"Bùi Anh Dũng") -> Bùi Anh Dũng | C10: =IFERROR(__xludf.DUMMYFUNCTION("""COMPUTED_VALUE"""),"Tam Bình") -> Tam Bình | D10: =IFERROR(__xludf.DUMMYFUNCTION("""COMPUTED_VALUE"""),"Cô Hoa") -> Cô Hoa | E10: =IFERROR(__xludf.DUMMYFUNCTION("""COMPUTED_VALUE"""),46186.0) -> 46186 | F10: =IFERROR(__xludf.DUMMYFUNCTION("""COMPUTED_VALUE"""),"Tạ Khắc Tập") -> Tạ Khắc Tập | G10: =IFERROR(__xludf.DUMMYFUNCTION("""COMPUTED_VALUE"""),"Võ Tứ Hợp") -> Võ Tứ Hợp | J10: =IFERROR(__xludf.DUMMYFUNCTION("""COMPUTED_VALUE"""),"QUÁ HẠN") -> QUÁ HẠN
A11: =IFERROR(__xludf.DUMMYFUNCTION("""COMPUTED_VALUE"""),"357/BK-2026") -> 357/BK-2026 | B11: =IFERROR(__xludf.DUMMYFUNCTION("""COMPUTED_VALUE"""),"Nguyễn Văn Quỳnh") -> Nguyễn Văn Quỳnh | C11: =IFERROR(__xludf.DUMMYFUNCTION("""COMPUTED_VALUE"""),"Tam Bình") -> Tam Bình | D11: =IFERROR(__xludf.DUMMYFUNCTION("""COMPUTED_VALUE"""),"Cô Hoa") -> Cô Hoa | E11: =IFERROR(__xludf.DUMMYFUNCTION("""COMPUTED_VALUE"""),46186.0) -> 46186 | F11: =IFERROR(__xludf.DUMMYFUNCTION("""COMPUTED_VALUE"""),"Tạ Khắc Tập") -> Tạ Khắc Tập | G11: =IFERROR(__xludf.DUMMYFUNCTION("""COMPUTED_VALUE"""),"Võ Tứ Hợp") -> Võ Tứ Hợp | J11: =IFERROR(__xludf.DUMMYFUNCTION("""COMPUTED_VALUE"""),"QUÁ HẠN") -> QUÁ HẠN
A12: =IFERROR(__xludf.DUMMYFUNCTION("""COMPUTED_VALUE"""),"365/BK-2026") -> 365/BK-2026 | B12: =IFERROR(__xludf.DUMMYFUNCTION("""COMPUTED_VALUE"""),"Hồ Trọng Dũng ") -> Hồ Trọng Dũng | C12: =IFERROR(__xludf.DUMMYFUNCTION("""COMPUTED_VALUE"""),"Hiệp Bình") -> Hiệp Bình | D12: =IFERROR(__xludf.DUMMYFUNCTION("""COMPUTED_VALUE"""),"Anh Tùng Bất Động Sản") -> Anh Tùng Bất Động Sản | E12: =IFERROR(__xludf.DUMMYFUNCTION("""COMPUTED_VALUE"""),46191.0) -> 46191 | F12: =IFERROR(__xludf.DUMMYFUNCTION("""COMPUTED_VALUE"""),"Võ Thành Minh") -> Võ Thành Minh | G12: =IFERROR(__xludf.DUMMYFUNCTION("""COMPUTED_VALUE"""),"Không cần") -> Không cần | J12: =IFERROR(__xludf.DUMMYFUNCTION("""COMPUTED_VALUE"""),"QUÁ HẠN") -> QUÁ HẠN
A13: =IFERROR(__xludf.DUMMYFUNCTION("""COMPUTED_VALUE"""),"383/BK-2026") -> 383/BK-2026 | B13: =IFERROR(__xludf.DUMMYFUNCTION("""COMPUTED_VALUE"""),"Nguyễn Ngọc Thu 1") -> Nguyễn Ngọc Thu 1 | C13: =IFERROR(__xludf.DUMMYFUNCTION("""COMPUTED_VALUE"""),"Tăng Nhơn Phú") -> Tăng Nhơn Phú | D13: =IFERROR(__xludf.DUMMYFUNCTION("""COMPUTED_VALUE"""),"Đạt Việt Phát Land") -> Đạt Việt Phát Land | E13: =IFERROR(__xludf.DUMMYFUNCTION("""COMPUTED_VALUE"""),46192.0) -> 46192 | F13: =IFERROR(__xludf.DUMMYFUNCTION("""COMPUTED_VALUE"""),"Trương Tấn Quốc") -> Trương Tấn Quốc | G13: =IFERROR(__xludf.DUMMYFUNCTION("""COMPUTED_VALUE"""),"Võ Tứ Hợp") -> Võ Tứ Hợp | J13: =IFERROR(__xludf.DUMMYFUNCTION("""COMPUTED_VALUE"""),"QUÁ HẠN") -> QUÁ HẠN
A14: =IFERROR(__xludf.DUMMYFUNCTION("""COMPUTED_VALUE"""),"384/BK-2026") -> 384/BK-2026 | B14: =IFERROR(__xludf.DUMMYFUNCTION("""COMPUTED_VALUE"""),"Nguyễn Ngọc Thu 2") -> Nguyễn Ngọc Thu 2 | C14: =IFERROR(__xludf.DUMMYFUNCTION("""COMPUTED_VALUE"""),"Tăng Nhơn Phú") -> Tăng Nhơn Phú | D14: =IFERROR(__xludf.DUMMYFUNCTION("""COMPUTED_VALUE"""),"Đạt Việt Phát Land") -> Đạt Việt Phát Land | E14: =IFERROR(__xludf.DUMMYFUNCTION("""COMPUTED_VALUE"""),46192.0) -> 46192 | F14: =IFERROR(__xludf.DUMMYFUNCTION("""COMPUTED_VALUE"""),"Trương Tấn Quốc") -> Trương Tấn Quốc | G14: =IFERROR(__xludf.DUMMYFUNCTION("""COMPUTED_VALUE"""),"Võ Tứ Hợp") -> Võ Tứ Hợp | J14: =IFERROR(__xludf.DUMMYFUNCTION("""COMPUTED_VALUE"""),"QUÁ HẠN") -> QUÁ HẠN
A15: =IFERROR(__xludf.DUMMYFUNCTION("""COMPUTED_VALUE"""),"395/BK-2026") -> 395/BK-2026 | B15: =IFERROR(__xludf.DUMMYFUNCTION("""COMPUTED_VALUE"""),"Đinh Văn Hoàng Hải(Bình Thạnh)") -> Đinh Văn Hoàng Hải(Bình Thạnh) | C15: =IFERROR(__xludf.DUMMYFUNCTION("""COMPUTED_VALUE"""),"Ngoài Thủ Đức") -> Ngoài Thủ Đức | D15: =IFERROR(__xludf.DUMMYFUNCTION("""COMPUTED_VALUE"""),"Công Ty") -> Công Ty | E15: =IFERROR(__xludf.DUMMYFUNCTION("""COMPUTED_VALUE"""),46199.0) -> 46199 | F15: =IFERROR(__xludf.DUMMYFUNCTION("""COMPUTED_VALUE"""),"Lê Văn Dựng") -> Lê Văn Dựng | G15: =IFERROR(__xludf.DUMMYFUNCTION("""COMPUTED_VALUE"""),"Võ Tứ Hợp") -> Võ Tứ Hợp | J15: =IFERROR(__xludf.DUMMYFUNCTION("""COMPUTED_VALUE"""),"Trong hạn") -> Trong hạn

Sheet Nhật ký nộp hồ sơ 
A1: Dấu thời gian | B1: Mã hợp đồng: | C1: Người đi nộp | D1: Kết quả lần nộp: | E1: Ghi chú / Yêu cầu của cán bộ: | F1: Ngày hẹn trả kết quả | G1: Ảnh chụp biên nhận | H1: Người nhận báo cáo | I1: Ngày đi nộp | J1: FILE BẢN VẼ ĐẠT | K1: Mã hợp đồng đang xử lý:
A2: 45884.452 | B2: 272/BK-2025 | C2: Không cần | D2: Hoàn thành | H2: Vy | I2: 45880
A3: 45884.454 | B3: 273/BK-2025 | C3: Không cần | D3: Hoàn thành | H3: Vy | I3: 45880
A4: 45884.454 | B4: 274/BK-2025 | C4: Không cần | D4: Hoàn thành | H4: Vy | I4: 45883
A5: 45883.687 | B5: 330/BK-2025 | C5: Vy | D5: Nộp thành công - Chờ kết quả | F5: 45894 | G5: https://drive.google.com/open?id=1mbWSdEzmuVAbsYg3sEBo9Vx1DaLL4eF_ | H5: Vy | I5: 45882
A6: 45883.493 | B6: 334/BK-2025 | C6: Không cần | D6: Hoàn thành | F6: 45878 | H6: Vy | I6: 45879
A7: 45881.684 | B7: 335/BK-2025 | C7: Hằng | D7: Nộp thành công - Chờ kết quả | F7: 45891 | G7: https://drive.google.com/open?id=1KZMi-oZkW51FO5qW-25h-W3sq5JwGoPD | H7: Vy | I7: 45880
A8: 45883.49 | B8: 336/BK-2025 | C8: Không cần | D8: Hoàn thành | H8: Vy | I8: 45878
A9: 45884.624 | B9: 337/BK-2025 | C9: Hằng | D9: Nộp thành công - Chờ kết quả | F9: 45895 | G9: https://drive.google.com/open?id=1CCrH-j3BNTvR75TunGGSsKb7oXpPqgYd | H9: Vy | I9: 45884
A10: 45884.667 | B10: 338/BK-2025 | C10: Hằng | D10: Nộp thành công - Chờ kết quả | F10: 45896 | G10: https://drive.google.com/open?id=1Re8nkozMAR6RyxfONEnB07E_Cx1Inqlf | H10: Vy | I10: 45884
A11: 45883.493 | B11: 339/BK-225 | C11: Không cần | D11: Hoàn thành | H11: Vy | I11: 45879
A12: 45882.663 | B12: 341/BK-2025 | C12: Vy | D12: Nộp thành công - Chờ kết quả | F12: 45894 | G12: https://drive.google.com/open?id=1_cGRHw5lyvnfewQwwYb8TwelB9CaKZmJ | H12: Vy | I12: 45881
A13: 45883.491 | B13: 342/BK-2025 | C13: Không cần | D13: Hoàn thành | H13: Vy | I13: 45881
A14: 45884.339 | B14: 343/BK-2025 | C14: Không cần | D14: Hoàn thành | H14: Vy | I14: 45881
A15: 45883.494 | B15: 344/BK-2025 | C15: Không cần | D15: Hoàn thành | H15: Vy | I15: 45874
A16: 45883.588 | B16: 345/BK-2025 | C16: Vy | D16: Nộp thành công - Chờ kết quả | F16: 45894 | G16: https://drive.google.com/open?id=128EjSWz_8TOhPZQahkOKsKSMdzkqetGH | H16: Vy | I16: 45882
A17: 45883.59 | B17: 346/BK-2025 | C17: Vy | D17: Nộp thành công - Chờ kết quả | F17: 45894 | G17: https://drive.google.com/open?id=1pGdKsJFlC4Dg9fgFsHg_K52gg24aX0XG | H17: Vy | I17: 45882
A18: 45883.495 | B18: 351/BK-2025 | C18: Không cần | D18: Hoàn thành | H18: Vy | I18: 45882
A19: 45883.496 | B19: 352/BK-2025 | C19: Không cần | D19: Hoàn thành | H19: Vy | I19: 45882
A20: 45884.34 | B20: 354/BK-2025 | C20: Không cần | D20: Hoàn thành | H20: Vy | I20: 45882
A21: 45883.696 | B21: 355/BK-2025 | C21: Không cần | D21: Hoàn thành | H21: Vy | I21: 45883
A22: 45885.342 | B22: 359/BK-2025 | C22: Không cần | D22: Hoàn thành | H22: Vy | I22: 45883
A23: 45884.586 | B23: 552-1/BK-2025 | C23: Hằng | D23: Nộp thành công - Chờ kết quả | F23: 45889 | G23: https://drive.google.com/open?id=1gWdvwj9lCPRGEoMkc8nF9EyXBp_zyz8H | H23: Vy | I23: 45880
A24: 45884.587 | B24: 552-2/BK-2025 | C24: Hằng | D24: Nộp thành công - Chờ kết quả | F24: 45889 | G24: https://drive.google.com/open?id=1VVRXxw73EslTyEPCo7eM4fXk6CYADLGW | H24: Vy | I24: 45880
A25: 45887.584 | B25: 346/BK-2025 | C25: Vy | D25: Hoàn thành | H25: Vy | I25: 45887 | J25: https://drive.google.com/open?id=1nF98DlNKLNrds70wau9NxVMJFefSQeQ0
A26: 45887.627 | B26: 360/BK-2025 | C26: Hằng | D26: Nộp thành công - Chờ kết quả | F26: 45896 | G26: https://drive.google.com/open?id=1x-LJoOSs6_6UUdiZAn4BXC70tQlh1i6l | H26: Vy | I26: 45887
A27: 45887.629 | B27: 219/BK-2025 | C27: Hằng | D27: Nộp thành công - Chờ kết quả | F27: 45896 | G27: https://drive.google.com/open?id=1EdvmkURDhaNgl_yB8O9kh4MltnCBJ3bg | H27: Vy | I27: 45887
A28: 45887.63 | B28: 361/BK-2025 | C28: Không cần | D28: Hoàn thành | H28: Vy | I28: 45887
A29: 45887.719 | B29: 330/BK-2025 | C29: Vy | D29: Hoàn thành | H29: Vy | I29: 45887 | J29: https://drive.google.com/open?id=1lZNte1PvFgMZ6cu_S8Lnvz9spF3H4s-m
A30: 45888.414 | B30: 356/BK-2025 | C30: Vy | D30: Nộp thành công - Chờ kết quả | F30: 45897 | G30: https://drive.google.com/open?id=1h6HfrpkmchRGJTwikvVqXHs66B4nM5FL | H30: Vy | I30: 45887
A31: 45889.381 | B31: 367/BK-2025 | C31: Không cần | D31: Hoàn thành | H31: Vy | I31: 45888
A32: 45889.381 | B32: 368/BK-2025 | C32: Không cần | D32: Hoàn thành | H32: Vy | I32: 45888
A33: 45889.382 | B33: 369/BK-2025 | C33: Không cần | D33: Hoàn thành | H33: Vy | I33: 45888
A34: 45889.384 | B34: 370/BK-2025 | C34: Không cần | D34: Hoàn thành | H34: Vy | I34: 45888
A35: 45889.425 | B35: 363/BK-2025 | C35: Không cần | D35: Hoàn thành | H35: Vy | I35: 45888
A36: 45889.582 | B36: 366/BK-2025 | C36: Không cần | D36: Hoàn thành | H36: Vy | I36: 45889
A37: 45890.456 | B37: 337/BK-2025 | C37: Hằng | D37: Hoàn thành | H37: Vy | I37: 45890 | J37: https://drive.google.com/open?id=1yymKoRo9Sb4PB1ao3BnFBcVY_27tbgpZ
A38: 45890.692 | B38: 372/BK-2025 | C38: Hằng | D38: Nộp thành công - Chờ kết quả | F38: 45903 | G38: https://drive.google.com/open?id=15SAC6dNoNx9UTl_LS8P_h8rWkOsQr5tQ | H38: Vy | I38: 45889
A39: 45890.696 | B39: 375/BK-2025 | C39: Không cần | D39: Hoàn thành | H39: Vy | I39: 45890
A40: 45891.406 | B40: 374/BK-2025 | C40: Hằng | D40: Nộp thành công - Chờ kết quả | F40: 45904 | G40: https://drive.google.com/open?id=1wxL4E4vPaMBXu13vJbn4xjevqfhdwHCu | H40: Vy | I40: 45890
...

Sheet Hợp đồng đang xử lý
A1: shd
A2: =IFERROR(__xludf.DUMMYFUNCTION("FILTER('Bảng tổng hợp'!B:B, ('Bảng tổng hợp'!K:K=""Đang xử lý"")+('Bảng tổng hợp'!K:K=""Nộp thành công - Chờ kết quả"")+('Bảng tổng hợp'!K:K="""")) "),"219/BK-2025") -> 219/BK-2025
A3: =IFERROR(__xludf.DUMMYFUNCTION("""COMPUTED_VALUE"""),"326/BK-2025") -> 326/BK-2025
A4: =IFERROR(__xludf.DUMMYFUNCTION("""COMPUTED_VALUE"""),"347/BK-2025") -> 347/BK-2025
A5: =IFERROR(__xludf.DUMMYFUNCTION("""COMPUTED_VALUE"""),"348/BK-2025") -> 348/BK-2025
A6: =IFERROR(__xludf.DUMMYFUNCTION("""COMPUTED_VALUE"""),"349/BK-2025") -> 349/BK-2025
A7: =IFERROR(__xludf.DUMMYFUNCTION("""COMPUTED_VALUE"""),"350/BK-2025") -> 350/BK-2025
A8: =IFERROR(__xludf.DUMMYFUNCTION("""COMPUTED_VALUE"""),"357/BK-2025") -> 357/BK-2025
A9: =IFERROR(__xludf.DUMMYFUNCTION("""COMPUTED_VALUE"""),"358/BK-2025") -> 358/BK-2025
A10: =IFERROR(__xludf.DUMMYFUNCTION("""COMPUTED_VALUE"""),"364/BK-2025") -> 364/BK-2025
A11: =IFERROR(__xludf.DUMMYFUNCTION("""COMPUTED_VALUE"""),"379/BK-2025") -> 379/BK-2025
A12: =IFERROR(__xludf.DUMMYFUNCTION("""COMPUTED_VALUE"""),"388/BK-2025") -> 388/BK-2025
A13: =IFERROR(__xludf.DUMMYFUNCTION("""COMPUTED_VALUE"""),"401/BK-2025") -> 401/BK-2025
A14: =IFERROR(__xludf.DUMMYFUNCTION("""COMPUTED_VALUE"""),"399/BK-2025") -> 399/BK-2025
A15: =IFERROR(__xludf.DUMMYFUNCTION("""COMPUTED_VALUE"""),"407/BK-2025") -> 407/BK-2025
A16: =IFERROR(__xludf.DUMMYFUNCTION("""COMPUTED_VALUE"""),"419/BK-2025") -> 419/BK-2025
A17: =IFERROR(__xludf.DUMMYFUNCTION("""COMPUTED_VALUE"""),"423/BK-2025") -> 423/BK-2025
